File: FrgTools/Example Notebooks/Smartlab XRD Processing/Data/CsEuPbBr3_A.ras
*RAS_DATA_START
*RAS_HEADER_START
*DISP_FMT_X "%.2f"
*DISP_FMT_Y "%.0f"
*DISP_FULLSCALE "31622.4000000000"
*DISP_LINE_COLOR "255.0000000000"
*DISP_LINE_STYLE "0.0000000000"
*DISP_LINE_WIDTH "0.2500000000"
*DISP_NOTE "Collected Data-3"
*DISP_OFFSET_Y "0.0000000000"
*DISP_PEAKSEARCH_UNIT_Y "cps"
*DISP_RANGE_BOTTOM "0.0000000000"
*DISP_RANGE_LEFT "10.0000000000"
*DISP_RANGE_LOGCUTOFF "0.0100000000"
*DISP_RANGE_RIGHT "60.0000000000"
*DISP_RANGE_TOP "31622.4000000000"
*DISP_SCALE_MODE_Y "0.0000000000"
*DISP_TAB_NAME "Theta/2-Theta"
*DISP_TITLE_Y "Intensity"
*DISP_UNIT_Y "cps"
*DISP_WINDOW_NAME "MSG_MACROENGINE"
*FILE_COMMENT " "
*FILE_MD5 ""
*FILE_MEMO " "
*FILE_OPERATOR "qmtlab"
*FILE_PART_ID "MEAS_KHP2_00068"
*FILE_SAMPLE " "
*FILE_TYPE "RAS_RAW"
*FILE_USERGROUP "System Manager"
*FILE_VERSION "1.0000000000"
*HW_ATTACHMENT_ID "ATT0022"
*HW_ATTACHMENT_NAME "RxRy|RxRy"
*HW_COUNTER_ID-0 "CUT0021"
*HW_COUNTER_ID-1 "CUT0020"
*HW_COUNTER_ID-2 ""
*HW_COUNTER_ID-3 "CSL0021"
*HW_COUNTER_ID-4 "CMC0021"
*HW_COUNTER_NAME-0 "SC-70|SC-70"
*HW_COUNTER_NAME-1 "None|None"
*HW_COUNTER_NAME-2 ""
*HW_COUNTER_NAME-3 "BBM|BBM"
*HW_COUNTER_NAME-4 "検出器モノクロメータ|Detector monochromator"
*HW_COUNTER_SELECT_NAME "SC-70|SC-70"
*HW_ECP_HV "655.5000000000"
*HW_ECP_HV_UNIT "V"
*HW_GONIOMETER_ID "GON0024"
*HW_GONIOMETER_NAME "SmartLab(In-plane)|SmartLab(In-plane)"
*HW_GONIOMETER_RADIUS-0 "90.0"
*HW_GONIOMETER_RADIUS-1 "114.0"
*HW_GONIOMETER_RADIUS-2 "190.0"
*HW_GONIOMETER_RADIUS-3 "300.0"
*HW_GONIOMETER_RADIUS-4 "187.0"
*HW_GONIOMETER_RADIUS-5 "300.0"
*HW_GONIOMETER_RADIUS-6 "113.0"
*HW_GONIOMETER_RADIUS-7 "331.0"
*HW_I_OPT_ID-0 "CBO0021"
*HW_I_OPT_ID-1 "ICR0023"
*HW_I_OPT_ID-2 "ISL0021"
*HW_I_OPT_ID-3 "ISO0021"
*HW_I_OPT_ID-4 "IAD0021"
*HW_I_OPT_ID-5 "IPR0001"
*HW_I_OPT_NAME-0 "CBOユニット|CBO unit"
*HW_I_OPT_NAME-1 "標準入射光学ユニット|Standard incident optical unit"
*HW_I_OPT_NAME-2 "標準入射スリットボックス|Standard incident slit box"
*HW_I_OPT_NAME-3 "入射平行スリット|Incident parallel slit"
*HW_I_OPT_NAME-4 "長手制限スリット|Length limiting slit"
*HW_I_OPT_NAME-5 "None|None"
*HW_R_ATTENUATER_AUTOMODE "0"
*HW_R_OPT_ID-0 "RSS0021"
*HW_R_OPT_ID-1 "RCR0022"
*HW_R_OPT_ID-2 "RSO0021"
*HW_R_OPT_ID-3 "RRS0021"
*HW_R_OPT_ID-4 "ATN0021"
*HW_R_OPT_ID-5 "RFL0021"
*HW_R_OPT_ID-6 "RAD0021"
*HW_R_OPT_NAME-0 "標準受光スリットボックス1|Standard receiving slit box # 1"
*HW_R_OPT_NAME-1 "標準受光光学ユニット1|Standard receiving unit # 1"
*HW_R_OPT_NAME-2 "標準受光光学ユニット2|Standard receiving optical unit # 2"
*HW_R_OPT_NAME-3 "標準受光スリットボックス2|Standard receiving slit box # 2"
*HW_R_OPT_NAME-4 "標準アッテネータ|Standard Attenuator"
*HW_R_OPT_NAME-5 "Cu Kβ|Cu K-beta"
*HW_R_OPT_NAME-6 "調整用受光スリット|Alignment receiving slit"
*HW_SAMPLE_HOLDER_ID "SMP0026"
*HW_SAMPLE_HOLDER_NAME "Z-φステージ|Z-Phi Stage"
*HW_XG_CURRENT_MAX "50"
*HW_XG_CURRENT_MIN "2"
*HW_XG_CURRENT_RESOLUTION "2"
*HW_XG_CURRENT_UNIT "mA"
*HW_XG_FOCUS "1mm x 10mm"
*HW_XG_FOCUS_TYPE "Normal"
*HW_XG_ID ""
*HW_XG_NAME "3kW 封入管(ID:1200)|3kW Sealed tube(ID:1200)"
*HW_XG_TARGET_ATOMIC_NUMBER "29.0000000000"
*HW_XG_TARGET_NAME "Cu"
*HW_XG_TYPE "Hermetic"
*HW_XG_VOLTAGE_MAX "60"
*HW_XG_VOLTAGE_MIN "20"
*HW_XG_VOLTAGE_RESOLUTION "2"
*HW_XG_VOLTAGE_UNIT "kV"
*HW_XG_WATT_MAX "2"
*HW_XG_WATT_UNIT "kW"
*HW_XG_WAVE_LENGTH_ALPHA1 "1.540593"
*HW_XG_WAVE_LENGTH_ALPHA2 "1.544414"
*HW_XG_WAVE_LENGTH_BETA "1.392250"
*MEAS_COND_AXIS_NAME-0 "Theta/2-Theta"
*MEAS_COND_AXIS_NAME-1 "2-Theta"
*MEAS_COND_AXIS_NAME-2 "Omega"
*MEAS_COND_AXIS_NAME-3 "Phi"
*MEAS_COND_AXIS_NAME-4 "Z"
*MEAS_COND_AXIS_NAME-5 "Rx"
*MEAS_COND_AXIS_NAME-6 "Ry"
*MEAS_COND_AXIS_NAME-7 "2-Theta/Omega"
*MEAS_COND_AXIS_NAME-8 "2-ThetaChi"
*MEAS_COND_AXIS_NAME-9 "2-ThetaChi/Phi"
*MEAS_COND_AXIS_NAME-10 "Alpha"
*MEAS_COND_AXIS_NAME-11 "Beta"
*MEAS_COND_AXIS_NAME-12 "Theta_s"
*MEAS_COND_AXIS_NAME-13 "Theta_d"
*MEAS_COND_AXIS_NAME-14 "Ts"
*MEAS_COND_AXIS_NAME-15 "CBO selection slit"
*MEAS_COND_AXIS_NAME-16 "M"
*MEAS_COND_AXIS_NAME-17 "Incident parallel slit"
*MEAS_COND_AXIS_NAME-18 "Incident slit"
*MEAS_COND_AXIS_NAME-19 ""
*MEAS_COND_AXIS_NAME-20 "Zs"
*MEAS_COND_AXIS_NAME-21 "Incident monochromator"
*MEAS_COND_AXIS_NAME-22 "Length limiting slit"
*MEAS_COND_AXIS_NAME-23 "Center slit"
*MEAS_COND_AXIS_NAME-24 "Filter"
*MEAS_COND_AXIS_NAME-25 "Receiving slit # 1"
*MEAS_COND_AXIS_NAME-26 "Receiving slit # 2"
*MEAS_COND_AXIS_NAME-27 "Receiving optical device"
*MEAS_COND_AXIS_NAME-28 "Receiving parallel slit"
*MEAS_COND_AXIS_NAME-29 "Alignment receiving slit"
*MEAS_COND_AXIS_NAME-30 ""
*MEAS_COND_AXIS_NAME-31 ""
*MEAS_COND_AXIS_NAME-32 "Zd"
*MEAS_COND_AXIS_NAME-33 "Attenuator"
*MEAS_COND_AXIS_NAME-34 "Diffracted beam monochromator"
*MEAS_COND_AXIS_NAME-35 "Monochromator slit"
*MEAS_COND_AXIS_NAME-36 "2-ThetaB"
*MEAS_COND_AXIS_NAME-37 "Primary beam"
*MEAS_COND_AXIS_NAME-38 "HV"
*MEAS_COND_AXIS_NAME-39 "PHA"
*MEAS_COND_AXIS_NAME_INTERNAL-0 "TwoThetaTheta"
*MEAS_COND_AXIS_NAME_INTERNAL-1 "TwoTheta"
*MEAS_COND_AXIS_NAME_INTERNAL-2 "Omega"
*MEAS_COND_AXIS_NAME_INTERNAL-3 "Phi"
*MEAS_COND_AXIS_NAME_INTERNAL-4 "Z"
*MEAS_COND_AXIS_NAME_INTERNAL-5 "Rx"
*MEAS_COND_AXIS_NAME_INTERNAL-6 "Ry"
*MEAS_COND_AXIS_NAME_INTERNAL-7 "TwoThetaOmega"
*MEAS_COND_AXIS_NAME_INTERNAL-8 "TwoThetaChi"
*MEAS_COND_AXIS_NAME_INTERNAL-9 "TwoThetaChiPhi"
*MEAS_COND_AXIS_NAME_INTERNAL-10 "Alpha"
*MEAS_COND_AXIS_NAME_INTERNAL-11 "Beta"
*MEAS_COND_AXIS_NAME_INTERNAL-12 "ThetaS"
*MEAS_COND_AXIS_NAME_INTERNAL-13 "ThetaD"
*MEAS_COND_AXIS_NAME_INTERNAL-14 "Ts"
*MEAS_COND_AXIS_NAME_INTERNAL-15 "CBO"
*MEAS_COND_AXIS_NAME_INTERNAL-16 "CBO-M"
*MEAS_COND_AXIS_NAME_INTERNAL-17 "IncidentSollerSlit"
*MEAS_COND_AXIS_NAME_INTERNAL-18 "IncidentSlitBox"
*MEAS_COND_AXIS_NAME_INTERNAL-19 "IncidentSlitBox-_Axis"
*MEAS_COND_AXIS_NAME_INTERNAL-20 "Zs"
*MEAS_COND_AXIS_NAME_INTERNAL-21 "IncidentMonochromator"
*MEAS_COND_AXIS_NAME_INTERNAL-22 "IncidentAxdSlit"
*MEAS_COND_AXIS_NAME_INTERNAL-23 "CenterSlit"
*MEAS_COND_AXIS_NAME_INTERNAL-24 "Filter"
*MEAS_COND_AXIS_NAME_INTERNAL-25 "ReceivingSlitBox1"
*MEAS_COND_AXIS_NAME_INTERNAL-26 "ReceivingSlitBox2"
*MEAS_COND_AXIS_NAME_INTERNAL-27 "ReceivingOptics"
*MEAS_COND_AXIS_NAME_INTERNAL-28 "ReceivingSollerSlit"
*MEAS_COND_AXIS_NAME_INTERNAL-29 "ReceivingAxdSlit"
*MEAS_COND_AXIS_NAME_INTERNAL-30 "ReceivingSlitBox1-_Axis"
*MEAS_COND_AXIS_NAME_INTERNAL-31 "ReceivingSlitBox2-_Axis"
*MEAS_COND_AXIS_NAME_INTERNAL-32 "ReceivingSlitBox2-Zd"
*MEAS_COND_AXIS_NAME_INTERNAL-33 "Attenuator"
*MEAS_COND_AXIS_NAME_INTERNAL-34 "CounterMonochromator"
*MEAS_COND_AXIS_NAME_INTERNAL-35 "CounterSlit"
*MEAS_COND_AXIS_NAME_INTERNAL-36 "TwoThetaB"
*MEAS_COND_AXIS_NAME_INTERNAL-37 "IncidentPrimary"
*MEAS_COND_AXIS_NAME_INTERNAL-38 "HV"
*MEAS_COND_AXIS_NAME_INTERNAL-39 "PHA"
*MEAS_COND_AXIS_NAME_MAGICNO-0 "83951616.0000000000"
*MEAS_COND_AXIS_NAME_MAGICNO-1 "268632064.0000000000"
*MEAS_COND_AXIS_NAME_MAGICNO-2 "268500992.0000000000"
*MEAS_COND_AXIS_NAME_MAGICNO-3 "268500992.0000000000"
*MEAS_COND_AXIS_NAME_MAGICNO-4 "285278208.0000000000"
*MEAS_COND_AXIS_NAME_MAGICNO-5 "285278208.0000000000"
*MEAS_COND_AXIS_NAME_MAGICNO-6 "285278208.0000000000"
*MEAS_COND_AXIS_NAME_MAGICNO-7 "83951616.0000000000"
*MEAS_COND_AXIS_NAME_MAGICNO-8 "268632064.0000000000"
*MEAS_COND_AXIS_NAME_MAGICNO-9 "83951616.0000000000"
*MEAS_COND_AXIS_NAME_MAGICNO-10 "17039360.0000000000"
*MEAS_COND_AXIS_NAME_MAGICNO-11 "17039360.0000000000"
*MEAS_COND_AXIS_NAME_MAGICNO-12 "131072.0000000000"
*MEAS_COND_AXIS_NAME_MAGICNO-13 "131072.0000000000"
*MEAS_COND_AXIS_NAME_MAGICNO-14 "318898176.0000000000"
*MEAS_COND_AXIS_NAME_MAGICNO-15 "20971521.0000000000"
*MEAS_COND_AXIS_NAME_MAGICNO-16 "285343744.0000000000"
*MEAS_COND_AXIS_NAME_MAGICNO-17 "20971521.0000000000"
*MEAS_COND_AXIS_NAME_MAGICNO-18 "22020097.0000000000"
*MEAS_COND_AXIS_NAME_MAGICNO-19 "25165824.0000000000"
*MEAS_COND_AXIS_NAME_MAGICNO-20 "318898176.0000000000"
*MEAS_COND_AXIS_NAME_MAGICNO-21 "1.0000000000"
*MEAS_COND_AXIS_NAME_MAGICNO-22 "20971521.0000000000"
*MEAS_COND_AXIS_NAME_MAGICNO-23 "20971521.0000000000"
*MEAS_COND_AXIS_NAME_MAGICNO-24 "20971521.0000000000"
*MEAS_COND_AXIS_NAME_MAGICNO-25 "23068673.0000000000"
*MEAS_COND_AXIS_NAME_MAGICNO-26 "23068673.0000000000"
*MEAS_COND_AXIS_NAME_MAGICNO-27 "20971521.0000000000"
*MEAS_COND_AXIS_NAME_MAGICNO-28 "20971521.0000000000"
*MEAS_COND_AXIS_NAME_MAGICNO-29 "20971521.0000000000"
*MEAS_COND_AXIS_NAME_MAGICNO-30 "25165824.0000000000"
*MEAS_COND_AXIS_NAME_MAGICNO-31 "25165824.0000000000"
*MEAS_COND_AXIS_NAME_MAGICNO-32 "285343744.0000000000"
*MEAS_COND_AXIS_NAME_MAGICNO-33 "17301505.0000000000"
*MEAS_COND_AXIS_NAME_MAGICNO-34 "20971521.0000000000"
*MEAS_COND_AXIS_NAME_MAGICNO-35 "20971521.0000000000"
*MEAS_COND_AXIS_NAME_MAGICNO-36 "17039360.0000000000"
*MEAS_COND_AXIS_NAME_MAGICNO-37 "20971521.0000000000"
*MEAS_COND_AXIS_NAME_MAGICNO-38 "0.0000000000"
*MEAS_COND_AXIS_NAME_MAGICNO-39 "0.0000000000"
*MEAS_COND_AXIS_OFFSET-0 "-"
*MEAS_COND_AXIS_OFFSET-1 "-0.0565000000"
*MEAS_COND_AXIS_OFFSET-2 "-0.3059000000"
*MEAS_COND_AXIS_OFFSET-3 "0.0000000000"
*MEAS_COND_AXIS_OFFSET-4 "-"
*MEAS_COND_AXIS_OFFSET-5 "-"
*MEAS_COND_AXIS_OFFSET-6 "-"
*MEAS_COND_AXIS_OFFSET-7 "-"
*MEAS_COND_AXIS_OFFSET-8 "0.0000000000"
*MEAS_COND_AXIS_OFFSET-9 "-"
*MEAS_COND_AXIS_OFFSET-10 "-"
*MEAS_COND_AXIS_OFFSET-11 "-"
*MEAS_COND_AXIS_OFFSET-12 "-0.3059000000"
*MEAS_COND_AXIS_OFFSET-13 "0.2494000000"
*MEAS_COND_AXIS_OFFSET-14 "-"
*MEAS_COND_AXIS_OFFSET-15 "-"
*MEAS_COND_AXIS_OFFSET-16 "-"
*MEAS_COND_AXIS_OFFSET-17 "-"
*MEAS_COND_AXIS_OFFSET-18 "-"
*MEAS_COND_AXIS_OFFSET-19 "-"
*MEAS_COND_AXIS_OFFSET-20 "-"
*MEAS_COND_AXIS_OFFSET-21 "-"
*MEAS_COND_AXIS_OFFSET-22 "-"
*MEAS_COND_AXIS_OFFSET-23 "-"
*MEAS_COND_AXIS_OFFSET-24 "-"
*MEAS_COND_AXIS_OFFSET-25 "-"
*MEAS_COND_AXIS_OFFSET-26 "-"
*MEAS_COND_AXIS_OFFSET-27 "-"
*MEAS_COND_AXIS_OFFSET-28 "-"
*MEAS_COND_AXIS_OFFSET-29 "-"
*MEAS_COND_AXIS_OFFSET-30 "-"
*MEAS_COND_AXIS_OFFSET-31 "-"
*MEAS_COND_AXIS_OFFSET-32 "-"
*MEAS_COND_AXIS_OFFSET-33 "-"
*MEAS_COND_AXIS_OFFSET-34 "-"
*MEAS_COND_AXIS_OFFSET-35 "-"
*MEAS_COND_AXIS_OFFSET-36 "-"
*MEAS_COND_AXIS_OFFSET-37 "-"
*MEAS_COND_AXIS_OFFSET-38 "-"
*MEAS_COND_AXIS_OFFSET-39 "-"
*MEAS_COND_AXIS_POSITION-0 "0.0000000000"
*MEAS_COND_AXIS_POSITION-1 "0.0000000000"
*MEAS_COND_AXIS_POSITION-2 "0.0000000000"
*MEAS_COND_AXIS_POSITION-3 "0.0000000000"
*MEAS_COND_AXIS_POSITION-4 "-1.6608000000"
*MEAS_COND_AXIS_POSITION-5 "0.0000000000"
*MEAS_COND_AXIS_POSITION-6 "0.0000000000"
*MEAS_COND_AXIS_POSITION-7 "0.0000000000"
*MEAS_COND_AXIS_POSITION-8 "0.0000000000"
*MEAS_COND_AXIS_POSITION-9 "0.0000000000"
*MEAS_COND_AXIS_POSITION-10 "90.0000000000"
*MEAS_COND_AXIS_POSITION-11 "0.0000000000"
*MEAS_COND_AXIS_POSITION-12 "0.0000000000"
*MEAS_COND_AXIS_POSITION-13 "0.0000000000"
*MEAS_COND_AXIS_POSITION-14 "-0.6988100000"
*MEAS_COND_AXIS_POSITION-15 "BB"
*MEAS_COND_AXIS_POSITION-16 "0.0000000000"
*MEAS_COND_AXIS_POSITION-17 "Soller_slit_5.0deg"
*MEAS_COND_AXIS_POSITION-18 "1/2deg"
*MEAS_COND_AXIS_POSITION-19 "1.6581000000"
*MEAS_COND_AXIS_POSITION-20 "-0.2171900000"
*MEAS_COND_AXIS_POSITION-21 "0.0000000000"
*MEAS_COND_AXIS_POSITION-22 "10.0mm"
*MEAS_COND_AXIS_POSITION-23 "None"
*MEAS_COND_AXIS_POSITION-24 "Cu_K-beta"
*MEAS_COND_AXIS_POSITION-25 "1/2deg"
*MEAS_COND_AXIS_POSITION-26 "0.300mm"
*MEAS_COND_AXIS_POSITION-27 "PSA_open"
*MEAS_COND_AXIS_POSITION-28 "Soller_slit_5.0deg"
*MEAS_COND_AXIS_POSITION-29 "None"
*MEAS_COND_AXIS_POSITION-30 "0.9862000000"
*MEAS_COND_AXIS_POSITION-31 "0.3000000000"
*MEAS_COND_AXIS_POSITION-32 "0.4521900000"
*MEAS_COND_AXIS_POSITION-33 "Open"
*MEAS_COND_AXIS_POSITION-34 "None"
*MEAS_COND_AXIS_POSITION-35 "None"
*MEAS_COND_AXIS_POSITION-36 "0.0000000000"
*MEAS_COND_AXIS_POSITION-37 "None"
*MEAS_COND_AXIS_POSITION-38 "655.5000000000"
*MEAS_COND_AXIS_POSITION-39 "526.2500000000"
*MEAS_COND_AXIS_UNIT-0 "deg"
*MEAS_COND_AXIS_UNIT-1 "deg"
*MEAS_COND_AXIS_UNIT-2 "deg"
*MEAS_COND_AXIS_UNIT-3 "deg"
*MEAS_COND_AXIS_UNIT-4 "mm"
*MEAS_COND_AXIS_UNIT-5 "deg"
*MEAS_COND_AXIS_UNIT-6 "deg"
*MEAS_COND_AXIS_UNIT-7 "deg"
*MEAS_COND_AXIS_UNIT-8 "deg"
*MEAS_COND_AXIS_UNIT-9 "deg"
*MEAS_COND_AXIS_UNIT-10 "deg"
*MEAS_COND_AXIS_UNIT-11 "deg"
*MEAS_COND_AXIS_UNIT-12 "deg"
*MEAS_COND_AXIS_UNIT-13 "deg"
*MEAS_COND_AXIS_UNIT-14 "mm"
*MEAS_COND_AXIS_UNIT-15 ""
*MEAS_COND_AXIS_UNIT-16 "pulse"
*MEAS_COND_AXIS_UNIT-17 ""
*MEAS_COND_AXIS_UNIT-18 ""
*MEAS_COND_AXIS_UNIT-19 "mm"
*MEAS_COND_AXIS_UNIT-20 "mm"
*MEAS_COND_AXIS_UNIT-21 ""
*MEAS_COND_AXIS_UNIT-22 ""
*MEAS_COND_AXIS_UNIT-23 ""
*MEAS_COND_AXIS_UNIT-24 ""
*MEAS_COND_AXIS_UNIT-25 ""
*MEAS_COND_AXIS_UNIT-26 ""
*MEAS_COND_AXIS_UNIT-27 ""
*MEAS_COND_AXIS_UNIT-28 ""
*MEAS_COND_AXIS_UNIT-29 ""
*MEAS_COND_AXIS_UNIT-30 "mm"
*MEAS_COND_AXIS_UNIT-31 "mm"
*MEAS_COND_AXIS_UNIT-32 "mm"
*MEAS_COND_AXIS_UNIT-33 ""
*MEAS_COND_AXIS_UNIT-34 ""
*MEAS_COND_AXIS_UNIT-35 ""
*MEAS_COND_AXIS_UNIT-36 "deg"
*MEAS_COND_AXIS_UNIT-37 ""
*MEAS_COND_AXIS_UNIT-38 "V"
*MEAS_COND_AXIS_UNIT-39 "mV"
*MEAS_COND_COUNTER_CNTLOSS_CORR "1.0000000000"
*MEAS_COND_COUNTER_PHABASE "526.2500000000"
*MEAS_COND_COUNTER_PHAWINDOW "807.5000000000"
*MEAS_COND_COUNTER_PHA_UNIT "mV"
*MEAS_COND_COUNTER_TAUDIFF "0.1731010000"
*MEAS_COND_COUNTER_TAUINT "0.6617980000"
*MEAS_COND_IRRADIATION_MODE "OFF"
*MEAS_COND_IRRADIATION_WIDTH ""
*MEAS_COND_OPT_ATTR "Bragg-Brentano focusing"
*MEAS_COND_OPT_NAME "@BB focusing"
*MEAS_COND_UNSYMMETRIC_MODE "OFF"
*MEAS_COND_XG_CURRENT "44.0000000000"
*MEAS_COND_XG_VOLTAGE "40.0000000000"
*MEAS_COND_XG_WAVE_TYPE "Ka"
*MEAS_DATA_COUNT "2501.0000000000"
*MEAS_SCAN_AXIS_X "Theta/2-Theta"
*MEAS_SCAN_AXIS_X_INTERNAL "TwoThetaTheta"
*MEAS_SCAN_END_TIME "01/18/21 15:27:05"
*MEAS_SCAN_MODE "STEP"
*MEAS_SCAN_MONITOR "0"
*MEAS_SCAN_RESOLUTION_X "0.0002"
*MEAS_SCAN_SPEED "1.000000"
*MEAS_SCAN_SPEED_UNIT "sec."
*MEAS_SCAN_SPEED_USER "1.00"
*MEAS_SCAN_START "10.0000000000"
*MEAS_SCAN_START_TIME "01/18/21 14:40:13"
*MEAS_SCAN_STEP "0.0200000000"
*MEAS_SCAN_STOP "60.0000000000"
*MEAS_SCAN_UNIT_X "deg"
*MEAS_SCAN_UNIT_Y "counts"
*RAS_HEADER_END
*RAS_INT_START
10.0000 209.0000 1.0000
10.0400 216.0000 1.0000
10.0800 193.0000 1.0000
10.1200 216.0000 1.0000
10.1600 199.0000 1.0000
10.2000 224.0000 1.0000
10.2400 201.0000 1.0000
10.2800 243.0000 1.0000
10.3200 208.0000 1.0000
10.3600 204.0000 1.0000
10.4000 231.0000 1.0000
10.4400 228.0000 1.0000
10.4800 220.0000 1.0000
10.5200 220.0000 1.0000
10.5600 207.0000 1.0000
10.6000 204.0000 1.0000
10.6400 218.0000 1.0000
10.6800 223.0000 1.0000
10.7200 197.0000 1.0000
10.7600 229.0000 1.0000
10.8000 242.0000 1.0000
10.8400 243.0000 1.0000
10.8800 233.0000 1.0000
10.9200 198.0000 1.0000
10.9600 216.0000 1.0000
11.0000 213.0000 1.0000
11.0400 213.0000 1.0000
11.0800 216.0000 1.0000
11.1200 233.0000 1.0000
11.1600 250.0000 1.0000
11.2000 202.0000 1.0000
11.2400 218.0000 1.0000
11.2800 210.0000 1.0000
11.3200 224.0000 1.0000
11.3600 235.0000 1.0000
11.4000 211.0000 1.0000
11.4400 223.0000 1.0000
11.4800 199.0000 1.0000
11.5200 239.0000 1.0000
11.5600 203.0000 1.0000
11.6000 226.0000 1.0000
11.6400 210.0000 1.0000
11.6800 208.0000 1.0000
11.7200 228.0000 1.0000
11.7600 205.0000 1.0000
11.8000 257.0000 1.0000
11.8400 234.0000 1.0000
11.8800 227.0000 1.0000
11.9200 222.0000 1.0000
11.9600 256.0000 1.0000
12.0000 231.0000 1.0000
12.0400 233.0000 1.0000
12.0800 240.0000 1.0000
12.1200 222.0000 1.0000
12.1600 253.0000 1.0000
12.2000 255.0000 1.0000
12.2400 292.0000 1.0000
12.2800 263.0000 1.0000
12.3200 232.0000 1.0000
12.3600 255.0000 1.0000
12.4000 267.0000 1.0000
12.4400 280.0000 1.0000
12.4800 287.0000 1.0000
12.5200 282.0000 1.0000
12.5600 273.0000 1.0000
12.6000 334.0000 1.0000
12.6400 516.0000 1.0000
12.6800 448.0000 1.0000
12.7200 292.0000 1.0000
12.7600 256.0000 1.0000
12.8000 252.0000 1.0000
12.8400 253.0000 1.0000
12.8800 265.0000 1.0000
12.9200 273.0000 1.0000
12.9600 237.0000 1.0000
13.0000 261.0000 1.0000
13.0400 249.0000 1.0000
13.0800 282.0000 1.0000
13.1200 243.0000 1.0000
13.1600 251.0000 1.0000
13.2000 282.0000 1.0000
13.2400 235.0000 1.0000
13.2800 258.0000 1.0000
13.3200 270.0000 1.0000
13.3600 245.0000 1.0000
13.4000 217.0000 1.0000
13.4400 257.0000 1.0000
13.4800 262.0000 1.0000
13.5200 247.0000 1.0000
13.5600 305.0000 1.0000
13.6000 278.0000 1.0000
13.6400 268.0000 1.0000
13.6800 265.0000 1.0000
13.7200 377.0000 1.0000
13.7600 355.0000 1.0000
13.8000 302.0000 1.0000
13.8400 244.0000 1.0000
13.8800 264.0000 1.0000
13.9200 298.0000 1.0000
13.9600 292.0000 1.0000
14.0000 297.0000 1.0000
14.0400 270.0000 1.0000
14.0800 269.0000 1.0000
14.1200 275.0000 1.0000
14.1600 288.0000 1.0000
14.2000 270.0000 1.0000
14.2400 257.0000 1.0000
14.2800 261.0000 1.0000
14.3200 280.0000 1.0000
14.3600 275.0000 1.0000
14.4000 260.0000 1.0000
14.4400 276.0000 1.0000
14.4800 255.0000 1.0000
14.5200 281.0000 1.0000
14.5600 314.0000 1.0000
14.6000 343.0000 1.0000
14.6400 314.0000 1.0000
14.6800 381.0000 1.0000
14.7200 357.0000 1.0000
14.7600 314.0000 1.0000
14.8000 314.0000 1.0000
14.8400 326.0000 1.0000
14.8800 369.0000 1.0000
14.9200 401.0000 1.0000
14.9600 430.0000 1.0000
15.0000 580.0000 1.0000
15.0400 1172.0000 1.0000
15.0800 1413.0000 1.0000
15.1200 1035.0000 1.0000
15.1600 1692.0000 1.0000
15.2000 8794.0000 1.0000
15.2400 8900.0000 1.0000
15.2800 2672.0000 1.0000
15.3200 640.0000 1.0000
15.3600 502.0000 1.0000
15.4000 417.0000 1.0000
15.4400 373.0000 1.0000
15.4800 335.0000 1.0000
15.5200 328.0000 1.0000
15.5600 358.0000 1.0000
15.6000 338.0000 1.0000
15.6400 336.0000 1.0000
15.6800 347.0000 1.0000
15.7200 323.0000 1.0000
15.7600 342.0000 1.0000
15.8000 330.0000 1.0000
15.8400 346.0000 1.0000
15.8800 326.0000 1.0000
15.9200 308.0000 1.0000
15.9600 315.0000 1.0000
16.0000 326.0000 1.0000
16.0400 313.0000 1.0000
16.0800 334.0000 1.0000
16.1200 317.0000 1.0000
16.1600 315.0000 1.0000
16.2000 296.0000 1.0000
16.2400 293.0000 1.0000
16.2800 293.0000 1.0000
16.3200 310.0000 1.0000
16.3600 343.0000 1.0000
16.4000 306.0000 1.0000
16.4400 288.0000 1.0000
16.4800 337.0000 1.0000
16.5200 300.0000 1.0000
16.5600 323.0000 1.0000
16.6000 294.0000 1.0000
16.6400 325.0000 1.0000
16.6800 304.0000 1.0000
16.7200 326.0000 1.0000
16.7600 293.0000 1.0000
16.8000 291.0000 1.0000
16.8400 307.0000 1.0000
16.8800 304.0000 1.0000
16.9200 276.0000 1.0000
16.9600 290.0000 1.0000
17.0000 301.0000 1.0000
17.0400 306.0000 1.0000
17.0800 324.0000 1.0000
17.1200 325.0000 1.0000
17.1600 300.0000 1.0000
17.2000 331.0000 1.0000
17.2400 302.0000 1.0000
17.2800 313.0000 1.0000
17.3200 342.0000 1.0000
17.3600 299.0000 1.0000
17.4000 313.0000 1.0000
17.4400 313.0000 1.0000
17.4800 291.0000 1.0000
17.5200 293.0000 1.0000
17.5600 310.0000 1.0000
17.6000 300.0000 1.0000
17.6400 294.0000 1.0000
17.6800 366.0000 1.0000
17.7200 305.0000 1.0000
17.7600 302.0000 1.0000
17.8000 316.0000 1.0000
17.8400 325.0000 1.0000
17.8800 336.0000 1.0000
17.9200 320.0000 1.0000
17.9600 337.0000 1.0000
18.0000 319.0000 1.0000
18.0400 354.0000 1.0000
18.0800 307.0000 1.0000
18.1200 310.0000 1.0000
18.1600 322.0000 1.0000
18.2000 321.0000 1.0000
18.2400 313.0000 1.0000
18.2800 323.0000 1.0000
18.3200 331.0000 1.0000
18.3600 331.0000 1.0000
18.4000 335.0000 1.0000
18.4400 320.0000 1.0000
18.4800 335.0000 1.0000
18.5200 323.0000 1.0000
18.5600 373.0000 1.0000
18.6000 334.0000 1.0000
18.6400 366.0000 1.0000
18.6800 330.0000 1.0000
18.7200 343.0000 1.0000
18.7600 341.0000 1.0000
18.8000 378.0000 1.0000
18.8400 335.0000 1.0000
18.8800 343.0000 1.0000
18.9200 333.0000 1.0000
18.9600 339.0000 1.0000
19.0000 353.0000 1.0000
19.0400 349.0000 1.0000
19.0800 359.0000 1.0000
19.1200 375.0000 1.0000
19.1600 392.0000 1.0000
19.2000 388.0000 1.0000
19.2400 383.0000 1.0000
19.2800 347.0000 1.0000
19.3200 343.0000 1.0000
19.3600 355.0000 1.0000
19.4000 381.0000 1.0000
19.4400 399.0000 1.0000
19.4800 386.0000 1.0000
19.5200 337.0000 1.0000
19.5600 381.0000 1.0000
19.6000 375.0000 1.0000
19.6400 398.0000 1.0000
19.6800 409.0000 1.0000
19.7200 369.0000 1.0000
19.7600 362.0000 1.0000
19.8000 395.0000 1.0000
19.8400 393.0000 1.0000
19.8800 401.0000 1.0000
19.9200 380.0000 1.0000
19.9600 380.0000 1.0000
20.0000 388.0000 1.0000
20.0400 400.0000 1.0000
20.0800 382.0000 1.0000
20.1200 399.0000 1.0000
20.1600 391.0000 1.0000
20.2000 419.0000 1.0000
20.2400 418.0000 1.0000
20.2800 375.0000 1.0000
20.3200 394.0000 1.0000
20.3600 392.0000 1.0000
20.4000 414.0000 1.0000
20.4400 389.0000 1.0000
20.4800 423.0000 1.0000
20.5200 416.0000 1.0000
20.5600 406.0000 1.0000
20.6000 413.0000 1.0000
20.6400 413.0000 1.0000
20.6800 414.0000 1.0000
20.7200 415.0000 1.0000
20.7600 430.0000 1.0000
20.8000 400.0000 1.0000
20.8400 406.0000 1.0000
20.8800 385.0000 1.0000
20.9200 412.0000 1.0000
20.9600 415.0000 1.0000
21.0000 429.0000 1.0000
21.0400 431.0000 1.0000
21.0800 424.0000 1.0000
21.1200 446.0000 1.0000
21.1600 455.0000 1.0000
21.2000 425.0000 1.0000
21.2400 404.0000 1.0000
21.2800 446.0000 1.0000
21.3200 426.0000 1.0000
21.3600 479.0000 1.0000
21.4000 559.0000 1.0000
21.4400 620.0000 1.0000
21.4800 666.0000 1.0000
21.5200 602.0000 1.0000
21.5600 558.0000 1.0000
21.6000 528.0000 1.0000
21.6400 580.0000 1.0000
21.6800 512.0000 1.0000
21.7200 499.0000 1.0000
21.7600 498.0000 1.0000
21.8000 439.0000 1.0000
21.8400 425.0000 1.0000
21.8800 426.0000 1.0000
21.9200 408.0000 1.0000
21.9600 415.0000 1.0000
22.0000 382.0000 1.0000
22.0400 410.0000 1.0000
22.0800 383.0000 1.0000
22.1200 416.0000 1.0000
22.1600 377.0000 1.0000
22.2000 365.0000 1.0000
22.2400 386.0000 1.0000
22.2800 402.0000 1.0000
22.3200 404.0000 1.0000
22.3600 416.0000 1.0000
22.4000 379.0000 1.0000
22.4400 398.0000 1.0000
22.4800 407.0000 1.0000
22.5200 365.0000 1.0000
22.5600 384.0000 1.0000
22.6000 384.0000 1.0000
22.6400 379.0000 1.0000
22.6800 366.0000 1.0000
22.7200 370.0000 1.0000
22.7600 372.0000 1.0000
22.8000 369.0000 1.0000
22.8400 356.0000 1.0000
22.8800 389.0000 1.0000
22.9200 354.0000 1.0000
22.9600 353.0000 1.0000
23.0000 363.0000 1.0000
23.0400 372.0000 1.0000
23.0800 362.0000 1.0000
23.1200 358.0000 1.0000
23.1600 344.0000 1.0000
23.2000 334.0000 1.0000
23.2400 336.0000 1.0000
23.2800 380.0000 1.0000
23.3200 375.0000 1.0000
23.3600 375.0000 1.0000
23.4000 364.0000 1.0000
23.4400 335.0000 1.0000
23.4800 355.0000 1.0000
23.5200 319.0000 1.0000
23.5600 367.0000 1.0000
23.6000 346.0000 1.0000
23.6400 356.0000 1.0000
23.6800 347.0000 1.0000
23.7200 314.0000 1.0000
23.7600 333.0000 1.0000
23.8000 326.0000 1.0000
23.8400 325.0000 1.0000
23.8800 325.0000 1.0000
23.9200 323.0000 1.0000
23.9600 308.0000 1.0000
24.0000 308.0000 1.0000
24.0400 299.0000 1.0000
24.0800 312.0000 1.0000
24.1200 297.0000 1.0000
24.1600 350.0000 1.0000
24.2000 335.0000 1.0000
24.2400 369.0000 1.0000
24.2800 326.0000 1.0000
24.3200 273.0000 1.0000
24.3600 348.0000 1.0000
24.4000 297.0000 1.0000
24.4400 301.0000 1.0000
24.4800 332.0000 1.0000
24.5200 308.0000 1.0000
24.5600 309.0000 1.0000
24.6000 345.0000 1.0000
24.6400 320.0000 1.0000
24.6800 380.0000 1.0000
24.7200 377.0000 1.0000
24.7600 343.0000 1.0000
24.8000 314.0000 1.0000
24.8400 275.0000 1.0000
24.8800 302.0000 1.0000
24.9200 290.0000 1.0000
24.9600 251.0000 1.0000
25.0000 266.0000 1.0000
25.0400 294.0000 1.0000
25.0800 282.0000 1.0000
25.1200 284.0000 1.0000
25.1600 282.0000 1.0000
25.2000 306.0000 1.0000
25.2400 277.0000 1.0000
25.2800 295.0000 1.0000
25.3200 322.0000 1.0000
25.3600 325.0000 1.0000
25.4000 400.0000 1.0000
25.4400 636.0000 1.0000
25.4800 509.0000 1.0000
25.5200 385.0000 1.0000
25.5600 279.0000 1.0000
25.6000 285.0000 1.0000
25.6400 289.0000 1.0000
25.6800 254.0000 1.0000
25.7200 274.0000 1.0000
25.7600 264.0000 1.0000
25.8000 263.0000 1.0000
25.8400 284.0000 1.0000
25.8800 247.0000 1.0000
25.9200 301.0000 1.0000
25.9600 265.0000 1.0000
26.0000 258.0000 1.0000
26.0400 224.0000 1.0000
26.0800 256.0000 1.0000
26.1200 228.0000 1.0000
26.1600 231.0000 1.0000
26.2000 209.0000 1.0000
26.2400 260.0000 1.0000
26.2800 254.0000 1.0000
26.3200 265.0000 1.0000
26.3600 329.0000 1.0000
26.4000 335.0000 1.0000
26.4400 391.0000 1.0000
26.4800 434.0000 1.0000
26.5200 313.0000 1.0000
26.5600 302.0000 1.0000
26.6000 247.0000 1.0000
26.6400 248.0000 1.0000
26.6800 251.0000 1.0000
26.7200 232.0000 1.0000
26.7600 224.0000 1.0000
26.8000 210.0000 1.0000
26.8400 226.0000 1.0000
26.8800 238.0000 1.0000
26.9200 233.0000 1.0000
26.9600 226.0000 1.0000
27.0000 275.0000 1.0000
27.0400 256.0000 1.0000
27.0800 292.0000 1.0000
27.1200 272.0000 1.0000
27.1600 253.0000 1.0000
27.2000 235.0000 1.0000
27.2400 202.0000 1.0000
27.2800 234.0000 1.0000
27.3200 214.0000 1.0000
27.3600 226.0000 1.0000
27.4000 258.0000 1.0000
27.4400 213.0000 1.0000
27.4800 254.0000 1.0000
27.5200 209.0000 1.0000
27.5600 202.0000 1.0000
27.6000 226.0000 1.0000
27.6400 294.0000 1.0000
27.6800 483.0000 1.0000
27.7200 326.0000 1.0000
27.7600 242.0000 1.0000
27.8000 237.0000 1.0000
27.8400 197.0000 1.0000
27.8800 245.0000 1.0000
27.9200 200.0000 1.0000
27.9600 200.0000 1.0000
28.0000 182.0000 1.0000
28.0400 198.0000 1.0000
28.0800 221.0000 1.0000
28.1200 200.0000 1.0000
28.1600 202.0000 1.0000
28.2000 202.0000 1.0000
28.2400 187.0000 1.0000
28.2800 206.0000 1.0000
28.3200 207.0000 1.0000
28.3600 212.0000 1.0000
28.4000 183.0000 1.0000
28.4400 202.0000 1.0000
28.4800 221.0000 1.0000
28.5200 195.0000 1.0000
28.5600 200.0000 1.0000
28.6000 234.0000 1.0000
28.6400 259.0000 1.0000
28.6800 208.0000 1.0000
28.7200 222.0000 1.0000
28.7600 191.0000 1.0000
28.8000 177.0000 1.0000
28.8400 181.0000 1.0000
28.8800 187.0000 1.0000
28.9200 159.0000 1.0000
28.9600 181.0000 1.0000
29.0000 174.0000 1.0000
29.0400 200.0000 1.0000
29.0800 169.0000 1.0000
29.1200 171.0000 1.0000
29.1600 172.0000 1.0000
29.2000 185.0000 1.0000
29.2400 205.0000 1.0000
29.2800 214.0000 1.0000
29.3200 231.0000 1.0000
29.3600 262.0000 1.0000
29.4000 264.0000 1.0000
29.4400 220.0000 1.0000
29.4800 210.0000 1.0000
29.5200 206.0000 1.0000
29.5600 204.0000 1.0000
29.6000 311.0000 1.0000
29.6400 392.0000 1.0000
29.6800 347.0000 1.0000
29.7200 301.0000 1.0000
29.7600 281.0000 1.0000
29.8000 286.0000 1.0000
29.8400 301.0000 1.0000
29.8800 281.0000 1.0000
29.9200 276.0000 1.0000
29.9600 300.0000 1.0000
30.0000 262.0000 1.0000
30.0400 289.0000 1.0000
30.0800 282.0000 1.0000
30.1200 274.0000 1.0000
30.1600 330.0000 1.0000
30.2000 321.0000 1.0000
30.2400 371.0000 1.0000
30.2800 431.0000 1.0000
30.3200 572.0000 1.0000
30.3600 1796.0000 1.0000
30.4000 2787.0000 1.0000
30.4400 1741.0000 1.0000
30.4800 1796.0000 1.0000
30.5200 1166.0000 1.0000
30.5600 1438.0000 1.0000
30.6000 1658.0000 1.0000
30.6400 3091.0000 1.0000
30.6800 18312.0000 1.0000
30.7200 24151.0000 1.0000
30.7600 12074.0000 1.0000
30.8000 11924.0000 1.0000
30.8400 2066.0000 1.0000
30.8800 1017.0000 1.0000
30.9200 653.0000 1.0000
30.9600 501.0000 1.0000
31.0000 426.0000 1.0000
31.0400 384.0000 1.0000
31.0800 336.0000 1.0000
31.1200 328.0000 1.0000
31.1600 271.0000 1.0000
31.2000 304.0000 1.0000
31.2400 344.0000 1.0000
31.2800 385.0000 1.0000
31.3200 328.0000 1.0000
31.3600 346.0000 1.0000
31.4000 262.0000 1.0000
31.4400 257.0000 1.0000
31.4800 244.0000 1.0000
31.5200 239.0000 1.0000
31.5600 219.0000 1.0000
31.6000 253.0000 1.0000
31.6400 234.0000 1.0000
31.6800 218.0000 1.0000
31.7200 215.0000 1.0000
31.7600 206.0000 1.0000
31.8000 230.0000 1.0000
31.8400 217.0000 1.0000
31.8800 181.0000 1.0000
31.9200 242.0000 1.0000
31.9600 197.0000 1.0000
32.0000 192.0000 1.0000
32.0400 202.0000 1.0000
32.0800 179.0000 1.0000
32.1200 217.0000 1.0000
32.1600 204.0000 1.0000
32.2000 203.0000 1.0000
32.2400 223.0000 1.0000
32.2800 218.0000 1.0000
32.3200 218.0000 1.0000
32.3600 218.0000 1.0000
32.4000 200.0000 1.0000
32.4400 209.0000 1.0000
32.4800 209.0000 1.0000
32.5200 213.0000 1.0000
32.5600 191.0000 1.0000
32.6000 173.0000 1.0000
32.6400 209.0000 1.0000
32.6800 201.0000 1.0000
32.7200 190.0000 1.0000
32.7600 206.0000 1.0000
32.8000 191.0000 1.0000
32.8400 175.0000 1.0000
32.8800 163.0000 1.0000
32.9200 190.0000 1.0000
32.9600 177.0000 1.0000
33.0000 166.0000 1.0000
33.0400 163.0000 1.0000
33.0800 202.0000 1.0000
33.1200 185.0000 1.0000
33.1600 188.0000 1.0000
33.2000 185.0000 1.0000
33.2400 172.0000 1.0000
33.2800 185.0000 1.0000
33.3200 177.0000 1.0000
33.3600 198.0000 1.0000
33.4000 177.0000 1.0000
33.4400 186.0000 1.0000
33.4800 203.0000 1.0000
33.5200 218.0000 1.0000
33.5600 202.0000 1.0000
33.6000 204.0000 1.0000
33.6400 195.0000 1.0000
33.6800 192.0000 1.0000
33.7200 177.0000 1.0000
33.7600 196.0000 1.0000
33.8000 186.0000 1.0000
33.8400 199.0000 1.0000
33.8800 149.0000 1.0000
33.9200 184.0000 1.0000
33.9600 192.0000 1.0000
34.0000 159.0000 1.0000
34.0400 184.0000 1.0000
34.0800 205.0000 1.0000
34.1200 187.0000 1.0000
34.1600 171.0000 1.0000
34.2000 183.0000 1.0000
34.2400 167.0000 1.0000
34.2800 184.0000 1.0000
34.3200 205.0000 1.0000
34.3600 187.0000 1.0000
34.4000 190.0000 1.0000
34.4400 222.0000 1.0000
34.4800 203.0000 1.0000
34.5200 185.0000 1.0000
34.5600 172.0000 1.0000
34.6000 174.0000 1.0000
34.6400 164.0000 1.0000
34.6800 170.0000 1.0000
34.7200 152.0000 1.0000
34.7600 150.0000 1.0000
34.8000 162.0000 1.0000
34.8400 146.0000 1.0000
34.8800 167.0000 1.0000
34.9200 131.0000 1.0000
34.9600 155.0000 1.0000
35.0000 169.0000 1.0000
35.0400 152.0000 1.0000
35.0800 150.0000 1.0000
35.1200 149.0000 1.0000
35.1600 154.0000 1.0000
35.2000 166.0000 1.0000
35.2400 151.0000 1.0000
35.2800 151.0000 1.0000
35.3200 139.0000 1.0000
35.3600 146.0000 1.0000
35.4000 150.0000 1.0000
35.4400 148.0000 1.0000
35.4800 170.0000 1.0000
35.5200 131.0000 1.0000
35.5600 142.0000 1.0000
35.6000 156.0000 1.0000
35.6400 145.0000 1.0000
35.6800 159.0000 1.0000
35.7200 143.0000 1.0000
35.7600 134.0000 1.0000
35.8000 124.0000 1.0000
35.8400 161.0000 1.0000
35.8800 133.0000 1.0000
35.9200 146.0000 1.0000
35.9600 150.0000 1.0000
36.0000 158.0000 1.0000
36.0400 157.0000 1.0000
36.0800 146.0000 1.0000
36.1200 150.0000 1.0000
36.1600 139.0000 1.0000
36.2000 148.0000 1.0000
36.2400 138.0000 1.0000
36.2800 149.0000 1.0000
36.3200 155.0000 1.0000
36.3600 132.0000 1.0000
36.4000 134.0000 1.0000
36.4400 145.0000 1.0000
36.4800 137.0000 1.0000
36.5200 148.0000 1.0000
36.5600 167.0000 1.0000
36.6000 133.0000 1.0000
36.6400 135.0000 1.0000
36.6800 128.0000 1.0000
36.7200 136.0000 1.0000
36.7600 133.0000 1.0000
36.8000 128.0000 1.0000
36.8400 133.0000 1.0000
36.8800 121.0000 1.0000
36.9200 112.0000 1.0000
36.9600 130.0000 1.0000
37.0000 131.0000 1.0000
37.0400 115.0000 1.0000
37.0800 121.0000 1.0000
37.1200 126.0000 1.0000
37.1600 127.0000 1.0000
37.2000 129.0000 1.0000
37.2400 145.0000 1.0000
37.2800 124.0000 1.0000
37.3200 139.0000 1.0000
37.3600 145.0000 1.0000
37.4000 123.0000 1.0000
37.4400 135.0000 1.0000
37.4800 128.0000 1.0000
37.5200 170.0000 1.0000
37.5600 152.0000 1.0000
37.6000 162.0000 1.0000
37.6400 171.0000 1.0000
37.6800 188.0000 1.0000
37.7200 208.0000 1.0000
37.7600 162.0000 1.0000
37.8000 227.0000 1.0000
37.8400 242.0000 1.0000
37.8800 186.0000 1.0000
37.9200 202.0000 1.0000
37.9600 162.0000 1.0000
38.0000 131.0000 1.0000
38.0400 138.0000 1.0000
38.0800 133.0000 1.0000
38.1200 111.0000 1.0000
38.1600 130.0000 1.0000
38.2000 133.0000 1.0000
38.2400 126.0000 1.0000
38.2800 139.0000 1.0000
38.3200 137.0000 1.0000
38.3600 127.0000 1.0000
38.4000 99.0000 1.0000
38.4400 137.0000 1.0000
38.4800 133.0000 1.0000
38.5200 108.0000 1.0000
38.5600 138.0000 1.0000
38.6000 117.0000 1.0000
38.6400 139.0000 1.0000
38.6800 113.0000 1.0000
38.7200 125.0000 1.0000
38.7600 107.0000 1.0000
38.8000 111.0000 1.0000
38.8400 123.0000 1.0000
38.8800 144.0000 1.0000
38.9200 119.0000 1.0000
38.9600 109.0000 1.0000
39.0000 127.0000 1.0000
39.0400 112.0000 1.0000
39.0800 120.0000 1.0000
39.1200 130.0000 1.0000
39.1600 118.0000 1.0000
39.2000 129.0000 1.0000
39.2400 100.0000 1.0000
39.2800 127.0000 1.0000
39.3200 128.0000 1.0000
39.3600 98.0000 1.0000
39.4000 118.0000 1.0000
39.4400 128.0000 1.0000
39.4800 114.0000 1.0000
39.5200 118.0000 1.0000
39.5600 102.0000 1.0000
39.6000 110.0000 1.0000
39.6400 128.0000 1.0000
39.6800 119.0000 1.0000
39.7200 115.0000 1.0000
39.7600 107.0000 1.0000
39.8000 117.0000 1.0000
39.8400 105.0000 1.0000
39.8800 110.0000 1.0000
39.9200 103.0000 1.0000
39.9600 109.0000 1.0000
40.0000 99.0000 1.0000
40.0400 120.0000 1.0000
40.0800 117.0000 1.0000
40.1200 99.0000 1.0000
40.1600 94.0000 1.0000
40.2000 103.0000 1.0000
40.2400 111.0000 1.0000
40.2800 116.0000 1.0000
40.3200 101.0000 1.0000
40.3600 89.0000 1.0000
40.4000 88.0000 1.0000
40.4400 114.0000 1.0000
40.4800 95.0000 1.0000
40.5200 101.0000 1.0000
40.5600 86.0000 1.0000
40.6000 110.0000 1.0000
40.6400 102.0000 1.0000
40.6800 87.0000 1.0000
40.7200 85.0000 1.0000
40.7600 85.0000 1.0000
40.8000 109.0000 1.0000
40.8400 94.0000 1.0000
40.8800 84.0000 1.0000
40.9200 106.0000 1.0000
40.9600 96.0000 1.0000
41.0000 96.0000 1.0000
41.0400 97.0000 1.0000
41.0800 102.0000 1.0000
41.1200 107.0000 1.0000
41.1600 110.0000 1.0000
41.2000 106.0000 1.0000
41.2400 95.0000 1.0000
41.2800 120.0000 1.0000
41.3200 97.0000 1.0000
41.3600 98.0000 1.0000
41.4000 92.0000 1.0000
41.4400 93.0000 1.0000
41.4800 104.0000 1.0000
41.5200 106.0000 1.0000
41.5600 101.0000 1.0000
41.6000 96.0000 1.0000
41.6400 104.0000 1.0000
41.6800 105.0000 1.0000
41.7200 107.0000 1.0000
41.7600 91.0000 1.0000
41.8000 104.0000 1.0000
41.8400 111.0000 1.0000
41.8800 115.0000 1.0000
41.9200 112.0000 1.0000
41.9600 107.0000 1.0000
42.0000 122.0000 1.0000
42.0400 108.0000 1.0000
42.0800 105.0000 1.0000
42.1200 109.0000 1.0000
42.1600 111.0000 1.0000
42.2000 90.0000 1.0000
42.2400 108.0000 1.0000
42.2800 95.0000 1.0000
42.3200 118.0000 1.0000
42.3600 112.0000 1.0000
42.4000 95.0000 1.0000
42.4400 105.0000 1.0000
42.4800 130.0000 1.0000
42.5200 123.0000 1.0000
42.5600 131.0000 1.0000
42.6000 109.0000 1.0000
42.6400 115.0000 1.0000
42.6800 96.0000 1.0000
42.7200 109.0000 1.0000
42.7600 108.0000 1.0000
42.8000 109.0000 1.0000
42.8400 96.0000 1.0000
42.8800 103.0000 1.0000
42.9200 107.0000 1.0000
42.9600 113.0000 1.0000
43.0000 88.0000 1.0000
43.0400 109.0000 1.0000
43.0800 90.0000 1.0000
43.1200 115.0000 1.0000
43.1600 107.0000 1.0000
43.2000 97.0000 1.0000
43.2400 108.0000 1.0000
43.2800 98.0000 1.0000
43.3200 94.0000 1.0000
43.3600 109.0000 1.0000
43.4000 115.0000 1.0000
43.4400 110.0000 1.0000
43.4800 96.0000 1.0000
43.5200 116.0000 1.0000
43.5600 105.0000 1.0000
43.6000 85.0000 1.0000
43.6400 130.0000 1.0000
43.6800 106.0000 1.0000
43.7200 169.0000 1.0000
43.7600 175.0000 1.0000
43.8000 134.0000 1.0000
43.8400 153.0000 1.0000
43.8800 160.0000 1.0000
43.9200 113.0000 1.0000
43.9600 91.0000 1.0000
44.0000 104.0000 1.0000
44.0400 116.0000 1.0000
44.0800 114.0000 1.0000
44.1200 120.0000 1.0000
44.1600 100.0000 1.0000
44.2000 99.0000 1.0000
44.2400 93.0000 1.0000
44.2800 97.0000 1.0000
44.3200 118.0000 1.0000
44.3600 108.0000 1.0000
44.4000 92.0000 1.0000
44.4400 115.0000 1.0000
44.4800 81.0000 1.0000
44.5200 105.0000 1.0000
44.5600 91.0000 1.0000
44.6000 98.0000 1.0000
44.6400 105.0000 1.0000
44.6800 96.0000 1.0000
44.7200 109.0000 1.0000
44.7600 94.0000 1.0000
44.8000 81.0000 1.0000
44.8400 102.0000 1.0000
44.8800 104.0000 1.0000
44.9200 83.0000 1.0000
44.9600 112.0000 1.0000
45.0000 103.0000 1.0000
45.0400 106.0000 1.0000
45.0800 91.0000 1.0000
45.1200 99.0000 1.0000
45.1600 115.0000 1.0000
45.2000 109.0000 1.0000
45.2400 97.0000 1.0000
45.2800 103.0000 1.0000
45.3200 107.0000 1.0000
45.3600 88.0000 1.0000
45.4000 97.0000 1.0000
45.4400 84.0000 1.0000
45.4800 116.0000 1.0000
45.5200 104.0000 1.0000
45.5600 96.0000 1.0000
45.6000 92.0000 1.0000
45.6400 103.0000 1.0000
45.6800 94.0000 1.0000
45.7200 98.0000 1.0000
45.7600 78.0000 1.0000
45.8000 101.0000 1.0000
45.8400 95.0000 1.0000
45.8800 98.0000 1.0000
45.9200 125.0000 1.0000
45.9600 119.0000 1.0000
46.0000 94.0000 1.0000
46.0400 90.0000 1.0000
46.0800 88.0000 1.0000
46.1200 95.0000 1.0000
46.1600 105.0000 1.0000
46.2000 102.0000 1.0000
46.2400 103.0000 1.0000
46.2800 123.0000 1.0000
46.3200 124.0000 1.0000
46.3600 116.0000 1.0000
46.4000 98.0000 1.0000
46.4400 118.0000 1.0000
46.4800 122.0000 1.0000
46.5200 126.0000 1.0000
46.5600 109.0000 1.0000
46.6000 130.0000 1.0000
46.6400 143.0000 1.0000
46.6800 118.0000 1.0000
46.7200 117.0000 1.0000
46.7600 171.0000 1.0000
46.8000 299.0000 1.0000
46.8400 212.0000 1.0000
46.8800 125.0000 1.0000
46.9200 194.0000 1.0000
46.9600 147.0000 1.0000
47.0000 93.0000 1.0000
47.0400 107.0000 1.0000
47.0800 98.0000 1.0000
47.1200 87.0000 1.0000
47.1600 108.0000 1.0000
47.2000 86.0000 1.0000
47.2400 111.0000 1.0000
47.2800 84.0000 1.0000
47.3200 94.0000 1.0000
47.3600 80.0000 1.0000
47.4000 94.0000 1.0000
47.4400 83.0000 1.0000
47.4800 88.0000 1.0000
47.5200 99.0000 1.0000
47.5600 92.0000 1.0000
47.6000 92.0000 1.0000
47.6400 90.0000 1.0000
47.6800 94.0000 1.0000
47.7200 107.0000 1.0000
47.7600 82.0000 1.0000
47.8000 113.0000 1.0000
47.8400 88.0000 1.0000
47.8800 117.0000 1.0000
47.9200 98.0000 1.0000
47.9600 111.0000 1.0000
48.0000 114.0000 1.0000
48.0400 96.0000 1.0000
48.0800 107.0000 1.0000
48.1200 101.0000 1.0000
48.1600 92.0000 1.0000
48.2000 89.0000 1.0000
48.2400 97.0000 1.0000
48.2800 88.0000 1.0000
48.3200 93.0000 1.0000
48.3600 82.0000 1.0000
48.4000 73.0000 1.0000
48.4400 89.0000 1.0000
48.4800 91.0000 1.0000
48.5200 63.0000 1.0000
48.5600 110.0000 1.0000
48.6000 96.0000 1.0000
48.6400 88.0000 1.0000
48.6800 91.0000 1.0000
48.7200 88.0000 1.0000
48.7600 91.0000 1.0000
48.8000 87.0000 1.0000
48.8400 89.0000 1.0000
48.8800 70.0000 1.0000
48.9200 98.0000 1.0000
48.9600 70.0000 1.0000
49.0000 104.0000 1.0000
49.0400 98.0000 1.0000
49.0800 85.0000 1.0000
49.1200 83.0000 1.0000
49.1600 74.0000 1.0000
49.2000 83.0000 1.0000
49.2400 90.0000 1.0000
49.2800 85.0000 1.0000
49.3200 85.0000 1.0000
49.3600 78.0000 1.0000
49.4000 123.0000 1.0000
49.4400 114.0000 1.0000
49.4800 92.0000 1.0000
49.5200 114.0000 1.0000
49.5600 99.0000 1.0000
49.6000 116.0000 1.0000
49.6400 114.0000 1.0000
49.6800 88.0000 1.0000
49.7200 102.0000 1.0000
49.7600 92.0000 1.0000
49.8000 81.0000 1.0000
49.8400 85.0000 1.0000
49.8800 90.0000 1.0000
49.9200 72.0000 1.0000
49.9600 89.0000 1.0000
50.0000 87.0000 1.0000
50.0400 85.0000 1.0000
50.0800 89.0000 1.0000
50.1200 76.0000 1.0000
50.1600 93.0000 1.0000
50.2000 87.0000 1.0000
50.2400 87.0000 1.0000
50.2800 96.0000 1.0000
50.3200 85.0000 1.0000
50.3600 89.0000 1.0000
50.4000 83.0000 1.0000
50.4400 93.0000 1.0000
50.4800 80.0000 1.0000
50.5200 73.0000 1.0000
50.5600 84.0000 1.0000
50.6000 88.0000 1.0000
50.6400 91.0000 1.0000
50.6800 91.0000 1.0000
50.7200 99.0000 1.0000
50.7600 89.0000 1.0000
50.8000 93.0000 1.0000
50.8400 80.0000 1.0000
50.8800 96.0000 1.0000
50.9200 73.0000 1.0000
50.9600 75.0000 1.0000
51.0000 95.0000 1.0000
51.0400 73.0000 1.0000
51.0800 89.0000 1.0000
51.1200 99.0000 1.0000
51.1600 96.0000 1.0000
51.2000 89.0000 1.0000
51.2400 98.0000 1.0000
51.2800 99.0000 1.0000
51.3200 87.0000 1.0000
51.3600 79.0000 1.0000
51.4000 112.0000 1.0000
51.4400 85.0000 1.0000
51.4800 90.0000 1.0000
51.5200 94.0000 1.0000
51.5600 78.0000 1.0000
51.6000 94.0000 1.0000
51.6400 64.0000 1.0000
51.6800 79.0000 1.0000
51.7200 80.0000 1.0000
51.7600 91.0000 1.0000
51.8000 81.0000 1.0000
51.8400 91.0000 1.0000
51.8800 81.0000 1.0000
51.9200 90.0000 1.0000
51.9600 95.0000 1.0000
52.0000 79.0000 1.0000
52.0400 78.0000 1.0000
52.0800 78.0000 1.0000
52.1200 89.0000 1.0000
52.1600 97.0000 1.0000
52.2000 95.0000 1.0000
52.2400 105.0000 1.0000
52.2800 104.0000 1.0000
52.3200 95.0000 1.0000
52.3600 106.0000 1.0000
52.4000 84.0000 1.0000
52.4400 110.0000 1.0000
52.4800 93.0000 1.0000
52.5200 87.0000 1.0000
52.5600 72.0000 1.0000
52.6000 102.0000 1.0000
52.6400 88.0000 1.0000
52.6800 86.0000 1.0000
52.7200 86.0000 1.0000
52.7600 89.0000 1.0000
52.8000 81.0000 1.0000
52.8400 85.0000 1.0000
52.8800 82.0000 1.0000
52.9200 72.0000 1.0000
52.9600 93.0000 1.0000
53.0000 87.0000 1.0000
53.0400 95.0000 1.0000
53.0800 66.0000 1.0000
53.1200 89.0000 1.0000
53.1600 80.0000 1.0000
53.2000 104.0000 1.0000
53.2400 92.0000 1.0000
53.2800 88.0000 1.0000
53.3200 86.0000 1.0000
53.3600 81.0000 1.0000
53.4000 98.0000 1.0000
53.4400 88.0000 1.0000
53.4800 77.0000 1.0000
53.5200 88.0000 1.0000
53.5600 85.0000 1.0000
53.6000 80.0000 1.0000
53.6400 72.0000 1.0000
53.6800 93.0000 1.0000
53.7200 79.0000 1.0000
53.7600 99.0000 1.0000
53.8000 78.0000 1.0000
53.8400 91.0000 1.0000
53.8800 88.0000 1.0000
53.9200 81.0000 1.0000
53.9600 79.0000 1.0000
54.0000 94.0000 1.0000
54.0400 72.0000 1.0000
54.0800 92.0000 1.0000
54.1200 84.0000 1.0000
54.1600 104.0000 1.0000
54.2000 88.0000 1.0000
54.2400 117.0000 1.0000
54.2800 129.0000 1.0000
54.3200 118.0000 1.0000
54.3600 148.0000 1.0000
54.4000 153.0000 1.0000
54.4400 138.0000 1.0000
54.4800 225.0000 1.0000
54.5200 213.0000 1.0000
54.5600 153.0000 1.0000
54.6000 124.0000 1.0000
54.6400 163.0000 1.0000
54.6800 157.0000 1.0000
54.7200 86.0000 1.0000
54.7600 84.0000 1.0000
54.8000 103.0000 1.0000
54.8400 81.0000 1.0000
54.8800 106.0000 1.0000
54.9200 84.0000 1.0000
54.9600 77.0000 1.0000
55.0000 80.0000 1.0000
55.0400 73.0000 1.0000
55.0800 85.0000 1.0000
55.1200 93.0000 1.0000
55.1600 82.0000 1.0000
55.2000 91.0000 1.0000
55.2400 91.0000 1.0000
55.2800 92.0000 1.0000
55.3200 73.0000 1.0000
55.3600 74.0000 1.0000
55.4000 111.0000 1.0000
55.4400 86.0000 1.0000
55.4800 101.0000 1.0000
55.5200 91.0000 1.0000
55.5600 89.0000 1.0000
55.6000 85.0000 1.0000
55.6400 94.0000 1.0000
55.6800 84.0000 1.0000
55.7200 86.0000 1.0000
55.7600 94.0000 1.0000
55.8000 96.0000 1.0000
55.8400 68.0000 1.0000
55.8800 93.0000 1.0000
55.9200 100.0000 1.0000
55.9600 86.0000 1.0000
56.0000 87.0000 1.0000
56.0400 94.0000 1.0000
56.0800 71.0000 1.0000
56.1200 66.0000 1.0000
56.1600 79.0000 1.0000
56.2000 60.0000 1.0000
56.2400 83.0000 1.0000
56.2800 81.0000 1.0000
56.3200 82.0000 1.0000
56.3600 94.0000 1.0000
56.4000 85.0000 1.0000
56.4400 92.0000 1.0000
56.4800 73.0000 1.0000
56.5200 79.0000 1.0000
56.5600 83.0000 1.0000
56.6000 85.0000 1.0000
56.6400 87.0000 1.0000
56.6800 74.0000 1.0000
56.7200 91.0000 1.0000
56.7600 79.0000 1.0000
56.8000 77.0000 1.0000
56.8400 95.0000 1.0000
56.8800 78.0000 1.0000
56.9200 86.0000 1.0000
56.9600 79.0000 1.0000
57.0000 82.0000 1.0000
57.0400 69.0000 1.0000
57.0800 81.0000 1.0000
57.1200 80.0000 1.0000
57.1600 81.0000 1.0000
57.2000 114.0000 1.0000
57.2400 99.0000 1.0000
57.2800 76.0000 1.0000
57.3200 96.0000 1.0000
57.3600 75.0000 1.0000
57.4000 84.0000 1.0000
57.4400 62.0000 1.0000
57.4800 95.0000 1.0000
57.5200 90.0000 1.0000
57.5600 85.0000 1.0000
57.6000 81.0000 1.0000
57.6400 69.0000 1.0000
57.6800 70.0000 1.0000
57.7200 87.0000 1.0000
57.7600 80.0000 1.0000
57.8000 73.0000 1.0000
57.8400 82.0000 1.0000
57.8800 90.0000 1.0000
57.9200 68.0000 1.0000
57.9600 67.0000 1.0000
58.0000 66.0000 1.0000
58.0400 99.0000 1.0000
58.0800 80.0000 1.0000
58.1200 81.0000 1.0000
58.1600 88.0000 1.0000
58.2000 86.0000 1.0000
58.2400 77.0000 1.0000
58.2800 86.0000 1.0000
58.3200 84.0000 1.0000
58.3600 91.0000 1.0000
58.4000 76.0000 1.0000
58.4400 88.0000 1.0000
58.4800 92.0000 1.0000
58.5200 72.0000 1.0000
58.5600 67.0000 1.0000
58.6000 82.0000 1.0000
58.6400 95.0000 1.0000
58.6800 82.0000 1.0000
58.7200 100.0000 1.0000
58.7600 76.0000 1.0000
58.8000 92.0000 1.0000
58.8400 96.0000 1.0000
58.8800 92.0000 1.0000
58.9200 79.0000 1.0000
58.9600 94.0000 1.0000
59.0000 103.0000 1.0000
59.0400 95.0000 1.0000
59.0800 80.0000 1.0000
59.1200 82.0000 1.0000
59.1600 99.0000 1.0000
59.2000 65.0000 1.0000
59.2400 98.0000 1.0000
59.2800 93.0000 1.0000
59.3200 90.0000 1.0000
59.3600 101.0000 1.0000
59.4000 86.0000 1.0000
59.4400 94.0000 1.0000
59.4800 110.0000 1.0000
59.5200 105.0000 1.0000
59.5600 92.0000 1.0000
59.6000 98.0000 1.0000
59.6400 88.0000 1.0000
59.6800 104.0000 1.0000
59.7200 83.0000 1.0000
59.7600 76.0000 1.0000
59.8000 85.0000 1.0000
59.8400 75.0000 1.0000
59.8800 72.0000 1.0000
59.9200 85.0000 1.0000
59.9600 81.0000 1.0000
60.0000 77.0000 1.0000
*RAS_INT_END
*RAS_TEMPERATURE_START
*RAS_TEMPERATURE_END
*RAS_DATA_END