File: FrgTools/Example Notebooks/Smartlab XRD Processing/Data/CsPbF3_AF.ras
*RAS_DATA_START
*RAS_HEADER_START
*DISP_FMT_X "%.2f"
*DISP_FMT_Y "%.0f"
*DISP_FULLSCALE "329.5000000000"
*DISP_LINE_COLOR "255.0000000000"
*DISP_LINE_STYLE "0.0000000000"
*DISP_LINE_WIDTH "0.2500000000"
*DISP_NOTE "Collected Data-8"
*DISP_OFFSET_Y "0.0000000000"
*DISP_PEAKSEARCH_UNIT_Y "cps"
*DISP_RANGE_BOTTOM "0.0000000000"
*DISP_RANGE_LEFT "15.0000000000"
*DISP_RANGE_LOGCUTOFF "0.0100000000"
*DISP_RANGE_RIGHT "90.0000000000"
*DISP_RANGE_TOP "329.5000000000"
*DISP_SCALE_MODE_Y "0.0000000000"
*DISP_TAB_NAME "Theta/2-Theta"
*DISP_TITLE_Y "Intensity"
*DISP_UNIT_Y "cps"
*DISP_WINDOW_NAME "MSG_MACROENGINE"
*FILE_COMMENT " "
*FILE_MD5 ""
*FILE_MEMO " "
*FILE_OPERATOR "qmtlab"
*FILE_PART_ID "MEAS_KHP2_00068"
*FILE_SAMPLE " "
*FILE_TYPE "RAS_RAW"
*FILE_USERGROUP "System Manager"
*FILE_VERSION "1.0000000000"
*HW_ATTACHMENT_ID "ATT0022"
*HW_ATTACHMENT_NAME "RxRy|RxRy"
*HW_COUNTER_ID-0 "CUT0021"
*HW_COUNTER_ID-1 "CUT0020"
*HW_COUNTER_ID-2 ""
*HW_COUNTER_ID-3 "CSL0021"
*HW_COUNTER_ID-4 "CMC0021"
*HW_COUNTER_NAME-0 "SC-70|SC-70"
*HW_COUNTER_NAME-1 "None|None"
*HW_COUNTER_NAME-2 ""
*HW_COUNTER_NAME-3 "BBM|BBM"
*HW_COUNTER_NAME-4 "検出器モノクロメータ|Detector monochromator"
*HW_COUNTER_SELECT_NAME "SC-70|SC-70"
*HW_ECP_HV "655.5000000000"
*HW_ECP_HV_UNIT "V"
*HW_GONIOMETER_ID "GON0024"
*HW_GONIOMETER_NAME "SmartLab(In-plane)|SmartLab(In-plane)"
*HW_GONIOMETER_RADIUS-0 "90.0"
*HW_GONIOMETER_RADIUS-1 "114.0"
*HW_GONIOMETER_RADIUS-2 "190.0"
*HW_GONIOMETER_RADIUS-3 "300.0"
*HW_GONIOMETER_RADIUS-4 "187.0"
*HW_GONIOMETER_RADIUS-5 "300.0"
*HW_GONIOMETER_RADIUS-6 "113.0"
*HW_GONIOMETER_RADIUS-7 "331.0"
*HW_I_OPT_ID-0 "CBO0021"
*HW_I_OPT_ID-1 "ICR0023"
*HW_I_OPT_ID-2 "ISL0021"
*HW_I_OPT_ID-3 "ISO0021"
*HW_I_OPT_ID-4 "IAD0021"
*HW_I_OPT_ID-5 "IPR0001"
*HW_I_OPT_NAME-0 "CBOユニット|CBO unit"
*HW_I_OPT_NAME-1 "標準入射光学ユニット|Standard incident optical unit"
*HW_I_OPT_NAME-2 "標準入射スリットボックス|Standard incident slit box"
*HW_I_OPT_NAME-3 "入射平行スリット|Incident parallel slit"
*HW_I_OPT_NAME-4 "長手制限スリット|Length limiting slit"
*HW_I_OPT_NAME-5 "None|None"
*HW_R_ATTENUATER_AUTOMODE "0"
*HW_R_OPT_ID-0 "RSS0021"
*HW_R_OPT_ID-1 "RCR0022"
*HW_R_OPT_ID-2 "RSO0021"
*HW_R_OPT_ID-3 "RRS0021"
*HW_R_OPT_ID-4 "ATN0021"
*HW_R_OPT_ID-5 "RFL0021"
*HW_R_OPT_ID-6 "RAD0021"
*HW_R_OPT_NAME-0 "標準受光スリットボックス1|Standard receiving slit box # 1"
*HW_R_OPT_NAME-1 "標準受光光学ユニット1|Standard receiving unit # 1"
*HW_R_OPT_NAME-2 "標準受光光学ユニット2|Standard receiving optical unit # 2"
*HW_R_OPT_NAME-3 "標準受光スリットボックス2|Standard receiving slit box # 2"
*HW_R_OPT_NAME-4 "標準アッテネータ|Standard Attenuator"
*HW_R_OPT_NAME-5 "Cu Kβ|Cu K-beta"
*HW_R_OPT_NAME-6 "調整用受光スリット|Alignment receiving slit"
*HW_SAMPLE_HOLDER_ID "SMP0026"
*HW_SAMPLE_HOLDER_NAME "Z-φステージ|Z-Phi Stage"
*HW_XG_CURRENT_MAX "50"
*HW_XG_CURRENT_MIN "2"
*HW_XG_CURRENT_RESOLUTION "2"
*HW_XG_CURRENT_UNIT "mA"
*HW_XG_FOCUS "1mm x 10mm"
*HW_XG_FOCUS_TYPE "Normal"
*HW_XG_ID ""
*HW_XG_NAME "3kW 封入管(ID:1200)|3kW Sealed tube(ID:1200)"
*HW_XG_TARGET_ATOMIC_NUMBER "29.0000000000"
*HW_XG_TARGET_NAME "Cu"
*HW_XG_TYPE "Hermetic"
*HW_XG_VOLTAGE_MAX "60"
*HW_XG_VOLTAGE_MIN "20"
*HW_XG_VOLTAGE_RESOLUTION "2"
*HW_XG_VOLTAGE_UNIT "kV"
*HW_XG_WATT_MAX "2"
*HW_XG_WATT_UNIT "kW"
*HW_XG_WAVE_LENGTH_ALPHA1 "1.540593"
*HW_XG_WAVE_LENGTH_ALPHA2 "1.544414"
*HW_XG_WAVE_LENGTH_BETA "1.392250"
*MEAS_COND_AXIS_NAME-0 "Theta/2-Theta"
*MEAS_COND_AXIS_NAME-1 "2-Theta"
*MEAS_COND_AXIS_NAME-2 "Omega"
*MEAS_COND_AXIS_NAME-3 "Phi"
*MEAS_COND_AXIS_NAME-4 "Z"
*MEAS_COND_AXIS_NAME-5 "Rx"
*MEAS_COND_AXIS_NAME-6 "Ry"
*MEAS_COND_AXIS_NAME-7 "2-Theta/Omega"
*MEAS_COND_AXIS_NAME-8 "2-ThetaChi"
*MEAS_COND_AXIS_NAME-9 "2-ThetaChi/Phi"
*MEAS_COND_AXIS_NAME-10 "Alpha"
*MEAS_COND_AXIS_NAME-11 "Beta"
*MEAS_COND_AXIS_NAME-12 "Theta_s"
*MEAS_COND_AXIS_NAME-13 "Theta_d"
*MEAS_COND_AXIS_NAME-14 "Ts"
*MEAS_COND_AXIS_NAME-15 "CBO selection slit"
*MEAS_COND_AXIS_NAME-16 "M"
*MEAS_COND_AXIS_NAME-17 "Incident parallel slit"
*MEAS_COND_AXIS_NAME-18 "Incident slit"
*MEAS_COND_AXIS_NAME-19 ""
*MEAS_COND_AXIS_NAME-20 "Zs"
*MEAS_COND_AXIS_NAME-21 "Incident monochromator"
*MEAS_COND_AXIS_NAME-22 "Length limiting slit"
*MEAS_COND_AXIS_NAME-23 "Center slit"
*MEAS_COND_AXIS_NAME-24 "Filter"
*MEAS_COND_AXIS_NAME-25 "Receiving slit # 1"
*MEAS_COND_AXIS_NAME-26 "Receiving slit # 2"
*MEAS_COND_AXIS_NAME-27 "Receiving optical device"
*MEAS_COND_AXIS_NAME-28 "Receiving parallel slit"
*MEAS_COND_AXIS_NAME-29 "Alignment receiving slit"
*MEAS_COND_AXIS_NAME-30 ""
*MEAS_COND_AXIS_NAME-31 ""
*MEAS_COND_AXIS_NAME-32 "Zd"
*MEAS_COND_AXIS_NAME-33 "Attenuator"
*MEAS_COND_AXIS_NAME-34 "Diffracted beam monochromator"
*MEAS_COND_AXIS_NAME-35 "Monochromator slit"
*MEAS_COND_AXIS_NAME-36 "2-ThetaB"
*MEAS_COND_AXIS_NAME-37 "Primary beam"
*MEAS_COND_AXIS_NAME-38 "HV"
*MEAS_COND_AXIS_NAME-39 "PHA"
*MEAS_COND_AXIS_NAME_INTERNAL-0 "TwoThetaTheta"
*MEAS_COND_AXIS_NAME_INTERNAL-1 "TwoTheta"
*MEAS_COND_AXIS_NAME_INTERNAL-2 "Omega"
*MEAS_COND_AXIS_NAME_INTERNAL-3 "Phi"
*MEAS_COND_AXIS_NAME_INTERNAL-4 "Z"
*MEAS_COND_AXIS_NAME_INTERNAL-5 "Rx"
*MEAS_COND_AXIS_NAME_INTERNAL-6 "Ry"
*MEAS_COND_AXIS_NAME_INTERNAL-7 "TwoThetaOmega"
*MEAS_COND_AXIS_NAME_INTERNAL-8 "TwoThetaChi"
*MEAS_COND_AXIS_NAME_INTERNAL-9 "TwoThetaChiPhi"
*MEAS_COND_AXIS_NAME_INTERNAL-10 "Alpha"
*MEAS_COND_AXIS_NAME_INTERNAL-11 "Beta"
*MEAS_COND_AXIS_NAME_INTERNAL-12 "ThetaS"
*MEAS_COND_AXIS_NAME_INTERNAL-13 "ThetaD"
*MEAS_COND_AXIS_NAME_INTERNAL-14 "Ts"
*MEAS_COND_AXIS_NAME_INTERNAL-15 "CBO"
*MEAS_COND_AXIS_NAME_INTERNAL-16 "CBO-M"
*MEAS_COND_AXIS_NAME_INTERNAL-17 "IncidentSollerSlit"
*MEAS_COND_AXIS_NAME_INTERNAL-18 "IncidentSlitBox"
*MEAS_COND_AXIS_NAME_INTERNAL-19 "IncidentSlitBox-_Axis"
*MEAS_COND_AXIS_NAME_INTERNAL-20 "Zs"
*MEAS_COND_AXIS_NAME_INTERNAL-21 "IncidentMonochromator"
*MEAS_COND_AXIS_NAME_INTERNAL-22 "IncidentAxdSlit"
*MEAS_COND_AXIS_NAME_INTERNAL-23 "CenterSlit"
*MEAS_COND_AXIS_NAME_INTERNAL-24 "Filter"
*MEAS_COND_AXIS_NAME_INTERNAL-25 "ReceivingSlitBox1"
*MEAS_COND_AXIS_NAME_INTERNAL-26 "ReceivingSlitBox2"
*MEAS_COND_AXIS_NAME_INTERNAL-27 "ReceivingOptics"
*MEAS_COND_AXIS_NAME_INTERNAL-28 "ReceivingSollerSlit"
*MEAS_COND_AXIS_NAME_INTERNAL-29 "ReceivingAxdSlit"
*MEAS_COND_AXIS_NAME_INTERNAL-30 "ReceivingSlitBox1-_Axis"
*MEAS_COND_AXIS_NAME_INTERNAL-31 "ReceivingSlitBox2-_Axis"
*MEAS_COND_AXIS_NAME_INTERNAL-32 "ReceivingSlitBox2-Zd"
*MEAS_COND_AXIS_NAME_INTERNAL-33 "Attenuator"
*MEAS_COND_AXIS_NAME_INTERNAL-34 "CounterMonochromator"
*MEAS_COND_AXIS_NAME_INTERNAL-35 "CounterSlit"
*MEAS_COND_AXIS_NAME_INTERNAL-36 "TwoThetaB"
*MEAS_COND_AXIS_NAME_INTERNAL-37 "IncidentPrimary"
*MEAS_COND_AXIS_NAME_INTERNAL-38 "HV"
*MEAS_COND_AXIS_NAME_INTERNAL-39 "PHA"
*MEAS_COND_AXIS_NAME_MAGICNO-0 "83951616.0000000000"
*MEAS_COND_AXIS_NAME_MAGICNO-1 "268632064.0000000000"
*MEAS_COND_AXIS_NAME_MAGICNO-2 "268500992.0000000000"
*MEAS_COND_AXIS_NAME_MAGICNO-3 "268500992.0000000000"
*MEAS_COND_AXIS_NAME_MAGICNO-4 "285278208.0000000000"
*MEAS_COND_AXIS_NAME_MAGICNO-5 "285278208.0000000000"
*MEAS_COND_AXIS_NAME_MAGICNO-6 "285278208.0000000000"
*MEAS_COND_AXIS_NAME_MAGICNO-7 "83951616.0000000000"
*MEAS_COND_AXIS_NAME_MAGICNO-8 "268632064.0000000000"
*MEAS_COND_AXIS_NAME_MAGICNO-9 "83951616.0000000000"
*MEAS_COND_AXIS_NAME_MAGICNO-10 "17039360.0000000000"
*MEAS_COND_AXIS_NAME_MAGICNO-11 "17039360.0000000000"
*MEAS_COND_AXIS_NAME_MAGICNO-12 "131072.0000000000"
*MEAS_COND_AXIS_NAME_MAGICNO-13 "131072.0000000000"
*MEAS_COND_AXIS_NAME_MAGICNO-14 "318898176.0000000000"
*MEAS_COND_AXIS_NAME_MAGICNO-15 "20971521.0000000000"
*MEAS_COND_AXIS_NAME_MAGICNO-16 "285343744.0000000000"
*MEAS_COND_AXIS_NAME_MAGICNO-17 "20971521.0000000000"
*MEAS_COND_AXIS_NAME_MAGICNO-18 "22020097.0000000000"
*MEAS_COND_AXIS_NAME_MAGICNO-19 "25165824.0000000000"
*MEAS_COND_AXIS_NAME_MAGICNO-20 "318898176.0000000000"
*MEAS_COND_AXIS_NAME_MAGICNO-21 "1.0000000000"
*MEAS_COND_AXIS_NAME_MAGICNO-22 "20971521.0000000000"
*MEAS_COND_AXIS_NAME_MAGICNO-23 "20971521.0000000000"
*MEAS_COND_AXIS_NAME_MAGICNO-24 "20971521.0000000000"
*MEAS_COND_AXIS_NAME_MAGICNO-25 "23068673.0000000000"
*MEAS_COND_AXIS_NAME_MAGICNO-26 "23068673.0000000000"
*MEAS_COND_AXIS_NAME_MAGICNO-27 "20971521.0000000000"
*MEAS_COND_AXIS_NAME_MAGICNO-28 "20971521.0000000000"
*MEAS_COND_AXIS_NAME_MAGICNO-29 "20971521.0000000000"
*MEAS_COND_AXIS_NAME_MAGICNO-30 "25165824.0000000000"
*MEAS_COND_AXIS_NAME_MAGICNO-31 "25165824.0000000000"
*MEAS_COND_AXIS_NAME_MAGICNO-32 "285343744.0000000000"
*MEAS_COND_AXIS_NAME_MAGICNO-33 "17301505.0000000000"
*MEAS_COND_AXIS_NAME_MAGICNO-34 "20971521.0000000000"
*MEAS_COND_AXIS_NAME_MAGICNO-35 "20971521.0000000000"
*MEAS_COND_AXIS_NAME_MAGICNO-36 "17039360.0000000000"
*MEAS_COND_AXIS_NAME_MAGICNO-37 "20971521.0000000000"
*MEAS_COND_AXIS_NAME_MAGICNO-38 "0.0000000000"
*MEAS_COND_AXIS_NAME_MAGICNO-39 "0.0000000000"
*MEAS_COND_AXIS_OFFSET-0 "-"
*MEAS_COND_AXIS_OFFSET-1 "0.0743000000"
*MEAS_COND_AXIS_OFFSET-2 "-0.2477000000"
*MEAS_COND_AXIS_OFFSET-3 "0.0000000000"
*MEAS_COND_AXIS_OFFSET-4 "-"
*MEAS_COND_AXIS_OFFSET-5 "-"
*MEAS_COND_AXIS_OFFSET-6 "-"
*MEAS_COND_AXIS_OFFSET-7 "-"
*MEAS_COND_AXIS_OFFSET-8 "0.0000000000"
*MEAS_COND_AXIS_OFFSET-9 "-"
*MEAS_COND_AXIS_OFFSET-10 "-"
*MEAS_COND_AXIS_OFFSET-11 "-"
*MEAS_COND_AXIS_OFFSET-12 "-0.2477000000"
*MEAS_COND_AXIS_OFFSET-13 "0.3220000000"
*MEAS_COND_AXIS_OFFSET-14 "-"
*MEAS_COND_AXIS_OFFSET-15 "-"
*MEAS_COND_AXIS_OFFSET-16 "-"
*MEAS_COND_AXIS_OFFSET-17 "-"
*MEAS_COND_AXIS_OFFSET-18 "-"
*MEAS_COND_AXIS_OFFSET-19 "-"
*MEAS_COND_AXIS_OFFSET-20 "-"
*MEAS_COND_AXIS_OFFSET-21 "-"
*MEAS_COND_AXIS_OFFSET-22 "-"
*MEAS_COND_AXIS_OFFSET-23 "-"
*MEAS_COND_AXIS_OFFSET-24 "-"
*MEAS_COND_AXIS_OFFSET-25 "-"
*MEAS_COND_AXIS_OFFSET-26 "-"
*MEAS_COND_AXIS_OFFSET-27 "-"
*MEAS_COND_AXIS_OFFSET-28 "-"
*MEAS_COND_AXIS_OFFSET-29 "-"
*MEAS_COND_AXIS_OFFSET-30 "-"
*MEAS_COND_AXIS_OFFSET-31 "-"
*MEAS_COND_AXIS_OFFSET-32 "-"
*MEAS_COND_AXIS_OFFSET-33 "-"
*MEAS_COND_AXIS_OFFSET-34 "-"
*MEAS_COND_AXIS_OFFSET-35 "-"
*MEAS_COND_AXIS_OFFSET-36 "-"
*MEAS_COND_AXIS_OFFSET-37 "-"
*MEAS_COND_AXIS_OFFSET-38 "-"
*MEAS_COND_AXIS_OFFSET-39 "-"
*MEAS_COND_AXIS_POSITION-0 "0.0000000000"
*MEAS_COND_AXIS_POSITION-1 "0.0000000000"
*MEAS_COND_AXIS_POSITION-2 "0.0000000000"
*MEAS_COND_AXIS_POSITION-3 "0.0000000000"
*MEAS_COND_AXIS_POSITION-4 "-0.3500000000"
*MEAS_COND_AXIS_POSITION-5 "0.0000000000"
*MEAS_COND_AXIS_POSITION-6 "0.0000000000"
*MEAS_COND_AXIS_POSITION-7 "0.0000000000"
*MEAS_COND_AXIS_POSITION-8 "0.0000000000"
*MEAS_COND_AXIS_POSITION-9 "0.0000000000"
*MEAS_COND_AXIS_POSITION-10 "90.0000000000"
*MEAS_COND_AXIS_POSITION-11 "0.0000000000"
*MEAS_COND_AXIS_POSITION-12 "0.0000000000"
*MEAS_COND_AXIS_POSITION-13 "0.0000000000"
*MEAS_COND_AXIS_POSITION-14 "-0.7132500000"
*MEAS_COND_AXIS_POSITION-15 "BB"
*MEAS_COND_AXIS_POSITION-16 "0.0000000000"
*MEAS_COND_AXIS_POSITION-17 "Soller_slit_5.0deg"
*MEAS_COND_AXIS_POSITION-18 "1/2deg"
*MEAS_COND_AXIS_POSITION-19 "1.6581000000"
*MEAS_COND_AXIS_POSITION-20 "-0.2062500000"
*MEAS_COND_AXIS_POSITION-21 "0.0000000000"
*MEAS_COND_AXIS_POSITION-22 "2.0mm"
*MEAS_COND_AXIS_POSITION-23 "None"
*MEAS_COND_AXIS_POSITION-24 "Cu_K-beta"
*MEAS_COND_AXIS_POSITION-25 "1/2deg"
*MEAS_COND_AXIS_POSITION-26 "0.300mm"
*MEAS_COND_AXIS_POSITION-27 "PSA_open"
*MEAS_COND_AXIS_POSITION-28 "Soller_slit_5.0deg"
*MEAS_COND_AXIS_POSITION-29 "None"
*MEAS_COND_AXIS_POSITION-30 "0.9862000000"
*MEAS_COND_AXIS_POSITION-31 "0.3000000000"
*MEAS_COND_AXIS_POSITION-32 "0.4228100000"
*MEAS_COND_AXIS_POSITION-33 "Open"
*MEAS_COND_AXIS_POSITION-34 "None"
*MEAS_COND_AXIS_POSITION-35 "None"
*MEAS_COND_AXIS_POSITION-36 "0.0000000000"
*MEAS_COND_AXIS_POSITION-37 "None"
*MEAS_COND_AXIS_POSITION-38 "655.5000000000"
*MEAS_COND_AXIS_POSITION-39 "526.2500000000"
*MEAS_COND_AXIS_UNIT-0 "deg"
*MEAS_COND_AXIS_UNIT-1 "deg"
*MEAS_COND_AXIS_UNIT-2 "deg"
*MEAS_COND_AXIS_UNIT-3 "deg"
*MEAS_COND_AXIS_UNIT-4 "mm"
*MEAS_COND_AXIS_UNIT-5 "deg"
*MEAS_COND_AXIS_UNIT-6 "deg"
*MEAS_COND_AXIS_UNIT-7 "deg"
*MEAS_COND_AXIS_UNIT-8 "deg"
*MEAS_COND_AXIS_UNIT-9 "deg"
*MEAS_COND_AXIS_UNIT-10 "deg"
*MEAS_COND_AXIS_UNIT-11 "deg"
*MEAS_COND_AXIS_UNIT-12 "deg"
*MEAS_COND_AXIS_UNIT-13 "deg"
*MEAS_COND_AXIS_UNIT-14 "mm"
*MEAS_COND_AXIS_UNIT-15 ""
*MEAS_COND_AXIS_UNIT-16 "pulse"
*MEAS_COND_AXIS_UNIT-17 ""
*MEAS_COND_AXIS_UNIT-18 ""
*MEAS_COND_AXIS_UNIT-19 "mm"
*MEAS_COND_AXIS_UNIT-20 "mm"
*MEAS_COND_AXIS_UNIT-21 ""
*MEAS_COND_AXIS_UNIT-22 ""
*MEAS_COND_AXIS_UNIT-23 ""
*MEAS_COND_AXIS_UNIT-24 ""
*MEAS_COND_AXIS_UNIT-25 ""
*MEAS_COND_AXIS_UNIT-26 ""
*MEAS_COND_AXIS_UNIT-27 ""
*MEAS_COND_AXIS_UNIT-28 ""
*MEAS_COND_AXIS_UNIT-29 ""
*MEAS_COND_AXIS_UNIT-30 "mm"
*MEAS_COND_AXIS_UNIT-31 "mm"
*MEAS_COND_AXIS_UNIT-32 "mm"
*MEAS_COND_AXIS_UNIT-33 ""
*MEAS_COND_AXIS_UNIT-34 ""
*MEAS_COND_AXIS_UNIT-35 ""
*MEAS_COND_AXIS_UNIT-36 "deg"
*MEAS_COND_AXIS_UNIT-37 ""
*MEAS_COND_AXIS_UNIT-38 "V"
*MEAS_COND_AXIS_UNIT-39 "mV"
*MEAS_COND_COUNTER_CNTLOSS_CORR "1.0000000000"
*MEAS_COND_COUNTER_PHABASE "526.2500000000"
*MEAS_COND_COUNTER_PHAWINDOW "807.5000000000"
*MEAS_COND_COUNTER_PHA_UNIT "mV"
*MEAS_COND_COUNTER_TAUDIFF "0.1731010000"
*MEAS_COND_COUNTER_TAUINT "0.6617980000"
*MEAS_COND_IRRADIATION_MODE "OFF"
*MEAS_COND_IRRADIATION_WIDTH ""
*MEAS_COND_OPT_ATTR "Bragg-Brentano focusing"
*MEAS_COND_OPT_NAME "@BB focusing"
*MEAS_COND_UNSYMMETRIC_MODE "OFF"
*MEAS_COND_XG_CURRENT "30.0000000000"
*MEAS_COND_XG_VOLTAGE "40.0000000000"
*MEAS_COND_XG_WAVE_TYPE "Ka"
*MEAS_DATA_COUNT "7501.0000000000"
*MEAS_SCAN_AXIS_X "Theta/2-Theta"
*MEAS_SCAN_AXIS_X_INTERNAL "TwoThetaTheta"
*MEAS_SCAN_END_TIME "07/16/19 18:36:37"
*MEAS_SCAN_MODE "CONTINUOUS"
*MEAS_SCAN_MONITOR "0"
*MEAS_SCAN_RESOLUTION_X "0.0002"
*MEAS_SCAN_SPEED "0.250000"
*MEAS_SCAN_SPEED_UNIT "deg/min"
*MEAS_SCAN_SPEED_USER "0.25"
*MEAS_SCAN_START "15.0000000000"
*MEAS_SCAN_START_TIME "07/16/19 13:36:21"
*MEAS_SCAN_STEP "0.0100000000"
*MEAS_SCAN_STOP "90.0000000000"
*MEAS_SCAN_UNIT_X "deg"
*MEAS_SCAN_UNIT_Y "counts"
*RAS_HEADER_END
*RAS_INT_START
15.0000 242.0000 1.0000
15.0600 251.0000 1.0000
15.1200 234.0000 1.0000
15.1800 277.0000 1.0000
15.2400 271.0000 1.0000
15.3000 240.0000 1.0000
15.3600 243.0000 1.0000
15.4200 265.0000 1.0000
15.4800 271.0000 1.0000
15.5400 281.0000 1.0000
15.6000 271.0000 1.0000
15.6600 248.0000 1.0000
15.7200 258.0000 1.0000
15.7800 269.0000 1.0000
15.8400 282.0000 1.0000
15.9000 278.0000 1.0000
15.9600 264.0000 1.0000
16.0200 251.0000 1.0000
16.0800 286.0000 1.0000
16.1400 272.0000 1.0000
16.2000 272.0000 1.0000
16.2600 301.0000 1.0000
16.3200 262.0000 1.0000
16.3800 279.0000 1.0000
16.4400 276.0000 1.0000
16.5000 275.0000 1.0000
16.5600 310.0000 1.0000
16.6200 277.0000 1.0000
16.6800 310.0000 1.0000
16.7400 290.0000 1.0000
16.8000 273.0000 1.0000
16.8600 291.0000 1.0000
16.9200 250.0000 1.0000
16.9800 300.0000 1.0000
17.0400 282.0000 1.0000
17.1000 294.0000 1.0000
17.1600 247.0000 1.0000
17.2200 273.0000 1.0000
17.2800 282.0000 1.0000
17.3400 302.0000 1.0000
17.4000 306.0000 1.0000
17.4600 293.0000 1.0000
17.5200 302.0000 1.0000
17.5800 304.0000 1.0000
17.6400 307.0000 1.0000
17.7000 285.0000 1.0000
17.7600 310.0000 1.0000
17.8200 289.0000 1.0000
17.8800 273.0000 1.0000
17.9400 292.0000 1.0000
18.0000 302.0000 1.0000
18.0600 299.0000 1.0000
18.1200 257.0000 1.0000
18.1800 283.0000 1.0000
18.2400 288.0000 1.0000
18.3000 337.0000 1.0000
18.3600 315.0000 1.0000
18.4200 334.0000 1.0000
18.4800 314.0000 1.0000
18.5400 329.0000 1.0000
18.6000 300.0000 1.0000
18.6600 297.0000 1.0000
18.7200 308.0000 1.0000
18.7800 275.0000 1.0000
18.8400 302.0000 1.0000
18.9000 263.0000 1.0000
18.9600 255.0000 1.0000
19.0200 292.0000 1.0000
19.0800 281.0000 1.0000
19.1400 250.0000 1.0000
19.2000 295.0000 1.0000
19.2600 256.0000 1.0000
19.3200 295.0000 1.0000
19.3800 245.0000 1.0000
19.4400 274.0000 1.0000
19.5000 248.0000 1.0000
19.5600 261.0000 1.0000
19.6200 227.0000 1.0000
19.6800 251.0000 1.0000
19.7400 274.0000 1.0000
19.8000 249.0000 1.0000
19.8600 233.0000 1.0000
19.9200 238.0000 1.0000
19.9800 242.0000 1.0000
20.0400 256.0000 1.0000
20.1000 251.0000 1.0000
20.1600 247.0000 1.0000
20.2200 256.0000 1.0000
20.2800 237.0000 1.0000
20.3400 256.0000 1.0000
20.4000 223.0000 1.0000
20.4600 239.0000 1.0000
20.5200 232.0000 1.0000
20.5800 236.0000 1.0000
20.6400 242.0000 1.0000
20.7000 241.0000 1.0000
20.7600 233.0000 1.0000
20.8200 215.0000 1.0000
20.8800 235.0000 1.0000
20.9400 221.0000 1.0000
21.0000 222.0000 1.0000
21.0600 215.0000 1.0000
21.1200 223.0000 1.0000
21.1800 240.0000 1.0000
21.2400 211.0000 1.0000
21.3000 210.0000 1.0000
21.3600 224.0000 1.0000
21.4200 232.0000 1.0000
21.4800 217.0000 1.0000
21.5400 214.0000 1.0000
21.6000 229.0000 1.0000
21.6600 178.0000 1.0000
21.7200 206.0000 1.0000
21.7800 203.0000 1.0000
21.8400 191.0000 1.0000
21.9000 210.0000 1.0000
21.9600 224.0000 1.0000
22.0200 195.0000 1.0000
22.0800 228.0000 1.0000
22.1400 181.0000 1.0000
22.2000 218.0000 1.0000
22.2600 201.0000 1.0000
22.3200 183.0000 1.0000
22.3800 197.0000 1.0000
22.4400 190.0000 1.0000
22.5000 194.0000 1.0000
22.5600 172.0000 1.0000
22.6200 188.0000 1.0000
22.6800 198.0000 1.0000
22.7400 181.0000 1.0000
22.8000 200.0000 1.0000
22.8600 219.0000 1.0000
22.9200 190.0000 1.0000
22.9800 199.0000 1.0000
23.0400 168.0000 1.0000
23.1000 175.0000 1.0000
23.1600 189.0000 1.0000
23.2200 180.0000 1.0000
23.2800 200.0000 1.0000
23.3400 180.0000 1.0000
23.4000 183.0000 1.0000
23.4600 208.0000 1.0000
23.5200 182.0000 1.0000
23.5800 189.0000 1.0000
23.6400 200.0000 1.0000
23.7000 177.0000 1.0000
23.7600 156.0000 1.0000
23.8200 173.0000 1.0000
23.8800 183.0000 1.0000
23.9400 175.0000 1.0000
24.0000 174.0000 1.0000
24.0600 202.0000 1.0000
24.1200 154.0000 1.0000
24.1800 177.0000 1.0000
24.2400 164.0000 1.0000
24.3000 169.0000 1.0000
24.3600 184.0000 1.0000
24.4200 183.0000 1.0000
24.4800 161.0000 1.0000
24.5400 168.0000 1.0000
24.6000 154.0000 1.0000
24.6600 165.0000 1.0000
24.7200 150.0000 1.0000
24.7800 152.0000 1.0000
24.8400 165.0000 1.0000
24.9000 152.0000 1.0000
24.9600 156.0000 1.0000
25.0200 172.0000 1.0000
25.0800 177.0000 1.0000
25.1400 156.0000 1.0000
25.2000 171.0000 1.0000
25.2600 152.0000 1.0000
25.3200 175.0000 1.0000
25.3800 173.0000 1.0000
25.4400 154.0000 1.0000
25.5000 164.0000 1.0000
25.5600 198.0000 1.0000
25.6200 187.0000 1.0000
25.6800 191.0000 1.0000
25.7400 184.0000 1.0000
25.8000 193.0000 1.0000
25.8600 181.0000 1.0000
25.9200 231.0000 1.0000
25.9800 291.0000 1.0000
26.0400 484.0000 1.0000
26.1000 624.0000 1.0000
26.1600 648.0000 1.0000
26.2200 539.0000 1.0000
26.2800 301.0000 1.0000
26.3400 227.0000 1.0000
26.4000 186.0000 1.0000
26.4600 170.0000 1.0000
26.5200 144.0000 1.0000
26.5800 129.0000 1.0000
26.6400 135.0000 1.0000
26.7000 132.0000 1.0000
26.7600 145.0000 1.0000
26.8200 136.0000 1.0000
26.8800 140.0000 1.0000
26.9400 140.0000 1.0000
27.0000 140.0000 1.0000
27.0600 143.0000 1.0000
27.1200 130.0000 1.0000
27.1800 126.0000 1.0000
27.2400 116.0000 1.0000
27.3000 123.0000 1.0000
27.3600 147.0000 1.0000
27.4200 128.0000 1.0000
27.4800 122.0000 1.0000
27.5400 105.0000 1.0000
27.6000 128.0000 1.0000
27.6600 111.0000 1.0000
27.7200 111.0000 1.0000
27.7800 137.0000 1.0000
27.8400 103.0000 1.0000
27.9000 110.0000 1.0000
27.9600 118.0000 1.0000
28.0200 132.0000 1.0000
28.0800 105.0000 1.0000
28.1400 136.0000 1.0000
28.2000 113.0000 1.0000
28.2600 135.0000 1.0000
28.3200 115.0000 1.0000
28.3800 117.0000 1.0000
28.4400 116.0000 1.0000
28.5000 123.0000 1.0000
28.5600 115.0000 1.0000
28.6200 114.0000 1.0000
28.6800 120.0000 1.0000
28.7400 102.0000 1.0000
28.8000 106.0000 1.0000
28.8600 112.0000 1.0000
28.9200 96.0000 1.0000
28.9800 103.0000 1.0000
29.0400 94.0000 1.0000
29.1000 103.0000 1.0000
29.1600 105.0000 1.0000
29.2200 116.0000 1.0000
29.2800 115.0000 1.0000
29.3400 87.0000 1.0000
29.4000 100.0000 1.0000
29.4600 82.0000 1.0000
29.5200 93.0000 1.0000
29.5800 125.0000 1.0000
29.6400 136.0000 1.0000
29.7000 125.0000 1.0000
29.7600 106.0000 1.0000
29.8200 102.0000 1.0000
29.8800 102.0000 1.0000
29.9400 90.0000 1.0000
30.0000 84.0000 1.0000
30.0600 96.0000 1.0000
30.1200 101.0000 1.0000
30.1800 101.0000 1.0000
30.2400 89.0000 1.0000
30.3000 95.0000 1.0000
30.3600 103.0000 1.0000
30.4200 82.0000 1.0000
30.4800 104.0000 1.0000
30.5400 80.0000 1.0000
30.6000 90.0000 1.0000
30.6600 75.0000 1.0000
30.7200 85.0000 1.0000
30.7800 84.0000 1.0000
30.8400 76.0000 1.0000
30.9000 78.0000 1.0000
30.9600 75.0000 1.0000
31.0200 83.0000 1.0000
31.0800 70.0000 1.0000
31.1400 93.0000 1.0000
31.2000 72.0000 1.0000
31.2600 70.0000 1.0000
31.3200 75.0000 1.0000
31.3800 84.0000 1.0000
31.4400 84.0000 1.0000
31.5000 89.0000 1.0000
31.5600 85.0000 1.0000
31.6200 72.0000 1.0000
31.6800 64.0000 1.0000
31.7400 63.0000 1.0000
31.8000 67.0000 1.0000
31.8600 67.0000 1.0000
31.9200 70.0000 1.0000
31.9800 90.0000 1.0000
32.0400 70.0000 1.0000
32.1000 72.0000 1.0000
32.1600 78.0000 1.0000
32.2200 71.0000 1.0000
32.2800 75.0000 1.0000
32.3400 62.0000 1.0000
32.4000 79.0000 1.0000
32.4600 67.0000 1.0000
32.5200 68.0000 1.0000
32.5800 74.0000 1.0000
32.6400 74.0000 1.0000
32.7000 60.0000 1.0000
32.7600 68.0000 1.0000
32.8200 73.0000 1.0000
32.8800 74.0000 1.0000
32.9400 55.0000 1.0000
33.0000 77.0000 1.0000
33.0600 60.0000 1.0000
33.1200 56.0000 1.0000
33.1800 65.0000 1.0000
33.2400 60.0000 1.0000
33.3000 66.0000 1.0000
33.3600 48.0000 1.0000
33.4200 68.0000 1.0000
33.4800 77.0000 1.0000
33.5400 67.0000 1.0000
33.6000 58.0000 1.0000
33.6600 86.0000 1.0000
33.7200 62.0000 1.0000
33.7800 53.0000 1.0000
33.8400 66.0000 1.0000
33.9000 71.0000 1.0000
33.9600 49.0000 1.0000
34.0200 54.0000 1.0000
34.0800 60.0000 1.0000
34.1400 85.0000 1.0000
34.2000 62.0000 1.0000
34.2600 57.0000 1.0000
34.3200 56.0000 1.0000
34.3800 79.0000 1.0000
34.4400 69.0000 1.0000
34.5000 74.0000 1.0000
34.5600 65.0000 1.0000
34.6200 66.0000 1.0000
34.6800 52.0000 1.0000
34.7400 54.0000 1.0000
34.8000 60.0000 1.0000
34.8600 45.0000 1.0000
34.9200 68.0000 1.0000
34.9800 68.0000 1.0000
35.0400 55.0000 1.0000
35.1000 63.0000 1.0000
35.1600 53.0000 1.0000
35.2200 59.0000 1.0000
35.2800 53.0000 1.0000
35.3400 51.0000 1.0000
35.4000 60.0000 1.0000
35.4600 63.0000 1.0000
35.5200 72.0000 1.0000
35.5800 58.0000 1.0000
35.6400 64.0000 1.0000
35.7000 56.0000 1.0000
35.7600 54.0000 1.0000
35.8200 53.0000 1.0000
35.8800 60.0000 1.0000
35.9400 55.0000 1.0000
36.0000 43.0000 1.0000
36.0600 63.0000 1.0000
36.1200 45.0000 1.0000
36.1800 50.0000 1.0000
36.2400 46.0000 1.0000
36.3000 49.0000 1.0000
36.3600 54.0000 1.0000
36.4200 43.0000 1.0000
36.4800 71.0000 1.0000
36.5400 48.0000 1.0000
36.6000 57.0000 1.0000
36.6600 60.0000 1.0000
36.7200 54.0000 1.0000
36.7800 67.0000 1.0000
36.8400 50.0000 1.0000
36.9000 72.0000 1.0000
36.9600 74.0000 1.0000
37.0200 61.0000 1.0000
37.0800 91.0000 1.0000
37.1400 114.0000 1.0000
37.2000 130.0000 1.0000
37.2600 175.0000 1.0000
37.3200 206.0000 1.0000
37.3800 210.0000 1.0000
37.4400 180.0000 1.0000
37.5000 116.0000 1.0000
37.5600 94.0000 1.0000
37.6200 64.0000 1.0000
37.6800 56.0000 1.0000
37.7400 77.0000 1.0000
37.8000 55.0000 1.0000
37.8600 56.0000 1.0000
37.9200 36.0000 1.0000
37.9800 71.0000 1.0000
38.0400 64.0000 1.0000
38.1000 61.0000 1.0000
38.1600 47.0000 1.0000
38.2200 62.0000 1.0000
38.2800 47.0000 1.0000
38.3400 47.0000 1.0000
38.4000 49.0000 1.0000
38.4600 56.0000 1.0000
38.5200 50.0000 1.0000
38.5800 42.0000 1.0000
38.6400 57.0000 1.0000
38.7000 47.0000 1.0000
38.7600 57.0000 1.0000
38.8200 46.0000 1.0000
38.8800 57.0000 1.0000
38.9400 56.0000 1.0000
39.0000 42.0000 1.0000
39.0600 40.0000 1.0000
39.1200 38.0000 1.0000
39.1800 59.0000 1.0000
39.2400 45.0000 1.0000
39.3000 42.0000 1.0000
39.3600 45.0000 1.0000
39.4200 59.0000 1.0000
39.4800 43.0000 1.0000
39.5400 40.0000 1.0000
39.6000 47.0000 1.0000
39.6600 46.0000 1.0000
39.7200 48.0000 1.0000
39.7800 48.0000 1.0000
39.8400 37.0000 1.0000
39.9000 35.0000 1.0000
39.9600 46.0000 1.0000
40.0200 40.0000 1.0000
40.0800 44.0000 1.0000
40.1400 43.0000 1.0000
40.2000 47.0000 1.0000
40.2600 50.0000 1.0000
40.3200 59.0000 1.0000
40.3800 46.0000 1.0000
40.4400 51.0000 1.0000
40.5000 50.0000 1.0000
40.5600 52.0000 1.0000
40.6200 43.0000 1.0000
40.6800 43.0000 1.0000
40.7400 41.0000 1.0000
40.8000 49.0000 1.0000
40.8600 45.0000 1.0000
40.9200 46.0000 1.0000
40.9800 36.0000 1.0000
41.0400 53.0000 1.0000
41.1000 54.0000 1.0000
41.1600 45.0000 1.0000
41.2200 51.0000 1.0000
41.2800 40.0000 1.0000
41.3400 49.0000 1.0000
41.4000 40.0000 1.0000
41.4600 55.0000 1.0000
41.5200 42.0000 1.0000
41.5800 48.0000 1.0000
41.6400 32.0000 1.0000
41.7000 49.0000 1.0000
41.7600 43.0000 1.0000
41.8200 58.0000 1.0000
41.8800 51.0000 1.0000
41.9400 63.0000 1.0000
42.0000 66.0000 1.0000
42.0600 60.0000 1.0000
42.1200 59.0000 1.0000
42.1800 55.0000 1.0000
42.2400 42.0000 1.0000
42.3000 51.0000 1.0000
42.3600 49.0000 1.0000
42.4200 56.0000 1.0000
42.4800 68.0000 1.0000
42.5400 67.0000 1.0000
42.6000 64.0000 1.0000
42.6600 52.0000 1.0000
42.7200 62.0000 1.0000
42.7800 33.0000 1.0000
42.8400 41.0000 1.0000
42.9000 32.0000 1.0000
42.9600 54.0000 1.0000
43.0200 45.0000 1.0000
43.0800 46.0000 1.0000
43.1400 38.0000 1.0000
43.2000 44.0000 1.0000
43.2600 39.0000 1.0000
43.3200 64.0000 1.0000
43.3800 41.0000 1.0000
43.4400 50.0000 1.0000
43.5000 35.0000 1.0000
43.5600 37.0000 1.0000
43.6200 44.0000 1.0000
43.6800 37.0000 1.0000
43.7400 46.0000 1.0000
43.8000 50.0000 1.0000
43.8600 61.0000 1.0000
43.9200 42.0000 1.0000
43.9800 44.0000 1.0000
44.0400 52.0000 1.0000
44.1000 40.0000 1.0000
44.1600 60.0000 1.0000
44.2200 40.0000 1.0000
44.2800 29.0000 1.0000
44.3400 60.0000 1.0000
44.4000 46.0000 1.0000
44.4600 54.0000 1.0000
44.5200 52.0000 1.0000
44.5800 41.0000 1.0000
44.6400 52.0000 1.0000
44.7000 34.0000 1.0000
44.7600 31.0000 1.0000
44.8200 59.0000 1.0000
44.8800 43.0000 1.0000
44.9400 49.0000 1.0000
45.0000 57.0000 1.0000
45.0600 44.0000 1.0000
45.1200 49.0000 1.0000
45.1800 35.0000 1.0000
45.2400 28.0000 1.0000
45.3000 39.0000 1.0000
45.3600 51.0000 1.0000
45.4200 48.0000 1.0000
45.4800 48.0000 1.0000
45.5400 35.0000 1.0000
45.6000 48.0000 1.0000
45.6600 42.0000 1.0000
45.7200 52.0000 1.0000
45.7800 54.0000 1.0000
45.8400 62.0000 1.0000
45.9000 77.0000 1.0000
45.9600 94.0000 1.0000
46.0200 141.0000 1.0000
46.0800 148.0000 1.0000
46.1400 218.0000 1.0000
46.2000 217.0000 1.0000
46.2600 173.0000 1.0000
46.3200 118.0000 1.0000
46.3800 107.0000 1.0000
46.4400 71.0000 1.0000
46.5000 62.0000 1.0000
46.5600 54.0000 1.0000
46.6200 50.0000 1.0000
46.6800 53.0000 1.0000
46.7400 48.0000 1.0000
46.8000 43.0000 1.0000
46.8600 55.0000 1.0000
46.9200 46.0000 1.0000
46.9800 42.0000 1.0000
47.0400 43.0000 1.0000
47.1000 40.0000 1.0000
47.1600 56.0000 1.0000
47.2200 49.0000 1.0000
47.2800 49.0000 1.0000
47.3400 48.0000 1.0000
47.4000 29.0000 1.0000
47.4600 40.0000 1.0000
47.5200 48.0000 1.0000
47.5800 37.0000 1.0000
47.6400 38.0000 1.0000
47.7000 34.0000 1.0000
47.7600 26.0000 1.0000
47.8200 41.0000 1.0000
47.8800 35.0000 1.0000
47.9400 35.0000 1.0000
48.0000 38.0000 1.0000
48.0600 47.0000 1.0000
48.1200 32.0000 1.0000
48.1800 56.0000 1.0000
48.2400 46.0000 1.0000
48.3000 30.0000 1.0000
48.3600 47.0000 1.0000
48.4200 47.0000 1.0000
48.4800 39.0000 1.0000
48.5400 46.0000 1.0000
48.6000 37.0000 1.0000
48.6600 33.0000 1.0000
48.7200 40.0000 1.0000
48.7800 31.0000 1.0000
48.8400 42.0000 1.0000
48.9000 52.0000 1.0000
48.9600 34.0000 1.0000
49.0200 41.0000 1.0000
49.0800 35.0000 1.0000
49.1400 39.0000 1.0000
49.2000 42.0000 1.0000
49.2600 37.0000 1.0000
49.3200 34.0000 1.0000
49.3800 38.0000 1.0000
49.4400 38.0000 1.0000
49.5000 28.0000 1.0000
49.5600 48.0000 1.0000
49.6200 32.0000 1.0000
49.6800 37.0000 1.0000
49.7400 37.0000 1.0000
49.8000 37.0000 1.0000
49.8600 32.0000 1.0000
49.9200 40.0000 1.0000
49.9800 31.0000 1.0000
50.0400 41.0000 1.0000
50.1000 46.0000 1.0000
50.1600 34.0000 1.0000
50.2200 46.0000 1.0000
50.2800 42.0000 1.0000
50.3400 42.0000 1.0000
50.4000 43.0000 1.0000
50.4600 48.0000 1.0000
50.5200 30.0000 1.0000
50.5800 45.0000 1.0000
50.6400 32.0000 1.0000
50.7000 33.0000 1.0000
50.7600 28.0000 1.0000
50.8200 44.0000 1.0000
50.8800 35.0000 1.0000
50.9400 46.0000 1.0000
51.0000 34.0000 1.0000
51.0600 33.0000 1.0000
51.1200 38.0000 1.0000
51.1800 35.0000 1.0000
51.2400 44.0000 1.0000
51.3000 38.0000 1.0000
51.3600 48.0000 1.0000
51.4200 41.0000 1.0000
51.4800 34.0000 1.0000
51.5400 37.0000 1.0000
51.6000 26.0000 1.0000
51.6600 30.0000 1.0000
51.7200 38.0000 1.0000
51.7800 30.0000 1.0000
51.8400 29.0000 1.0000
51.9000 41.0000 1.0000
51.9600 31.0000 1.0000
52.0200 28.0000 1.0000
52.0800 36.0000 1.0000
52.1400 40.0000 1.0000
52.2000 46.0000 1.0000
52.2600 31.0000 1.0000
52.3200 35.0000 1.0000
52.3800 37.0000 1.0000
52.4400 26.0000 1.0000
52.5000 37.0000 1.0000
52.5600 42.0000 1.0000
52.6200 30.0000 1.0000
52.6800 29.0000 1.0000
52.7400 43.0000 1.0000
52.8000 25.0000 1.0000
52.8600 43.0000 1.0000
52.9200 36.0000 1.0000
52.9800 25.0000 1.0000
53.0400 44.0000 1.0000
53.1000 33.0000 1.0000
53.1600 35.0000 1.0000
53.2200 34.0000 1.0000
53.2800 39.0000 1.0000
53.3400 33.0000 1.0000
53.4000 33.0000 1.0000
53.4600 38.0000 1.0000
53.5200 50.0000 1.0000
53.5800 44.0000 1.0000
53.6400 59.0000 1.0000
53.7000 62.0000 1.0000
53.7600 84.0000 1.0000
53.8200 81.0000 1.0000
53.8800 92.0000 1.0000
53.9400 70.0000 1.0000
54.0000 63.0000 1.0000
54.0600 61.0000 1.0000
54.1200 53.0000 1.0000
54.1800 50.0000 1.0000
54.2400 43.0000 1.0000
54.3000 46.0000 1.0000
54.3600 42.0000 1.0000
54.4200 31.0000 1.0000
54.4800 34.0000 1.0000
54.5400 33.0000 1.0000
54.6000 39.0000 1.0000
54.6600 39.0000 1.0000
54.7200 37.0000 1.0000
54.7800 42.0000 1.0000
54.8400 42.0000 1.0000
54.9000 30.0000 1.0000
54.9600 35.0000 1.0000
55.0200 38.0000 1.0000
55.0800 29.0000 1.0000
55.1400 32.0000 1.0000
55.2000 37.0000 1.0000
55.2600 32.0000 1.0000
55.3200 20.0000 1.0000
55.3800 43.0000 1.0000
55.4400 27.0000 1.0000
55.5000 33.0000 1.0000
55.5600 35.0000 1.0000
55.6200 34.0000 1.0000
55.6800 30.0000 1.0000
55.7400 33.0000 1.0000
55.8000 35.0000 1.0000
55.8600 32.0000 1.0000
55.9200 42.0000 1.0000
55.9800 26.0000 1.0000
56.0400 24.0000 1.0000
56.1000 28.0000 1.0000
56.1600 32.0000 1.0000
56.2200 24.0000 1.0000
56.2800 28.0000 1.0000
56.3400 39.0000 1.0000
56.4000 32.0000 1.0000
56.4600 32.0000 1.0000
56.5200 38.0000 1.0000
56.5800 29.0000 1.0000
56.6400 37.0000 1.0000
56.7000 23.0000 1.0000
56.7600 29.0000 1.0000
56.8200 27.0000 1.0000
56.8800 32.0000 1.0000
56.9400 26.0000 1.0000
57.0000 33.0000 1.0000
57.0600 41.0000 1.0000
57.1200 23.0000 1.0000
57.1800 33.0000 1.0000
57.2400 28.0000 1.0000
57.3000 28.0000 1.0000
57.3600 41.0000 1.0000
57.4200 33.0000 1.0000
57.4800 37.0000 1.0000
57.5400 32.0000 1.0000
57.6000 28.0000 1.0000
57.6600 23.0000 1.0000
57.7200 28.0000 1.0000
57.7800 24.0000 1.0000
57.8400 26.0000 1.0000
57.9000 23.0000 1.0000
57.9600 41.0000 1.0000
58.0200 39.0000 1.0000
58.0800 29.0000 1.0000
58.1400 27.0000 1.0000
58.2000 27.0000 1.0000
58.2600 27.0000 1.0000
58.3200 26.0000 1.0000
58.3800 18.0000 1.0000
58.4400 27.0000 1.0000
58.5000 30.0000 1.0000
58.5600 22.0000 1.0000
58.6200 27.0000 1.0000
58.6800 22.0000 1.0000
58.7400 36.0000 1.0000
58.8000 35.0000 1.0000
58.8600 33.0000 1.0000
58.9200 27.0000 1.0000
58.9800 31.0000 1.0000
59.0400 31.0000 1.0000
59.1000 27.0000 1.0000
59.1600 37.0000 1.0000
59.2200 33.0000 1.0000
59.2800 17.0000 1.0000
59.3400 32.0000 1.0000
59.4000 31.0000 1.0000
59.4600 30.0000 1.0000
59.5200 26.0000 1.0000
59.5800 26.0000 1.0000
59.6400 32.0000 1.0000
59.7000 20.0000 1.0000
59.7600 25.0000 1.0000
59.8200 25.0000 1.0000
59.8800 27.0000 1.0000
59.9400 29.0000 1.0000
60.0000 32.0000 1.0000
60.0600 33.0000 1.0000
60.1200 35.0000 1.0000
60.1800 26.0000 1.0000
60.2400 36.0000 1.0000
60.3000 39.0000 1.0000
60.3600 35.0000 1.0000
60.4200 36.0000 1.0000
60.4800 35.0000 1.0000
60.5400 37.0000 1.0000
60.6000 37.0000 1.0000
60.6600 45.0000 1.0000
60.7200 57.0000 1.0000
60.7800 57.0000 1.0000
60.8400 67.0000 1.0000
60.9000 69.0000 1.0000
60.9600 62.0000 1.0000
61.0200 67.0000 1.0000
61.0800 51.0000 1.0000
61.1400 43.0000 1.0000
61.2000 40.0000 1.0000
61.2600 35.0000 1.0000
61.3200 29.0000 1.0000
61.3800 24.0000 1.0000
61.4400 29.0000 1.0000
61.5000 28.0000 1.0000
61.5600 18.0000 1.0000
61.6200 21.0000 1.0000
61.6800 31.0000 1.0000
61.7400 30.0000 1.0000
61.8000 32.0000 1.0000
61.8600 40.0000 1.0000
61.9200 35.0000 1.0000
61.9800 22.0000 1.0000
62.0400 31.0000 1.0000
62.1000 36.0000 1.0000
62.1600 22.0000 1.0000
62.2200 21.0000 1.0000
62.2800 22.0000 1.0000
62.3400 26.0000 1.0000
62.4000 25.0000 1.0000
62.4600 12.0000 1.0000
62.5200 26.0000 1.0000
62.5800 21.0000 1.0000
62.6400 20.0000 1.0000
62.7000 30.0000 1.0000
62.7600 26.0000 1.0000
62.8200 25.0000 1.0000
62.8800 19.0000 1.0000
62.9400 20.0000 1.0000
63.0000 26.0000 1.0000
63.0600 20.0000 1.0000
63.1200 36.0000 1.0000
63.1800 20.0000 1.0000
63.2400 33.0000 1.0000
63.3000 24.0000 1.0000
63.3600 31.0000 1.0000
63.4200 25.0000 1.0000
63.4800 29.0000 1.0000
63.5400 23.0000 1.0000
63.6000 27.0000 1.0000
63.6600 27.0000 1.0000
63.7200 30.0000 1.0000
63.7800 34.0000 1.0000
63.8400 37.0000 1.0000
63.9000 23.0000 1.0000
63.9600 26.0000 1.0000
64.0200 27.0000 1.0000
64.0800 25.0000 1.0000
64.1400 28.0000 1.0000
64.2000 27.0000 1.0000
64.2600 23.0000 1.0000
64.3200 15.0000 1.0000
64.3800 26.0000 1.0000
64.4400 22.0000 1.0000
64.5000 31.0000 1.0000
64.5600 29.0000 1.0000
64.6200 28.0000 1.0000
64.6800 30.0000 1.0000
64.7400 20.0000 1.0000
64.8000 23.0000 1.0000
64.8600 23.0000 1.0000
64.9200 22.0000 1.0000
64.9800 35.0000 1.0000
65.0400 27.0000 1.0000
65.1000 19.0000 1.0000
65.1600 25.0000 1.0000
65.2200 26.0000 1.0000
65.2800 21.0000 1.0000
65.3400 36.0000 1.0000
65.4000 35.0000 1.0000
65.4600 25.0000 1.0000
65.5200 27.0000 1.0000
65.5800 25.0000 1.0000
65.6400 33.0000 1.0000
65.7000 26.0000 1.0000
65.7600 35.0000 1.0000
65.8200 29.0000 1.0000
65.8800 31.0000 1.0000
65.9400 28.0000 1.0000
66.0000 30.0000 1.0000
66.0600 25.0000 1.0000
66.1200 23.0000 1.0000
66.1800 19.0000 1.0000
66.2400 25.0000 1.0000
66.3000 33.0000 1.0000
66.3600 31.0000 1.0000
66.4200 25.0000 1.0000
66.4800 25.0000 1.0000
66.5400 26.0000 1.0000
66.6000 25.0000 1.0000
66.6600 27.0000 1.0000
66.7200 30.0000 1.0000
66.7800 32.0000 1.0000
66.8400 16.0000 1.0000
66.9000 29.0000 1.0000
66.9600 29.0000 1.0000
67.0200 30.0000 1.0000
67.0800 27.0000 1.0000
67.1400 30.0000 1.0000
67.2000 47.0000 1.0000
67.2600 32.0000 1.0000
67.3200 36.0000 1.0000
67.3800 37.0000 1.0000
67.4400 22.0000 1.0000
67.5000 26.0000 1.0000
67.5600 44.0000 1.0000
67.6200 32.0000 1.0000
67.6800 30.0000 1.0000
67.7400 28.0000 1.0000
67.8000 21.0000 1.0000
67.8600 31.0000 1.0000
67.9200 31.0000 1.0000
67.9800 31.0000 1.0000
68.0400 28.0000 1.0000
68.1000 15.0000 1.0000
68.1600 19.0000 1.0000
68.2200 36.0000 1.0000
68.2800 20.0000 1.0000
68.3400 28.0000 1.0000
68.4000 23.0000 1.0000
68.4600 21.0000 1.0000
68.5200 18.0000 1.0000
68.5800 25.0000 1.0000
68.6400 22.0000 1.0000
68.7000 24.0000 1.0000
68.7600 27.0000 1.0000
68.8200 23.0000 1.0000
68.8800 29.0000 1.0000
68.9400 18.0000 1.0000
69.0000 15.0000 1.0000
69.0600 23.0000 1.0000
69.1200 22.0000 1.0000
69.1800 27.0000 1.0000
69.2400 24.0000 1.0000
69.3000 18.0000 1.0000
69.3600 25.0000 1.0000
69.4200 21.0000 1.0000
69.4800 27.0000 1.0000
69.5400 18.0000 1.0000
69.6000 25.0000 1.0000
69.6600 31.0000 1.0000
69.7200 17.0000 1.0000
69.7800 21.0000 1.0000
69.8400 22.0000 1.0000
69.9000 27.0000 1.0000
69.9600 30.0000 1.0000
70.0200 19.0000 1.0000
70.0800 24.0000 1.0000
70.1400 34.0000 1.0000
70.2000 30.0000 1.0000
70.2600 23.0000 1.0000
70.3200 30.0000 1.0000
70.3800 24.0000 1.0000
70.4400 22.0000 1.0000
70.5000 29.0000 1.0000
70.5600 28.0000 1.0000
70.6200 25.0000 1.0000
70.6800 35.0000 1.0000
70.7400 25.0000 1.0000
70.8000 21.0000 1.0000
70.8600 23.0000 1.0000
70.9200 24.0000 1.0000
70.9800 26.0000 1.0000
71.0400 27.0000 1.0000
71.1000 23.0000 1.0000
71.1600 19.0000 1.0000
71.2200 20.0000 1.0000
71.2800 19.0000 1.0000
71.3400 27.0000 1.0000
71.4000 10.0000 1.0000
71.4600 20.0000 1.0000
71.5200 22.0000 1.0000
71.5800 22.0000 1.0000
71.6400 26.0000 1.0000
71.7000 27.0000 1.0000
71.7600 31.0000 1.0000
71.8200 28.0000 1.0000
71.8800 33.0000 1.0000
71.9400 18.0000 1.0000
72.0000 22.0000 1.0000
72.0600 24.0000 1.0000
72.1200 16.0000 1.0000
72.1800 19.0000 1.0000
72.2400 16.0000 1.0000
72.3000 22.0000 1.0000
72.3600 24.0000 1.0000
72.4200 35.0000 1.0000
72.4800 16.0000 1.0000
72.5400 23.0000 1.0000
72.6000 24.0000 1.0000
72.6600 21.0000 1.0000
72.7200 29.0000 1.0000
72.7800 20.0000 1.0000
72.8400 32.0000 1.0000
72.9000 25.0000 1.0000
72.9600 17.0000 1.0000
73.0200 32.0000 1.0000
73.0800 35.0000 1.0000
73.1400 42.0000 1.0000
73.2000 23.0000 1.0000
73.2600 25.0000 1.0000
73.3200 43.0000 1.0000
73.3800 46.0000 1.0000
73.4400 53.0000 1.0000
73.5000 44.0000 1.0000
73.5600 42.0000 1.0000
73.6200 45.0000 1.0000
73.6800 55.0000 1.0000
73.7400 56.0000 1.0000
73.8000 60.0000 1.0000
73.8600 57.0000 1.0000
73.9200 46.0000 1.0000
73.9800 43.0000 1.0000
74.0400 42.0000 1.0000
74.1000 32.0000 1.0000
74.1600 29.0000 1.0000
74.2200 23.0000 1.0000
74.2800 35.0000 1.0000
74.3400 29.0000 1.0000
74.4000 34.0000 1.0000
74.4600 21.0000 1.0000
74.5200 29.0000 1.0000
74.5800 28.0000 1.0000
74.6400 23.0000 1.0000
74.7000 24.0000 1.0000
74.7600 24.0000 1.0000
74.8200 23.0000 1.0000
74.8800 28.0000 1.0000
74.9400 21.0000 1.0000
75.0000 21.0000 1.0000
75.0600 20.0000 1.0000
75.1200 22.0000 1.0000
75.1800 19.0000 1.0000
75.2400 20.0000 1.0000
75.3000 22.0000 1.0000
75.3600 19.0000 1.0000
75.4200 26.0000 1.0000
75.4800 25.0000 1.0000
75.5400 29.0000 1.0000
75.6000 27.0000 1.0000
75.6600 23.0000 1.0000
75.7200 22.0000 1.0000
75.7800 23.0000 1.0000
75.8400 33.0000 1.0000
75.9000 18.0000 1.0000
75.9600 18.0000 1.0000
76.0200 26.0000 1.0000
76.0800 14.0000 1.0000
76.1400 26.0000 1.0000
76.2000 20.0000 1.0000
76.2600 19.0000 1.0000
76.3200 26.0000 1.0000
76.3800 23.0000 1.0000
76.4400 17.0000 1.0000
76.5000 25.0000 1.0000
76.5600 29.0000 1.0000
76.6200 27.0000 1.0000
76.6800 25.0000 1.0000
76.7400 29.0000 1.0000
76.8000 25.0000 1.0000
76.8600 22.0000 1.0000
76.9200 29.0000 1.0000
76.9800 22.0000 1.0000
77.0400 21.0000 1.0000
77.1000 21.0000 1.0000
77.1600 26.0000 1.0000
77.2200 27.0000 1.0000
77.2800 20.0000 1.0000
77.3400 19.0000 1.0000
77.4000 26.0000 1.0000
77.4600 20.0000 1.0000
77.5200 23.0000 1.0000
77.5800 20.0000 1.0000
77.6400 17.0000 1.0000
77.7000 19.0000 1.0000
77.7600 21.0000 1.0000
77.8200 24.0000 1.0000
77.8800 33.0000 1.0000
77.9400 17.0000 1.0000
78.0000 26.0000 1.0000
78.0600 22.0000 1.0000
78.1200 21.0000 1.0000
78.1800 20.0000 1.0000
78.2400 30.0000 1.0000
78.3000 24.0000 1.0000
78.3600 27.0000 1.0000
78.4200 24.0000 1.0000
78.4800 25.0000 1.0000
78.5400 21.0000 1.0000
78.6000 25.0000 1.0000
78.6600 15.0000 1.0000
78.7200 30.0000 1.0000
78.7800 23.0000 1.0000
78.8400 21.0000 1.0000
78.9000 21.0000 1.0000
78.9600 27.0000 1.0000
79.0200 19.0000 1.0000
79.0800 17.0000 1.0000
79.1400 15.0000 1.0000
79.2000 11.0000 1.0000
79.2600 33.0000 1.0000
79.3200 26.0000 1.0000
79.3800 26.0000 1.0000
79.4400 20.0000 1.0000
79.5000 25.0000 1.0000
79.5600 23.0000 1.0000
79.6200 29.0000 1.0000
79.6800 27.0000 1.0000
79.7400 23.0000 1.0000
79.8000 30.0000 1.0000
79.8600 24.0000 1.0000
79.9200 18.0000 1.0000
79.9800 21.0000 1.0000
80.0400 20.0000 1.0000
80.1000 21.0000 1.0000
80.1600 33.0000 1.0000
80.2200 26.0000 1.0000
80.2800 16.0000 1.0000
80.3400 22.0000 1.0000
80.4000 20.0000 1.0000
80.4600 25.0000 1.0000
80.5200 20.0000 1.0000
80.5800 24.0000 1.0000
80.6400 14.0000 1.0000
80.7000 25.0000 1.0000
80.7600 22.0000 1.0000
80.8200 21.0000 1.0000
80.8800 20.0000 1.0000
80.9400 20.0000 1.0000
81.0000 28.0000 1.0000
81.0600 27.0000 1.0000
81.1200 23.0000 1.0000
81.1800 21.0000 1.0000
81.2400 26.0000 1.0000
81.3000 25.0000 1.0000
81.3600 19.0000 1.0000
81.4200 24.0000 1.0000
81.4800 24.0000 1.0000
81.5400 23.0000 1.0000
81.6000 18.0000 1.0000
81.6600 28.0000 1.0000
81.7200 25.0000 1.0000
81.7800 18.0000 1.0000
81.8400 20.0000 1.0000
81.9000 33.0000 1.0000
81.9600 19.0000 1.0000
82.0200 20.0000 1.0000
82.0800 26.0000 1.0000
82.1400 15.0000 1.0000
82.2000 22.0000 1.0000
82.2600 22.0000 1.0000
82.3200 16.0000 1.0000
82.3800 23.0000 1.0000
82.4400 16.0000 1.0000
82.5000 19.0000 1.0000
82.5600 29.0000 1.0000
82.6200 20.0000 1.0000
82.6800 15.0000 1.0000
82.7400 9.0000 1.0000
82.8000 28.0000 1.0000
82.8600 20.0000 1.0000
82.9200 23.0000 1.0000
82.9800 17.0000 1.0000
83.0400 13.0000 1.0000
83.1000 23.0000 1.0000
83.1600 29.0000 1.0000
83.2200 26.0000 1.0000
83.2800 14.0000 1.0000
83.3400 27.0000 1.0000
83.4000 23.0000 1.0000
83.4600 29.0000 1.0000
83.5200 16.0000 1.0000
83.5800 15.0000 1.0000
83.6400 29.0000 1.0000
83.7000 28.0000 1.0000
83.7600 21.0000 1.0000
83.8200 24.0000 1.0000
83.8800 13.0000 1.0000
83.9400 15.0000 1.0000
84.0000 16.0000 1.0000
84.0600 16.0000 1.0000
84.1200 27.0000 1.0000
84.1800 21.0000 1.0000
84.2400 22.0000 1.0000
84.3000 12.0000 1.0000
84.3600 19.0000 1.0000
84.4200 16.0000 1.0000
84.4800 22.0000 1.0000
84.5400 26.0000 1.0000
84.6000 22.0000 1.0000
84.6600 18.0000 1.0000
84.7200 18.0000 1.0000
84.7800 25.0000 1.0000
84.8400 24.0000 1.0000
84.9000 20.0000 1.0000
84.9600 25.0000 1.0000
85.0200 21.0000 1.0000
85.0800 15.0000 1.0000
85.1400 18.0000 1.0000
85.2000 24.0000 1.0000
85.2600 26.0000 1.0000
85.3200 35.0000 1.0000
85.3800 24.0000 1.0000
85.4400 25.0000 1.0000
85.5000 34.0000 1.0000
85.5600 26.0000 1.0000
85.6200 37.0000 1.0000
85.6800 39.0000 1.0000
85.7400 43.0000 1.0000
85.8000 32.0000 1.0000
85.8600 26.0000 1.0000
85.9200 21.0000 1.0000
85.9800 21.0000 1.0000
86.0400 28.0000 1.0000
86.1000 20.0000 1.0000
86.1600 27.0000 1.0000
86.2200 20.0000 1.0000
86.2800 28.0000 1.0000
86.3400 25.0000 1.0000
86.4000 21.0000 1.0000
86.4600 14.0000 1.0000
86.5200 23.0000 1.0000
86.5800 17.0000 1.0000
86.6400 24.0000 1.0000
86.7000 24.0000 1.0000
86.7600 21.0000 1.0000
86.8200 20.0000 1.0000
86.8800 21.0000 1.0000
86.9400 17.0000 1.0000
87.0000 13.0000 1.0000
87.0600 28.0000 1.0000
87.1200 24.0000 1.0000
87.1800 18.0000 1.0000
87.2400 18.0000 1.0000
87.3000 18.0000 1.0000
87.3600 17.0000 1.0000
87.4200 15.0000 1.0000
87.4800 16.0000 1.0000
87.5400 19.0000 1.0000
87.6000 20.0000 1.0000
87.6600 18.0000 1.0000
87.7200 22.0000 1.0000
87.7800 22.0000 1.0000
87.8400 23.0000 1.0000
87.9000 16.0000 1.0000
87.9600 22.0000 1.0000
88.0200 26.0000 1.0000
88.0800 24.0000 1.0000
88.1400 19.0000 1.0000
88.2000 19.0000 1.0000
88.2600 21.0000 1.0000
88.3200 23.0000 1.0000
88.3800 19.0000 1.0000
88.4400 30.0000 1.0000
88.5000 16.0000 1.0000
88.5600 23.0000 1.0000
88.6200 17.0000 1.0000
88.6800 22.0000 1.0000
88.7400 16.0000 1.0000
88.8000 22.0000 1.0000
88.8600 17.0000 1.0000
88.9200 17.0000 1.0000
88.9800 14.0000 1.0000
89.0400 16.0000 1.0000
89.1000 16.0000 1.0000
89.1600 20.0000 1.0000
89.2200 25.0000 1.0000
89.2800 14.0000 1.0000
89.3400 12.0000 1.0000
89.4000 20.0000 1.0000
89.4600 31.0000 1.0000
89.5200 17.0000 1.0000
89.5800 15.0000 1.0000
89.6400 16.0000 1.0000
89.7000 18.0000 1.0000
89.7600 19.0000 1.0000
89.8200 20.0000 1.0000
89.8800 19.0000 1.0000
89.9400 13.0000 1.0000
90.0000 16.0000 1.0000
*RAS_INT_END
*RAS_TEMPERATURE_START
*RAS_TEMPERATURE_END
*RAS_DATA_END