File: FrgTools/Example Notebooks/Smartlab XRD Processing/Data/KPbF3.ras
*RAS_DATA_START
*RAS_HEADER_START
*DISP_FMT_X "%.3f"
*DISP_FMT_Y "%.0f"
*DISP_FULLSCALE "864.0000000000"
*DISP_LINE_COLOR "255.0000000000"
*DISP_LINE_STYLE "0.0000000000"
*DISP_LINE_WIDTH "0.2500000000"
*DISP_NOTE "Collected Data-12"
*DISP_OFFSET_Y "0.0000000000"
*DISP_PEAKSEARCH_UNIT_Y "cps"
*DISP_RANGE_BOTTOM "0.0000000000"
*DISP_RANGE_LEFT "10.0000000000"
*DISP_RANGE_LOGCUTOFF "0.0100000000"
*DISP_RANGE_RIGHT "90.0000000000"
*DISP_RANGE_TOP "864.0000000000"
*DISP_SCALE_MODE_Y "0.0000000000"
*DISP_TAB_NAME "Theta/2-Theta"
*DISP_TITLE_Y "Intensity"
*DISP_UNIT_Y "cps"
*DISP_WINDOW_NAME "MSG_MACROENGINE"
*FILE_COMMENT " "
*FILE_MD5 ""
*FILE_MEMO " "
*FILE_OPERATOR "administrator"
*FILE_PART_ID "MEAS_KHP2_00068"
*FILE_SAMPLE " "
*FILE_TYPE "RAS_RAW"
*FILE_USERGROUP "System Manager"
*FILE_VERSION "1.0000000000"
*HW_ATTACHMENT_ID "ATT0022"
*HW_ATTACHMENT_NAME "RxRy|RxRy"
*HW_COUNTER_ID-0 "CUT0021"
*HW_COUNTER_ID-1 "CUT0020"
*HW_COUNTER_ID-2 ""
*HW_COUNTER_ID-3 "CSL0021"
*HW_COUNTER_ID-4 "CMC0021"
*HW_COUNTER_NAME-0 "SC-70|SC-70"
*HW_COUNTER_NAME-1 "None|None"
*HW_COUNTER_NAME-2 ""
*HW_COUNTER_NAME-3 "BBM|BBM"
*HW_COUNTER_NAME-4 "検出器モノクロメータ|Detector monochromator"
*HW_COUNTER_SELECT_NAME "SC-70|SC-70"
*HW_ECP_HV "655.5000000000"
*HW_ECP_HV_UNIT "V"
*HW_GONIOMETER_ID "GON0024"
*HW_GONIOMETER_NAME "SmartLab(In-plane)|SmartLab(In-plane)"
*HW_GONIOMETER_RADIUS-0 "90.0"
*HW_GONIOMETER_RADIUS-1 "114.0"
*HW_GONIOMETER_RADIUS-2 "190.0"
*HW_GONIOMETER_RADIUS-3 "300.0"
*HW_GONIOMETER_RADIUS-4 "187.0"
*HW_GONIOMETER_RADIUS-5 "300.0"
*HW_GONIOMETER_RADIUS-6 "113.0"
*HW_GONIOMETER_RADIUS-7 "331.0"
*HW_I_OPT_ID-0 "CBO0021"
*HW_I_OPT_ID-1 "ICR0023"
*HW_I_OPT_ID-2 "ISL0021"
*HW_I_OPT_ID-3 "ISO0021"
*HW_I_OPT_ID-4 "IAD0021"
*HW_I_OPT_ID-5 "IPR0001"
*HW_I_OPT_NAME-0 "CBOユニット|CBO unit"
*HW_I_OPT_NAME-1 "標準入射光学ユニット|Standard incident optical unit"
*HW_I_OPT_NAME-2 "標準入射スリットボックス|Standard incident slit box"
*HW_I_OPT_NAME-3 "入射平行スリット|Incident parallel slit"
*HW_I_OPT_NAME-4 "長手制限スリット|Length limiting slit"
*HW_I_OPT_NAME-5 "None|None"
*HW_R_ATTENUATER_AUTOMODE "0"
*HW_R_OPT_ID-0 "RSS0021"
*HW_R_OPT_ID-1 "RCR0022"
*HW_R_OPT_ID-2 "RSO0021"
*HW_R_OPT_ID-3 "RRS0021"
*HW_R_OPT_ID-4 "ATN0021"
*HW_R_OPT_ID-5 "RFL0021"
*HW_R_OPT_ID-6 "RAD0021"
*HW_R_OPT_NAME-0 "標準受光スリットボックス1|Standard receiving slit box # 1"
*HW_R_OPT_NAME-1 "標準受光光学ユニット1|Standard receiving unit # 1"
*HW_R_OPT_NAME-2 "標準受光光学ユニット2|Standard receiving optical unit # 2"
*HW_R_OPT_NAME-3 "標準受光スリットボックス2|Standard receiving slit box # 2"
*HW_R_OPT_NAME-4 "標準アッテネータ|Standard Attenuator"
*HW_R_OPT_NAME-5 "Cu Kβ|Cu K-beta"
*HW_R_OPT_NAME-6 "調整用受光スリット|Alignment receiving slit"
*HW_SAMPLE_HOLDER_ID "SMP0026"
*HW_SAMPLE_HOLDER_NAME "Z-φステージ|Z-Phi Stage"
*HW_XG_CURRENT_MAX "50"
*HW_XG_CURRENT_MIN "2"
*HW_XG_CURRENT_RESOLUTION "2"
*HW_XG_CURRENT_UNIT "mA"
*HW_XG_FOCUS "1mm x 10mm"
*HW_XG_FOCUS_TYPE "Normal"
*HW_XG_ID ""
*HW_XG_NAME "3kW 封入管(ID:1200)|3kW Sealed tube(ID:1200)"
*HW_XG_TARGET_ATOMIC_NUMBER "29.0000000000"
*HW_XG_TARGET_NAME "Cu"
*HW_XG_TYPE "Hermetic"
*HW_XG_VOLTAGE_MAX "60"
*HW_XG_VOLTAGE_MIN "20"
*HW_XG_VOLTAGE_RESOLUTION "2"
*HW_XG_VOLTAGE_UNIT "kV"
*HW_XG_WATT_MAX "2"
*HW_XG_WATT_UNIT "kW"
*HW_XG_WAVE_LENGTH_ALPHA1 "1.540593"
*HW_XG_WAVE_LENGTH_ALPHA2 "1.544414"
*HW_XG_WAVE_LENGTH_BETA "1.392250"
*MEAS_COND_AXIS_NAME-0 "Theta/2-Theta"
*MEAS_COND_AXIS_NAME-1 "2-Theta"
*MEAS_COND_AXIS_NAME-2 "Omega"
*MEAS_COND_AXIS_NAME-3 "Phi"
*MEAS_COND_AXIS_NAME-4 "Z"
*MEAS_COND_AXIS_NAME-5 "Rx"
*MEAS_COND_AXIS_NAME-6 "Ry"
*MEAS_COND_AXIS_NAME-7 "2-Theta/Omega"
*MEAS_COND_AXIS_NAME-8 "2-ThetaChi"
*MEAS_COND_AXIS_NAME-9 "2-ThetaChi/Phi"
*MEAS_COND_AXIS_NAME-10 "Alpha"
*MEAS_COND_AXIS_NAME-11 "Beta"
*MEAS_COND_AXIS_NAME-12 "Theta_s"
*MEAS_COND_AXIS_NAME-13 "Theta_d"
*MEAS_COND_AXIS_NAME-14 "Ts"
*MEAS_COND_AXIS_NAME-15 "CBO selection slit"
*MEAS_COND_AXIS_NAME-16 "M"
*MEAS_COND_AXIS_NAME-17 "Incident parallel slit"
*MEAS_COND_AXIS_NAME-18 "Incident slit"
*MEAS_COND_AXIS_NAME-19 ""
*MEAS_COND_AXIS_NAME-20 "Zs"
*MEAS_COND_AXIS_NAME-21 "Incident monochromator"
*MEAS_COND_AXIS_NAME-22 "Length limiting slit"
*MEAS_COND_AXIS_NAME-23 "Center slit"
*MEAS_COND_AXIS_NAME-24 "Filter"
*MEAS_COND_AXIS_NAME-25 "Receiving slit # 1"
*MEAS_COND_AXIS_NAME-26 "Receiving slit # 2"
*MEAS_COND_AXIS_NAME-27 "Receiving optical device"
*MEAS_COND_AXIS_NAME-28 "Receiving parallel slit"
*MEAS_COND_AXIS_NAME-29 "Alignment receiving slit"
*MEAS_COND_AXIS_NAME-30 ""
*MEAS_COND_AXIS_NAME-31 ""
*MEAS_COND_AXIS_NAME-32 "Zd"
*MEAS_COND_AXIS_NAME-33 "Attenuator"
*MEAS_COND_AXIS_NAME-34 "Diffracted beam monochromator"
*MEAS_COND_AXIS_NAME-35 "Monochromator slit"
*MEAS_COND_AXIS_NAME-36 "2-ThetaB"
*MEAS_COND_AXIS_NAME-37 "Primary beam"
*MEAS_COND_AXIS_NAME-38 "HV"
*MEAS_COND_AXIS_NAME-39 "PHA"
*MEAS_COND_AXIS_NAME_INTERNAL-0 "TwoThetaTheta"
*MEAS_COND_AXIS_NAME_INTERNAL-1 "TwoTheta"
*MEAS_COND_AXIS_NAME_INTERNAL-2 "Omega"
*MEAS_COND_AXIS_NAME_INTERNAL-3 "Phi"
*MEAS_COND_AXIS_NAME_INTERNAL-4 "Z"
*MEAS_COND_AXIS_NAME_INTERNAL-5 "Rx"
*MEAS_COND_AXIS_NAME_INTERNAL-6 "Ry"
*MEAS_COND_AXIS_NAME_INTERNAL-7 "TwoThetaOmega"
*MEAS_COND_AXIS_NAME_INTERNAL-8 "TwoThetaChi"
*MEAS_COND_AXIS_NAME_INTERNAL-9 "TwoThetaChiPhi"
*MEAS_COND_AXIS_NAME_INTERNAL-10 "Alpha"
*MEAS_COND_AXIS_NAME_INTERNAL-11 "Beta"
*MEAS_COND_AXIS_NAME_INTERNAL-12 "ThetaS"
*MEAS_COND_AXIS_NAME_INTERNAL-13 "ThetaD"
*MEAS_COND_AXIS_NAME_INTERNAL-14 "Ts"
*MEAS_COND_AXIS_NAME_INTERNAL-15 "CBO"
*MEAS_COND_AXIS_NAME_INTERNAL-16 "CBO-M"
*MEAS_COND_AXIS_NAME_INTERNAL-17 "IncidentSollerSlit"
*MEAS_COND_AXIS_NAME_INTERNAL-18 "IncidentSlitBox"
*MEAS_COND_AXIS_NAME_INTERNAL-19 "IncidentSlitBox-_Axis"
*MEAS_COND_AXIS_NAME_INTERNAL-20 "Zs"
*MEAS_COND_AXIS_NAME_INTERNAL-21 "IncidentMonochromator"
*MEAS_COND_AXIS_NAME_INTERNAL-22 "IncidentAxdSlit"
*MEAS_COND_AXIS_NAME_INTERNAL-23 "CenterSlit"
*MEAS_COND_AXIS_NAME_INTERNAL-24 "Filter"
*MEAS_COND_AXIS_NAME_INTERNAL-25 "ReceivingSlitBox1"
*MEAS_COND_AXIS_NAME_INTERNAL-26 "ReceivingSlitBox2"
*MEAS_COND_AXIS_NAME_INTERNAL-27 "ReceivingOptics"
*MEAS_COND_AXIS_NAME_INTERNAL-28 "ReceivingSollerSlit"
*MEAS_COND_AXIS_NAME_INTERNAL-29 "ReceivingAxdSlit"
*MEAS_COND_AXIS_NAME_INTERNAL-30 "ReceivingSlitBox1-_Axis"
*MEAS_COND_AXIS_NAME_INTERNAL-31 "ReceivingSlitBox2-_Axis"
*MEAS_COND_AXIS_NAME_INTERNAL-32 "ReceivingSlitBox2-Zd"
*MEAS_COND_AXIS_NAME_INTERNAL-33 "Attenuator"
*MEAS_COND_AXIS_NAME_INTERNAL-34 "CounterMonochromator"
*MEAS_COND_AXIS_NAME_INTERNAL-35 "CounterSlit"
*MEAS_COND_AXIS_NAME_INTERNAL-36 "TwoThetaB"
*MEAS_COND_AXIS_NAME_INTERNAL-37 "IncidentPrimary"
*MEAS_COND_AXIS_NAME_INTERNAL-38 "HV"
*MEAS_COND_AXIS_NAME_INTERNAL-39 "PHA"
*MEAS_COND_AXIS_NAME_MAGICNO-0 "83951616.0000000000"
*MEAS_COND_AXIS_NAME_MAGICNO-1 "268632064.0000000000"
*MEAS_COND_AXIS_NAME_MAGICNO-2 "268500992.0000000000"
*MEAS_COND_AXIS_NAME_MAGICNO-3 "268500992.0000000000"
*MEAS_COND_AXIS_NAME_MAGICNO-4 "285278208.0000000000"
*MEAS_COND_AXIS_NAME_MAGICNO-5 "285278208.0000000000"
*MEAS_COND_AXIS_NAME_MAGICNO-6 "285278208.0000000000"
*MEAS_COND_AXIS_NAME_MAGICNO-7 "83951616.0000000000"
*MEAS_COND_AXIS_NAME_MAGICNO-8 "268632064.0000000000"
*MEAS_COND_AXIS_NAME_MAGICNO-9 "83951616.0000000000"
*MEAS_COND_AXIS_NAME_MAGICNO-10 "17039360.0000000000"
*MEAS_COND_AXIS_NAME_MAGICNO-11 "17039360.0000000000"
*MEAS_COND_AXIS_NAME_MAGICNO-12 "131072.0000000000"
*MEAS_COND_AXIS_NAME_MAGICNO-13 "131072.0000000000"
*MEAS_COND_AXIS_NAME_MAGICNO-14 "318898176.0000000000"
*MEAS_COND_AXIS_NAME_MAGICNO-15 "20971521.0000000000"
*MEAS_COND_AXIS_NAME_MAGICNO-16 "285343744.0000000000"
*MEAS_COND_AXIS_NAME_MAGICNO-17 "20971521.0000000000"
*MEAS_COND_AXIS_NAME_MAGICNO-18 "22020097.0000000000"
*MEAS_COND_AXIS_NAME_MAGICNO-19 "25165824.0000000000"
*MEAS_COND_AXIS_NAME_MAGICNO-20 "318898176.0000000000"
*MEAS_COND_AXIS_NAME_MAGICNO-21 "1.0000000000"
*MEAS_COND_AXIS_NAME_MAGICNO-22 "20971521.0000000000"
*MEAS_COND_AXIS_NAME_MAGICNO-23 "20971521.0000000000"
*MEAS_COND_AXIS_NAME_MAGICNO-24 "20971521.0000000000"
*MEAS_COND_AXIS_NAME_MAGICNO-25 "23068673.0000000000"
*MEAS_COND_AXIS_NAME_MAGICNO-26 "23068673.0000000000"
*MEAS_COND_AXIS_NAME_MAGICNO-27 "20971521.0000000000"
*MEAS_COND_AXIS_NAME_MAGICNO-28 "20971521.0000000000"
*MEAS_COND_AXIS_NAME_MAGICNO-29 "20971521.0000000000"
*MEAS_COND_AXIS_NAME_MAGICNO-30 "25165824.0000000000"
*MEAS_COND_AXIS_NAME_MAGICNO-31 "25165824.0000000000"
*MEAS_COND_AXIS_NAME_MAGICNO-32 "285343744.0000000000"
*MEAS_COND_AXIS_NAME_MAGICNO-33 "17301505.0000000000"
*MEAS_COND_AXIS_NAME_MAGICNO-34 "20971521.0000000000"
*MEAS_COND_AXIS_NAME_MAGICNO-35 "20971521.0000000000"
*MEAS_COND_AXIS_NAME_MAGICNO-36 "17039360.0000000000"
*MEAS_COND_AXIS_NAME_MAGICNO-37 "20971521.0000000000"
*MEAS_COND_AXIS_NAME_MAGICNO-38 "0.0000000000"
*MEAS_COND_AXIS_NAME_MAGICNO-39 "0.0000000000"
*MEAS_COND_AXIS_OFFSET-0 "-"
*MEAS_COND_AXIS_OFFSET-1 "0.0741000000"
*MEAS_COND_AXIS_OFFSET-2 "-0.2466000000"
*MEAS_COND_AXIS_OFFSET-3 "0.0000000000"
*MEAS_COND_AXIS_OFFSET-4 "-"
*MEAS_COND_AXIS_OFFSET-5 "-"
*MEAS_COND_AXIS_OFFSET-6 "-"
*MEAS_COND_AXIS_OFFSET-7 "-"
*MEAS_COND_AXIS_OFFSET-8 "0.0000000000"
*MEAS_COND_AXIS_OFFSET-9 "-"
*MEAS_COND_AXIS_OFFSET-10 "-"
*MEAS_COND_AXIS_OFFSET-11 "-"
*MEAS_COND_AXIS_OFFSET-12 "-0.2466000000"
*MEAS_COND_AXIS_OFFSET-13 "0.3207000000"
*MEAS_COND_AXIS_OFFSET-14 "-"
*MEAS_COND_AXIS_OFFSET-15 "-"
*MEAS_COND_AXIS_OFFSET-16 "-"
*MEAS_COND_AXIS_OFFSET-17 "-"
*MEAS_COND_AXIS_OFFSET-18 "-"
*MEAS_COND_AXIS_OFFSET-19 "-"
*MEAS_COND_AXIS_OFFSET-20 "-"
*MEAS_COND_AXIS_OFFSET-21 "-"
*MEAS_COND_AXIS_OFFSET-22 "-"
*MEAS_COND_AXIS_OFFSET-23 "-"
*MEAS_COND_AXIS_OFFSET-24 "-"
*MEAS_COND_AXIS_OFFSET-25 "-"
*MEAS_COND_AXIS_OFFSET-26 "-"
*MEAS_COND_AXIS_OFFSET-27 "-"
*MEAS_COND_AXIS_OFFSET-28 "-"
*MEAS_COND_AXIS_OFFSET-29 "-"
*MEAS_COND_AXIS_OFFSET-30 "-"
*MEAS_COND_AXIS_OFFSET-31 "-"
*MEAS_COND_AXIS_OFFSET-32 "-"
*MEAS_COND_AXIS_OFFSET-33 "-"
*MEAS_COND_AXIS_OFFSET-34 "-"
*MEAS_COND_AXIS_OFFSET-35 "-"
*MEAS_COND_AXIS_OFFSET-36 "-"
*MEAS_COND_AXIS_OFFSET-37 "-"
*MEAS_COND_AXIS_OFFSET-38 "-"
*MEAS_COND_AXIS_OFFSET-39 "-"
*MEAS_COND_AXIS_POSITION-0 "16.7540000000"
*MEAS_COND_AXIS_POSITION-1 "16.7540000000"
*MEAS_COND_AXIS_POSITION-2 "8.3770000000"
*MEAS_COND_AXIS_POSITION-3 "0.0000000000"
*MEAS_COND_AXIS_POSITION-4 "-0.3500000000"
*MEAS_COND_AXIS_POSITION-5 "0.0000000000"
*MEAS_COND_AXIS_POSITION-6 "0.0000000000"
*MEAS_COND_AXIS_POSITION-7 "16.7540000000"
*MEAS_COND_AXIS_POSITION-8 "0.0000000000"
*MEAS_COND_AXIS_POSITION-9 "0.0000000000"
*MEAS_COND_AXIS_POSITION-10 "90.0000000000"
*MEAS_COND_AXIS_POSITION-11 "0.0000000000"
*MEAS_COND_AXIS_POSITION-12 "8.3770000000"
*MEAS_COND_AXIS_POSITION-13 "8.3770000000"
*MEAS_COND_AXIS_POSITION-14 "-0.7513800000"
*MEAS_COND_AXIS_POSITION-15 "BB"
*MEAS_COND_AXIS_POSITION-16 "0.0000000000"
*MEAS_COND_AXIS_POSITION-17 "Soller_slit_5.0deg"
*MEAS_COND_AXIS_POSITION-18 "1/2deg"
*MEAS_COND_AXIS_POSITION-19 "1.6581000000"
*MEAS_COND_AXIS_POSITION-20 "-0.2278100000"
*MEAS_COND_AXIS_POSITION-21 "0.0000000000"
*MEAS_COND_AXIS_POSITION-22 "5.0mm"
*MEAS_COND_AXIS_POSITION-23 "None"
*MEAS_COND_AXIS_POSITION-24 "Cu_K-beta"
*MEAS_COND_AXIS_POSITION-25 "1/2deg"
*MEAS_COND_AXIS_POSITION-26 "0.300mm"
*MEAS_COND_AXIS_POSITION-27 "PSA_open"
*MEAS_COND_AXIS_POSITION-28 "Soller_slit_5.0deg"
*MEAS_COND_AXIS_POSITION-29 "None"
*MEAS_COND_AXIS_POSITION-30 "0.9862000000"
*MEAS_COND_AXIS_POSITION-31 "0.3000000000"
*MEAS_COND_AXIS_POSITION-32 "0.4415600000"
*MEAS_COND_AXIS_POSITION-33 "Open"
*MEAS_COND_AXIS_POSITION-34 "None"
*MEAS_COND_AXIS_POSITION-35 "None"
*MEAS_COND_AXIS_POSITION-36 "16.7540000000"
*MEAS_COND_AXIS_POSITION-37 "None"
*MEAS_COND_AXIS_POSITION-38 "655.5000000000"
*MEAS_COND_AXIS_POSITION-39 "526.2500000000"
*MEAS_COND_AXIS_UNIT-0 "deg"
*MEAS_COND_AXIS_UNIT-1 "deg"
*MEAS_COND_AXIS_UNIT-2 "deg"
*MEAS_COND_AXIS_UNIT-3 "deg"
*MEAS_COND_AXIS_UNIT-4 "mm"
*MEAS_COND_AXIS_UNIT-5 "deg"
*MEAS_COND_AXIS_UNIT-6 "deg"
*MEAS_COND_AXIS_UNIT-7 "deg"
*MEAS_COND_AXIS_UNIT-8 "deg"
*MEAS_COND_AXIS_UNIT-9 "deg"
*MEAS_COND_AXIS_UNIT-10 "deg"
*MEAS_COND_AXIS_UNIT-11 "deg"
*MEAS_COND_AXIS_UNIT-12 "deg"
*MEAS_COND_AXIS_UNIT-13 "deg"
*MEAS_COND_AXIS_UNIT-14 "mm"
*MEAS_COND_AXIS_UNIT-15 ""
*MEAS_COND_AXIS_UNIT-16 "pulse"
*MEAS_COND_AXIS_UNIT-17 ""
*MEAS_COND_AXIS_UNIT-18 ""
*MEAS_COND_AXIS_UNIT-19 "mm"
*MEAS_COND_AXIS_UNIT-20 "mm"
*MEAS_COND_AXIS_UNIT-21 ""
*MEAS_COND_AXIS_UNIT-22 ""
*MEAS_COND_AXIS_UNIT-23 ""
*MEAS_COND_AXIS_UNIT-24 ""
*MEAS_COND_AXIS_UNIT-25 ""
*MEAS_COND_AXIS_UNIT-26 ""
*MEAS_COND_AXIS_UNIT-27 ""
*MEAS_COND_AXIS_UNIT-28 ""
*MEAS_COND_AXIS_UNIT-29 ""
*MEAS_COND_AXIS_UNIT-30 "mm"
*MEAS_COND_AXIS_UNIT-31 "mm"
*MEAS_COND_AXIS_UNIT-32 "mm"
*MEAS_COND_AXIS_UNIT-33 ""
*MEAS_COND_AXIS_UNIT-34 ""
*MEAS_COND_AXIS_UNIT-35 ""
*MEAS_COND_AXIS_UNIT-36 "deg"
*MEAS_COND_AXIS_UNIT-37 ""
*MEAS_COND_AXIS_UNIT-38 "V"
*MEAS_COND_AXIS_UNIT-39 "mV"
*MEAS_COND_COUNTER_CNTLOSS_CORR "1.0000000000"
*MEAS_COND_COUNTER_PHABASE "526.2500000000"
*MEAS_COND_COUNTER_PHAWINDOW "807.5000000000"
*MEAS_COND_COUNTER_PHA_UNIT "mV"
*MEAS_COND_COUNTER_TAUDIFF "0.1731010000"
*MEAS_COND_COUNTER_TAUINT "0.6617980000"
*MEAS_COND_IRRADIATION_MODE "OFF"
*MEAS_COND_IRRADIATION_WIDTH ""
*MEAS_COND_OPT_ATTR "Bragg-Brentano focusing"
*MEAS_COND_OPT_NAME "@BB focusing"
*MEAS_COND_UNSYMMETRIC_MODE "OFF"
*MEAS_COND_XG_CURRENT "30.0000000000"
*MEAS_COND_XG_VOLTAGE "40.0000000000"
*MEAS_COND_XG_WAVE_TYPE "Ka"
*MEAS_DATA_COUNT "40001.0000000000"
*MEAS_SCAN_AXIS_X "Theta/2-Theta"
*MEAS_SCAN_AXIS_X_INTERNAL "TwoThetaTheta"
*MEAS_SCAN_END_TIME "04/04/19 20:41:14"
*MEAS_SCAN_MODE "CONTINUOUS"
*MEAS_SCAN_MONITOR "0"
*MEAS_SCAN_RESOLUTION_X "0.0002"
*MEAS_SCAN_SPEED "2.400000"
*MEAS_SCAN_SPEED_UNIT "deg/min"
*MEAS_SCAN_SPEED_USER "2.4"
*MEAS_SCAN_START "10.0000000000"
*MEAS_SCAN_START_TIME "04/04/19 20:07:40"
*MEAS_SCAN_STEP "0.0020000000"
*MEAS_SCAN_STOP "90.0000000000"
*MEAS_SCAN_UNIT_X "deg"
*MEAS_SCAN_UNIT_Y "counts"
*RAS_HEADER_END
*RAS_INT_START
10.0000 1.0000 1.0000
10.0540 0.0000 1.0000
10.1080 1.0000 1.0000
10.1620 3.0000 1.0000
10.2160 4.0000 1.0000
10.2700 3.0000 1.0000
10.3240 2.0000 1.0000
10.3780 1.0000 1.0000
10.4320 4.0000 1.0000
10.4860 2.0000 1.0000
10.5400 1.0000 1.0000
10.5940 4.0000 1.0000
10.6480 1.0000 1.0000
10.7020 4.0000 1.0000
10.7560 4.0000 1.0000
10.8100 1.0000 1.0000
10.8640 5.0000 1.0000
10.9180 1.0000 1.0000
10.9720 0.0000 1.0000
11.0260 0.0000 1.0000
11.0800 2.0000 1.0000
11.1340 2.0000 1.0000
11.1880 1.0000 1.0000
11.2420 2.0000 1.0000
11.2960 2.0000 1.0000
11.3500 2.0000 1.0000
11.4040 3.0000 1.0000
11.4580 1.0000 1.0000
11.5120 2.0000 1.0000
11.5660 2.0000 1.0000
11.6200 2.0000 1.0000
11.6740 0.0000 1.0000
11.7280 0.0000 1.0000
11.7820 2.0000 1.0000
11.8360 0.0000 1.0000
11.8900 1.0000 1.0000
11.9440 0.0000 1.0000
11.9980 2.0000 1.0000
12.0520 1.0000 1.0000
12.1060 3.0000 1.0000
12.1600 3.0000 1.0000
12.2140 1.0000 1.0000
12.2680 0.0000 1.0000
12.3220 3.0000 1.0000
12.3760 1.0000 1.0000
12.4300 0.0000 1.0000
12.4840 1.0000 1.0000
12.5380 2.0000 1.0000
12.5920 1.0000 1.0000
12.6460 0.0000 1.0000
12.7000 3.0000 1.0000
12.7540 3.0000 1.0000
12.8080 1.0000 1.0000
12.8620 3.0000 1.0000
12.9160 2.0000 1.0000
12.9700 2.0000 1.0000
13.0240 1.0000 1.0000
13.0780 0.0000 1.0000
13.1320 0.0000 1.0000
13.1860 1.0000 1.0000
13.2400 0.0000 1.0000
13.2940 0.0000 1.0000
13.3480 2.0000 1.0000
13.4020 3.0000 1.0000
13.4560 2.0000 1.0000
13.5100 2.0000 1.0000
13.5640 2.0000 1.0000
13.6180 0.0000 1.0000
13.6720 1.0000 1.0000
13.7260 1.0000 1.0000
13.7800 0.0000 1.0000
13.8340 2.0000 1.0000
13.8880 0.0000 1.0000
13.9420 2.0000 1.0000
13.9960 5.0000 1.0000
14.0500 1.0000 1.0000
14.1040 5.0000 1.0000
14.1580 1.0000 1.0000
14.2120 1.0000 1.0000
14.2660 2.0000 1.0000
14.3200 2.0000 1.0000
14.3740 2.0000 1.0000
14.4280 1.0000 1.0000
14.4820 1.0000 1.0000
14.5360 3.0000 1.0000
14.5900 1.0000 1.0000
14.6440 1.0000 1.0000
14.6980 1.0000 1.0000
14.7520 2.0000 1.0000
14.8060 1.0000 1.0000
14.8600 1.0000 1.0000
14.9140 1.0000 1.0000
14.9680 0.0000 1.0000
15.0220 0.0000 1.0000
15.0760 3.0000 1.0000
15.1300 0.0000 1.0000
15.1840 0.0000 1.0000
15.2380 2.0000 1.0000
15.2920 0.0000 1.0000
15.3460 2.0000 1.0000
15.4000 1.0000 1.0000
15.4540 1.0000 1.0000
15.5080 0.0000 1.0000
15.5620 1.0000 1.0000
15.6160 1.0000 1.0000
15.6700 4.0000 1.0000
15.7240 0.0000 1.0000
15.7780 4.0000 1.0000
15.8320 1.0000 1.0000
15.8860 3.0000 1.0000
15.9400 2.0000 1.0000
15.9940 6.0000 1.0000
16.0480 10.0000 1.0000
16.1020 8.0000 1.0000
16.1560 4.0000 1.0000
16.2100 1.0000 1.0000
16.2640 2.0000 1.0000
16.3180 2.0000 1.0000
16.3720 4.0000 1.0000
16.4260 3.0000 1.0000
16.4800 6.0000 1.0000
16.5340 5.0000 1.0000
16.5880 6.0000 1.0000
16.6420 2.0000 1.0000
16.6960 1.0000 1.0000
16.7500 4.0000 1.0000
16.8040 0.0000 1.0000
16.8580 1.0000 1.0000
16.9120 2.0000 1.0000
16.9660 2.0000 1.0000
17.0200 0.0000 1.0000
17.0740 4.0000 1.0000
17.1280 2.0000 1.0000
17.1820 1.0000 1.0000
17.2360 0.0000 1.0000
17.2900 2.0000 1.0000
17.3440 1.0000 1.0000
17.3980 3.0000 1.0000
17.4520 2.0000 1.0000
17.5060 1.0000 1.0000
17.5600 2.0000 1.0000
17.6140 4.0000 1.0000
17.6680 0.0000 1.0000
17.7220 1.0000 1.0000
17.7760 4.0000 1.0000
17.8300 1.0000 1.0000
17.8840 3.0000 1.0000
17.9380 3.0000 1.0000
17.9920 0.0000 1.0000
18.0460 3.0000 1.0000
18.1000 3.0000 1.0000
18.1540 0.0000 1.0000
18.2080 3.0000 1.0000
18.2620 3.0000 1.0000
18.3160 2.0000 1.0000
18.3700 4.0000 1.0000
18.4240 1.0000 1.0000
18.4780 1.0000 1.0000
18.5320 4.0000 1.0000
18.5860 2.0000 1.0000
18.6400 2.0000 1.0000
18.6940 2.0000 1.0000
18.7480 1.0000 1.0000
18.8020 2.0000 1.0000
18.8560 0.0000 1.0000
18.9100 1.0000 1.0000
18.9640 2.0000 1.0000
19.0180 1.0000 1.0000
19.0720 2.0000 1.0000
19.1260 1.0000 1.0000
19.1800 0.0000 1.0000
19.2340 2.0000 1.0000
19.2880 0.0000 1.0000
19.3420 2.0000 1.0000
19.3960 2.0000 1.0000
19.4500 1.0000 1.0000
19.5040 0.0000 1.0000
19.5580 1.0000 1.0000
19.6120 2.0000 1.0000
19.6660 0.0000 1.0000
19.7200 1.0000 1.0000
19.7740 0.0000 1.0000
19.8280 1.0000 1.0000
19.8820 2.0000 1.0000
19.9360 2.0000 1.0000
19.9900 3.0000 1.0000
20.0440 1.0000 1.0000
20.0980 3.0000 1.0000
20.1520 1.0000 1.0000
20.2060 1.0000 1.0000
20.2600 2.0000 1.0000
20.3140 2.0000 1.0000
20.3680 1.0000 1.0000
20.4220 2.0000 1.0000
20.4760 1.0000 1.0000
20.5300 1.0000 1.0000
20.5840 0.0000 1.0000
20.6380 0.0000 1.0000
20.6920 3.0000 1.0000
20.7460 1.0000 1.0000
20.8000 2.0000 1.0000
20.8540 1.0000 1.0000
20.9080 4.0000 1.0000
20.9620 0.0000 1.0000
21.0160 1.0000 1.0000
21.0700 0.0000 1.0000
21.1240 0.0000 1.0000
21.1780 0.0000 1.0000
21.2320 1.0000 1.0000
21.2860 2.0000 1.0000
21.3400 0.0000 1.0000
21.3940 0.0000 1.0000
21.4480 1.0000 1.0000
21.5020 2.0000 1.0000
21.5560 1.0000 1.0000
21.6100 1.0000 1.0000
21.6640 3.0000 1.0000
21.7180 1.0000 1.0000
21.7720 0.0000 1.0000
21.8260 1.0000 1.0000
21.8800 1.0000 1.0000
21.9340 1.0000 1.0000
21.9880 0.0000 1.0000
22.0420 0.0000 1.0000
22.0960 1.0000 1.0000
22.1500 2.0000 1.0000
22.2040 3.0000 1.0000
22.2580 3.0000 1.0000
22.3120 1.0000 1.0000
22.3660 2.0000 1.0000
22.4200 0.0000 1.0000
22.4740 0.0000 1.0000
22.5280 1.0000 1.0000
22.5820 0.0000 1.0000
22.6360 2.0000 1.0000
22.6900 1.0000 1.0000
22.7440 3.0000 1.0000
22.7980 0.0000 1.0000
22.8520 1.0000 1.0000
22.9060 2.0000 1.0000
22.9600 0.0000 1.0000
23.0140 0.0000 1.0000
23.0680 1.0000 1.0000
23.1220 1.0000 1.0000
23.1760 2.0000 1.0000
23.2300 2.0000 1.0000
23.2840 0.0000 1.0000
23.3380 2.0000 1.0000
23.3920 3.0000 1.0000
23.4460 1.0000 1.0000
23.5000 1.0000 1.0000
23.5540 3.0000 1.0000
23.6080 1.0000 1.0000
23.6620 1.0000 1.0000
23.7160 0.0000 1.0000
23.7700 0.0000 1.0000
23.8240 0.0000 1.0000
23.8780 1.0000 1.0000
23.9320 0.0000 1.0000
23.9860 1.0000 1.0000
24.0400 4.0000 1.0000
24.0940 4.0000 1.0000
24.1480 2.0000 1.0000
24.2020 1.0000 1.0000
24.2560 2.0000 1.0000
24.3100 2.0000 1.0000
24.3640 1.0000 1.0000
24.4180 0.0000 1.0000
24.4720 1.0000 1.0000
24.5260 0.0000 1.0000
24.5800 0.0000 1.0000
24.6340 1.0000 1.0000
24.6880 0.0000 1.0000
24.7420 4.0000 1.0000
24.7960 3.0000 1.0000
24.8500 1.0000 1.0000
24.9040 0.0000 1.0000
24.9580 1.0000 1.0000
25.0120 1.0000 1.0000
25.0660 0.0000 1.0000
25.1200 1.0000 1.0000
25.1740 2.0000 1.0000
25.2280 1.0000 1.0000
25.2820 0.0000 1.0000
25.3360 0.0000 1.0000
25.3900 1.0000 1.0000
25.4440 0.0000 1.0000
25.4980 0.0000 1.0000
25.5520 1.0000 1.0000
25.6060 1.0000 1.0000
25.6600 2.0000 1.0000
25.7140 1.0000 1.0000
25.7680 0.0000 1.0000
25.8220 0.0000 1.0000
25.8760 2.0000 1.0000
25.9300 2.0000 1.0000
25.9840 0.0000 1.0000
26.0380 1.0000 1.0000
26.0920 1.0000 1.0000
26.1460 0.0000 1.0000
26.2000 1.0000 1.0000
26.2540 1.0000 1.0000
26.3080 0.0000 1.0000
26.3620 1.0000 1.0000
26.4160 0.0000 1.0000
26.4700 4.0000 1.0000
26.5240 1.0000 1.0000
26.5780 1.0000 1.0000
26.6320 2.0000 1.0000
26.6860 1.0000 1.0000
26.7400 3.0000 1.0000
26.7940 0.0000 1.0000
26.8480 4.0000 1.0000
26.9020 1.0000 1.0000
26.9560 2.0000 1.0000
27.0100 3.0000 1.0000
27.0640 0.0000 1.0000
27.1180 2.0000 1.0000
27.1720 3.0000 1.0000
27.2260 1.0000 1.0000
27.2800 1.0000 1.0000
27.3340 0.0000 1.0000
27.3880 1.0000 1.0000
27.4420 4.0000 1.0000
27.4960 0.0000 1.0000
27.5500 0.0000 1.0000
27.6040 3.0000 1.0000
27.6580 2.0000 1.0000
27.7120 9.0000 1.0000
27.7660 1.0000 1.0000
27.8200 3.0000 1.0000
27.8740 3.0000 1.0000
27.9280 1.0000 1.0000
27.9820 1.0000 1.0000
28.0360 1.0000 1.0000
28.0900 1.0000 1.0000
28.1440 2.0000 1.0000
28.1980 1.0000 1.0000
28.2520 18.0000 1.0000
28.3060 19.0000 1.0000
28.3600 21.0000 1.0000
28.4140 16.0000 1.0000
28.4680 17.0000 1.0000
28.5220 27.0000 1.0000
28.5760 6.0000 1.0000
28.6300 8.0000 1.0000
28.6840 2.0000 1.0000
28.7380 2.0000 1.0000
28.7920 2.0000 1.0000
28.8460 2.0000 1.0000
28.9000 1.0000 1.0000
28.9540 3.0000 1.0000
29.0080 0.0000 1.0000
29.0620 3.0000 1.0000
29.1160 2.0000 1.0000
29.1700 3.0000 1.0000
29.2240 1.0000 1.0000
29.2780 0.0000 1.0000
29.3320 0.0000 1.0000
29.3860 1.0000 1.0000
29.4400 1.0000 1.0000
29.4940 1.0000 1.0000
29.5480 0.0000 1.0000
29.6020 0.0000 1.0000
29.6560 0.0000 1.0000
29.7100 2.0000 1.0000
29.7640 0.0000 1.0000
29.8180 1.0000 1.0000
29.8720 0.0000 1.0000
29.9260 2.0000 1.0000
29.9800 0.0000 1.0000
30.0340 2.0000 1.0000
30.0880 2.0000 1.0000
30.1420 0.0000 1.0000
30.1960 3.0000 1.0000
30.2500 1.0000 1.0000
30.3040 1.0000 1.0000
30.3580 0.0000 1.0000
30.4120 0.0000 1.0000
30.4660 2.0000 1.0000
30.5200 1.0000 1.0000
30.5740 1.0000 1.0000
30.6280 1.0000 1.0000
30.6820 0.0000 1.0000
30.7360 0.0000 1.0000
30.7900 1.0000 1.0000
30.8440 2.0000 1.0000
30.8980 2.0000 1.0000
30.9520 1.0000 1.0000
31.0060 2.0000 1.0000
31.0600 0.0000 1.0000
31.1140 0.0000 1.0000
31.1680 1.0000 1.0000
31.2220 2.0000 1.0000
31.2760 1.0000 1.0000
31.3300 1.0000 1.0000
31.3840 1.0000 1.0000
31.4380 4.0000 1.0000
31.4920 1.0000 1.0000
31.5460 1.0000 1.0000
31.6000 2.0000 1.0000
31.6540 1.0000 1.0000
31.7080 1.0000 1.0000
31.7620 1.0000 1.0000
31.8160 1.0000 1.0000
31.8700 0.0000 1.0000
31.9240 2.0000 1.0000
31.9780 2.0000 1.0000
32.0320 1.0000 1.0000
32.0860 1.0000 1.0000
32.1400 1.0000 1.0000
32.1940 1.0000 1.0000
32.2480 2.0000 1.0000
32.3020 1.0000 1.0000
32.3560 0.0000 1.0000
32.4100 2.0000 1.0000
32.4640 1.0000 1.0000
32.5180 1.0000 1.0000
32.5720 0.0000 1.0000
32.6260 1.0000 1.0000
32.6800 2.0000 1.0000
32.7340 2.0000 1.0000
32.7880 0.0000 1.0000
32.8420 1.0000 1.0000
32.8960 1.0000 1.0000
32.9500 1.0000 1.0000
33.0040 1.0000 1.0000
33.0580 1.0000 1.0000
33.1120 1.0000 1.0000
33.1660 1.0000 1.0000
33.2200 4.0000 1.0000
33.2740 2.0000 1.0000
33.3280 0.0000 1.0000
33.3820 1.0000 1.0000
33.4360 1.0000 1.0000
33.4900 1.0000 1.0000
33.5440 1.0000 1.0000
33.5980 4.0000 1.0000
33.6520 4.0000 1.0000
33.7060 3.0000 1.0000
33.7600 2.0000 1.0000
33.8140 2.0000 1.0000
33.8680 2.0000 1.0000
33.9220 0.0000 1.0000
33.9760 0.0000 1.0000
34.0300 1.0000 1.0000
34.0840 1.0000 1.0000
34.1380 1.0000 1.0000
34.1920 2.0000 1.0000
34.2460 1.0000 1.0000
34.3000 1.0000 1.0000
34.3540 0.0000 1.0000
34.4080 0.0000 1.0000
34.4620 1.0000 1.0000
34.5160 2.0000 1.0000
34.5700 1.0000 1.0000
34.6240 2.0000 1.0000
34.6780 0.0000 1.0000
34.7320 1.0000 1.0000
34.7860 0.0000 1.0000
34.8400 0.0000 1.0000
34.8940 1.0000 1.0000
34.9480 1.0000 1.0000
35.0020 1.0000 1.0000
35.0560 1.0000 1.0000
35.1100 1.0000 1.0000
35.1640 0.0000 1.0000
35.2180 2.0000 1.0000
35.2720 1.0000 1.0000
35.3260 2.0000 1.0000
35.3800 0.0000 1.0000
35.4340 1.0000 1.0000
35.4880 1.0000 1.0000
35.5420 1.0000 1.0000
35.5960 0.0000 1.0000
35.6500 1.0000 1.0000
35.7040 3.0000 1.0000
35.7580 0.0000 1.0000
35.8120 0.0000 1.0000
35.8660 2.0000 1.0000
35.9200 1.0000 1.0000
35.9740 1.0000 1.0000
36.0280 1.0000 1.0000
36.0820 1.0000 1.0000
36.1360 1.0000 1.0000
36.1900 3.0000 1.0000
36.2440 1.0000 1.0000
36.2980 2.0000 1.0000
36.3520 1.0000 1.0000
36.4060 1.0000 1.0000
36.4600 1.0000 1.0000
36.5140 0.0000 1.0000
36.5680 1.0000 1.0000
36.6220 0.0000 1.0000
36.6760 0.0000 1.0000
36.7300 1.0000 1.0000
36.7840 0.0000 1.0000
36.8380 0.0000 1.0000
36.8920 1.0000 1.0000
36.9460 2.0000 1.0000
37.0000 5.0000 1.0000
37.0540 1.0000 1.0000
37.1080 2.0000 1.0000
37.1620 2.0000 1.0000
37.2160 2.0000 1.0000
37.2700 0.0000 1.0000
37.3240 4.0000 1.0000
37.3780 3.0000 1.0000
37.4320 2.0000 1.0000
37.4860 3.0000 1.0000
37.5400 1.0000 1.0000
37.5940 0.0000 1.0000
37.6480 1.0000 1.0000
37.7020 0.0000 1.0000
37.7560 3.0000 1.0000
37.8100 1.0000 1.0000
37.8640 5.0000 1.0000
37.9180 2.0000 1.0000
37.9720 2.0000 1.0000
38.0260 1.0000 1.0000
38.0800 0.0000 1.0000
38.1340 0.0000 1.0000
38.1880 1.0000 1.0000
38.2420 1.0000 1.0000
38.2960 1.0000 1.0000
38.3500 1.0000 1.0000
38.4040 1.0000 1.0000
38.4580 1.0000 1.0000
38.5120 0.0000 1.0000
38.5660 1.0000 1.0000
38.6200 1.0000 1.0000
38.6740 2.0000 1.0000
38.7280 1.0000 1.0000
38.7820 2.0000 1.0000
38.8360 3.0000 1.0000
38.8900 3.0000 1.0000
38.9440 1.0000 1.0000
38.9980 2.0000 1.0000
39.0520 1.0000 1.0000
39.1060 2.0000 1.0000
39.1600 1.0000 1.0000
39.2140 1.0000 1.0000
39.2680 0.0000 1.0000
39.3220 1.0000 1.0000
39.3760 0.0000 1.0000
39.4300 0.0000 1.0000
39.4840 2.0000 1.0000
39.5380 0.0000 1.0000
39.5920 0.0000 1.0000
39.6460 0.0000 1.0000
39.7000 2.0000 1.0000
39.7540 0.0000 1.0000
39.8080 3.0000 1.0000
39.8620 1.0000 1.0000
39.9160 1.0000 1.0000
39.9700 3.0000 1.0000
40.0240 4.0000 1.0000
40.0780 5.0000 1.0000
40.1320 8.0000 1.0000
40.1860 3.0000 1.0000
40.2400 2.0000 1.0000
40.2940 1.0000 1.0000
40.3480 0.0000 1.0000
40.4020 4.0000 1.0000
40.4560 2.0000 1.0000
40.5100 4.0000 1.0000
40.5640 1.0000 1.0000
40.6180 2.0000 1.0000
40.6720 5.0000 1.0000
40.7260 3.0000 1.0000
40.7800 0.0000 1.0000
40.8340 6.0000 1.0000
40.8880 2.0000 1.0000
40.9420 6.0000 1.0000
40.9960 3.0000 1.0000
41.0500 0.0000 1.0000
41.1040 2.0000 1.0000
41.1580 2.0000 1.0000
41.2120 1.0000 1.0000
41.2660 1.0000 1.0000
41.3200 2.0000 1.0000
41.3740 1.0000 1.0000
41.4280 0.0000 1.0000
41.4820 2.0000 1.0000
41.5360 2.0000 1.0000
41.5900 2.0000 1.0000
41.6440 2.0000 1.0000
41.6980 2.0000 1.0000
41.7520 1.0000 1.0000
41.8060 1.0000 1.0000
41.8600 0.0000 1.0000
41.9140 1.0000 1.0000
41.9680 0.0000 1.0000
42.0220 0.0000 1.0000
42.0760 3.0000 1.0000
42.1300 0.0000 1.0000
42.1840 1.0000 1.0000
42.2380 1.0000 1.0000
42.2920 0.0000 1.0000
42.3460 2.0000 1.0000
42.4000 1.0000 1.0000
42.4540 2.0000 1.0000
42.5080 3.0000 1.0000
42.5620 1.0000 1.0000
42.6160 5.0000 1.0000
42.6700 1.0000 1.0000
42.7240 2.0000 1.0000
42.7780 3.0000 1.0000
42.8320 1.0000 1.0000
42.8860 1.0000 1.0000
42.9400 0.0000 1.0000
42.9940 1.0000 1.0000
43.0480 1.0000 1.0000
43.1020 2.0000 1.0000
43.1560 1.0000 1.0000
43.2100 0.0000 1.0000
43.2640 1.0000 1.0000
43.3180 0.0000 1.0000
43.3720 0.0000 1.0000
43.4260 0.0000 1.0000
43.4800 1.0000 1.0000
43.5340 2.0000 1.0000
43.5880 0.0000 1.0000
43.6420 2.0000 1.0000
43.6960 0.0000 1.0000
43.7500 1.0000 1.0000
43.8040 0.0000 1.0000
43.8580 3.0000 1.0000
43.9120 1.0000 1.0000
43.9660 0.0000 1.0000
44.0200 2.0000 1.0000
44.0740 0.0000 1.0000
44.1280 2.0000 1.0000
44.1820 2.0000 1.0000
44.2360 2.0000 1.0000
44.2900 1.0000 1.0000
44.3440 2.0000 1.0000
44.3980 0.0000 1.0000
44.4520 2.0000 1.0000
44.5060 2.0000 1.0000
44.5600 1.0000 1.0000
44.6140 2.0000 1.0000
44.6680 1.0000 1.0000
44.7220 0.0000 1.0000
44.7760 0.0000 1.0000
44.8300 2.0000 1.0000
44.8840 2.0000 1.0000
44.9380 0.0000 1.0000
44.9920 1.0000 1.0000
45.0460 0.0000 1.0000
45.1000 0.0000 1.0000
45.1540 1.0000 1.0000
45.2080 1.0000 1.0000
45.2620 1.0000 1.0000
45.3160 1.0000 1.0000
45.3700 1.0000 1.0000
45.4240 0.0000 1.0000
45.4780 0.0000 1.0000
45.5320 0.0000 1.0000
45.5860 3.0000 1.0000
45.6400 1.0000 1.0000
45.6940 0.0000 1.0000
45.7480 1.0000 1.0000
45.8020 1.0000 1.0000
45.8560 1.0000 1.0000
45.9100 1.0000 1.0000
45.9640 1.0000 1.0000
46.0180 0.0000 1.0000
46.0720 0.0000 1.0000
46.1260 1.0000 1.0000
46.1800 2.0000 1.0000
46.2340 0.0000 1.0000
46.2880 0.0000 1.0000
46.3420 2.0000 1.0000
46.3960 0.0000 1.0000
46.4500 1.0000 1.0000
46.5040 0.0000 1.0000
46.5580 1.0000 1.0000
46.6120 1.0000 1.0000
46.6660 2.0000 1.0000
46.7200 0.0000 1.0000
46.7740 1.0000 1.0000
46.8280 1.0000 1.0000
46.8820 1.0000 1.0000
46.9360 2.0000 1.0000
46.9900 1.0000 1.0000
47.0440 3.0000 1.0000
47.0980 1.0000 1.0000
47.1520 4.0000 1.0000
47.2060 3.0000 1.0000
47.2600 5.0000 1.0000
47.3140 5.0000 1.0000
47.3680 2.0000 1.0000
47.4220 3.0000 1.0000
47.4760 1.0000 1.0000
47.5300 2.0000 1.0000
47.5840 1.0000 1.0000
47.6380 0.0000 1.0000
47.6920 4.0000 1.0000
47.7460 1.0000 1.0000
47.8000 1.0000 1.0000
47.8540 0.0000 1.0000
47.9080 1.0000 1.0000
47.9620 1.0000 1.0000
48.0160 0.0000 1.0000
48.0700 0.0000 1.0000
48.1240 0.0000 1.0000
48.1780 2.0000 1.0000
48.2320 2.0000 1.0000
48.2860 1.0000 1.0000
48.3400 2.0000 1.0000
48.3940 0.0000 1.0000
48.4480 3.0000 1.0000
48.5020 1.0000 1.0000
48.5560 2.0000 1.0000
48.6100 1.0000 1.0000
48.6640 0.0000 1.0000
48.7180 1.0000 1.0000
48.7720 2.0000 1.0000
48.8260 5.0000 1.0000
48.8800 2.0000 1.0000
48.9340 1.0000 1.0000
48.9880 0.0000 1.0000
49.0420 1.0000 1.0000
49.0960 1.0000 1.0000
49.1500 1.0000 1.0000
49.2040 2.0000 1.0000
49.2580 2.0000 1.0000
49.3120 4.0000 1.0000
49.3660 1.0000 1.0000
49.4200 5.0000 1.0000
49.4740 6.0000 1.0000
49.5280 3.0000 1.0000
49.5820 1.0000 1.0000
49.6360 1.0000 1.0000
49.6900 2.0000 1.0000
49.7440 0.0000 1.0000
49.7980 2.0000 1.0000
49.8520 3.0000 1.0000
49.9060 2.0000 1.0000
49.9600 3.0000 1.0000
50.0140 4.0000 1.0000
50.0680 3.0000 1.0000
50.1220 5.0000 1.0000
50.1760 1.0000 1.0000
50.2300 1.0000 1.0000
50.2840 1.0000 1.0000
50.3380 2.0000 1.0000
50.3920 0.0000 1.0000
50.4460 4.0000 1.0000
50.5000 5.0000 1.0000
50.5540 5.0000 1.0000
50.6080 6.0000 1.0000
50.6620 2.0000 1.0000
50.7160 7.0000 1.0000
50.7700 6.0000 1.0000
50.8240 2.0000 1.0000
50.8780 1.0000 1.0000
50.9320 4.0000 1.0000
50.9860 2.0000 1.0000
51.0400 0.0000 1.0000
51.0940 1.0000 1.0000
51.1480 0.0000 1.0000
51.2020 2.0000 1.0000
51.2560 0.0000 1.0000
51.3100 1.0000 1.0000
51.3640 3.0000 1.0000
51.4180 1.0000 1.0000
51.4720 1.0000 1.0000
51.5260 0.0000 1.0000
51.5800 0.0000 1.0000
51.6340 1.0000 1.0000
51.6880 1.0000 1.0000
51.7420 1.0000 1.0000
51.7960 0.0000 1.0000
51.8500 1.0000 1.0000
51.9040 1.0000 1.0000
51.9580 0.0000 1.0000
52.0120 1.0000 1.0000
52.0660 1.0000 1.0000
52.1200 1.0000 1.0000
52.1740 3.0000 1.0000
52.2280 3.0000 1.0000
52.2820 2.0000 1.0000
52.3360 1.0000 1.0000
52.3900 5.0000 1.0000
52.4440 2.0000 1.0000
52.4980 0.0000 1.0000
52.5520 1.0000 1.0000
52.6060 1.0000 1.0000
52.6600 1.0000 1.0000
52.7140 0.0000 1.0000
52.7680 3.0000 1.0000
52.8220 2.0000 1.0000
52.8760 2.0000 1.0000
52.9300 3.0000 1.0000
52.9840 2.0000 1.0000
53.0380 1.0000 1.0000
53.0920 3.0000 1.0000
53.1460 1.0000 1.0000
53.2000 4.0000 1.0000
53.2540 1.0000 1.0000
53.3080 1.0000 1.0000
53.3620 1.0000 1.0000
53.4160 1.0000 1.0000
53.4700 0.0000 1.0000
53.5240 1.0000 1.0000
53.5780 1.0000 1.0000
53.6320 1.0000 1.0000
53.6860 3.0000 1.0000
53.7400 1.0000 1.0000
53.7940 1.0000 1.0000
53.8480 0.0000 1.0000
53.9020 0.0000 1.0000
53.9560 1.0000 1.0000
54.0100 2.0000 1.0000
54.0640 1.0000 1.0000
54.1180 2.0000 1.0000
54.1720 2.0000 1.0000
54.2260 3.0000 1.0000
54.2800 1.0000 1.0000
54.3340 1.0000 1.0000
54.3880 0.0000 1.0000
54.4420 1.0000 1.0000
54.4960 2.0000 1.0000
54.5500 4.0000 1.0000
54.6040 3.0000 1.0000
54.6580 3.0000 1.0000
54.7120 2.0000 1.0000
54.7660 0.0000 1.0000
54.8200 1.0000 1.0000
54.8740 2.0000 1.0000
54.9280 4.0000 1.0000
54.9820 2.0000 1.0000
55.0360 3.0000 1.0000
55.0900 0.0000 1.0000
55.1440 1.0000 1.0000
55.1980 0.0000 1.0000
55.2520 0.0000 1.0000
55.3060 0.0000 1.0000
55.3600 3.0000 1.0000
55.4140 1.0000 1.0000
55.4680 0.0000 1.0000
55.5220 3.0000 1.0000
55.5760 3.0000 1.0000
55.6300 2.0000 1.0000
55.6840 0.0000 1.0000
55.7380 2.0000 1.0000
55.7920 1.0000 1.0000
55.8460 5.0000 1.0000
55.9000 7.0000 1.0000
55.9540 3.0000 1.0000
56.0080 2.0000 1.0000
56.0620 1.0000 1.0000
56.1160 3.0000 1.0000
56.1700 1.0000 1.0000
56.2240 0.0000 1.0000
56.2780 0.0000 1.0000
56.3320 2.0000 1.0000
56.3860 1.0000 1.0000
56.4400 0.0000 1.0000
56.4940 2.0000 1.0000
56.5480 1.0000 1.0000
56.6020 2.0000 1.0000
56.6560 2.0000 1.0000
56.7100 1.0000 1.0000
56.7640 1.0000 1.0000
56.8180 1.0000 1.0000
56.8720 3.0000 1.0000
56.9260 4.0000 1.0000
56.9800 1.0000 1.0000
57.0340 2.0000 1.0000
57.0880 0.0000 1.0000
57.1420 2.0000 1.0000
57.1960 0.0000 1.0000
57.2500 3.0000 1.0000
57.3040 3.0000 1.0000
57.3580 2.0000 1.0000
57.4120 2.0000 1.0000
57.4660 1.0000 1.0000
57.5200 0.0000 1.0000
57.5740 2.0000 1.0000
57.6280 3.0000 1.0000
57.6820 2.0000 1.0000
57.7360 1.0000 1.0000
57.7900 0.0000 1.0000
57.8440 2.0000 1.0000
57.8980 3.0000 1.0000
57.9520 2.0000 1.0000
58.0060 1.0000 1.0000
58.0600 1.0000 1.0000
58.1140 4.0000 1.0000
58.1680 1.0000 1.0000
58.2220 1.0000 1.0000
58.2760 1.0000 1.0000
58.3300 0.0000 1.0000
58.3840 0.0000 1.0000
58.4380 2.0000 1.0000
58.4920 3.0000 1.0000
58.5460 1.0000 1.0000
58.6000 0.0000 1.0000
58.6540 4.0000 1.0000
58.7080 1.0000 1.0000
58.7620 1.0000 1.0000
58.8160 3.0000 1.0000
58.8700 2.0000 1.0000
58.9240 0.0000 1.0000
58.9780 0.0000 1.0000
59.0320 3.0000 1.0000
59.0860 1.0000 1.0000
59.1400 2.0000 1.0000
59.1940 3.0000 1.0000
59.2480 4.0000 1.0000
59.3020 1.0000 1.0000
59.3560 0.0000 1.0000
59.4100 2.0000 1.0000
59.4640 2.0000 1.0000
59.5180 2.0000 1.0000
59.5720 5.0000 1.0000
59.6260 2.0000 1.0000
59.6800 0.0000 1.0000
59.7340 1.0000 1.0000
59.7880 1.0000 1.0000
59.8420 1.0000 1.0000
59.8960 0.0000 1.0000
59.9500 2.0000 1.0000
60.0040 1.0000 1.0000
60.0580 1.0000 1.0000
60.1120 2.0000 1.0000
60.1660 0.0000 1.0000
60.2200 0.0000 1.0000
60.2740 0.0000 1.0000
60.3280 1.0000 1.0000
60.3820 1.0000 1.0000
60.4360 2.0000 1.0000
60.4900 1.0000 1.0000
60.5440 1.0000 1.0000
60.5980 2.0000 1.0000
60.6520 3.0000 1.0000
60.7060 1.0000 1.0000
60.7600 1.0000 1.0000
60.8140 1.0000 1.0000
60.8680 0.0000 1.0000
60.9220 1.0000 1.0000
60.9760 3.0000 1.0000
61.0300 0.0000 1.0000
61.0840 0.0000 1.0000
61.1380 1.0000 1.0000
61.1920 0.0000 1.0000
61.2460 0.0000 1.0000
61.3000 0.0000 1.0000
61.3540 1.0000 1.0000
61.4080 1.0000 1.0000
61.4620 0.0000 1.0000
61.5160 1.0000 1.0000
61.5700 1.0000 1.0000
61.6240 0.0000 1.0000
61.6780 0.0000 1.0000
61.7320 1.0000 1.0000
61.7860 3.0000 1.0000
61.8400 4.0000 1.0000
61.8940 2.0000 1.0000
61.9480 1.0000 1.0000
62.0020 1.0000 1.0000
62.0560 2.0000 1.0000
62.1100 0.0000 1.0000
62.1640 0.0000 1.0000
62.2180 1.0000 1.0000
62.2720 1.0000 1.0000
62.3260 1.0000 1.0000
62.3800 1.0000 1.0000
62.4340 0.0000 1.0000
62.4880 1.0000 1.0000
62.5420 1.0000 1.0000
62.5960 1.0000 1.0000
62.6500 1.0000 1.0000
62.7040 0.0000 1.0000
62.7580 0.0000 1.0000
62.8120 2.0000 1.0000
62.8660 1.0000 1.0000
62.9200 0.0000 1.0000
62.9740 0.0000 1.0000
63.0280 0.0000 1.0000
63.0820 1.0000 1.0000
63.1360 2.0000 1.0000
63.1900 0.0000 1.0000
63.2440 0.0000 1.0000
63.2980 1.0000 1.0000
63.3520 0.0000 1.0000
63.4060 0.0000 1.0000
63.4600 3.0000 1.0000
63.5140 1.0000 1.0000
63.5680 1.0000 1.0000
63.6220 0.0000 1.0000
63.6760 1.0000 1.0000
63.7300 2.0000 1.0000
63.7840 3.0000 1.0000
63.8380 0.0000 1.0000
63.8920 1.0000 1.0000
63.9460 1.0000 1.0000
64.0000 1.0000 1.0000
64.0540 3.0000 1.0000
64.1080 1.0000 1.0000
64.1620 1.0000 1.0000
64.2160 2.0000 1.0000
64.2700 0.0000 1.0000
64.3240 2.0000 1.0000
64.3780 0.0000 1.0000
64.4320 0.0000 1.0000
64.4860 0.0000 1.0000
64.5400 0.0000 1.0000
64.5940 1.0000 1.0000
64.6480 0.0000 1.0000
64.7020 1.0000 1.0000
64.7560 0.0000 1.0000
64.8100 0.0000 1.0000
64.8640 0.0000 1.0000
64.9180 0.0000 1.0000
64.9720 2.0000 1.0000
65.0260 4.0000 1.0000
65.0800 0.0000 1.0000
65.1340 3.0000 1.0000
65.1880 1.0000 1.0000
65.2420 0.0000 1.0000
65.2960 0.0000 1.0000
65.3500 2.0000 1.0000
65.4040 0.0000 1.0000
65.4580 0.0000 1.0000
65.5120 0.0000 1.0000
65.5660 0.0000 1.0000
65.6200 3.0000 1.0000
65.6740 0.0000 1.0000
65.7280 4.0000 1.0000
65.7820 1.0000 1.0000
65.8360 1.0000 1.0000
65.8900 1.0000 1.0000
65.9440 1.0000 1.0000
65.9980 1.0000 1.0000
66.0520 1.0000 1.0000
66.1060 0.0000 1.0000
66.1600 2.0000 1.0000
66.2140 0.0000 1.0000
66.2680 3.0000 1.0000
66.3220 2.0000 1.0000
66.3760 1.0000 1.0000
66.4300 4.0000 1.0000
66.4840 1.0000 1.0000
66.5380 1.0000 1.0000
66.5920 0.0000 1.0000
66.6460 0.0000 1.0000
66.7000 1.0000 1.0000
66.7540 3.0000 1.0000
66.8080 4.0000 1.0000
66.8620 2.0000 1.0000
66.9160 1.0000 1.0000
66.9700 1.0000 1.0000
67.0240 1.0000 1.0000
67.0780 0.0000 1.0000
67.1320 1.0000 1.0000
67.1860 0.0000 1.0000
67.2400 1.0000 1.0000
67.2940 2.0000 1.0000
67.3480 1.0000 1.0000
67.4020 0.0000 1.0000
67.4560 4.0000 1.0000
67.5100 1.0000 1.0000
67.5640 0.0000 1.0000
67.6180 2.0000 1.0000
67.6720 0.0000 1.0000
67.7260 3.0000 1.0000
67.7800 2.0000 1.0000
67.8340 1.0000 1.0000
67.8880 1.0000 1.0000
67.9420 2.0000 1.0000
67.9960 1.0000 1.0000
68.0500 0.0000 1.0000
68.1040 1.0000 1.0000
68.1580 0.0000 1.0000
68.2120 1.0000 1.0000
68.2660 3.0000 1.0000
68.3200 1.0000 1.0000
68.3740 2.0000 1.0000
68.4280 2.0000 1.0000
68.4820 2.0000 1.0000
68.5360 0.0000 1.0000
68.5900 2.0000 1.0000
68.6440 0.0000 1.0000
68.6980 2.0000 1.0000
68.7520 0.0000 1.0000
68.8060 0.0000 1.0000
68.8600 0.0000 1.0000
68.9140 2.0000 1.0000
68.9680 1.0000 1.0000
69.0220 0.0000 1.0000
69.0760 1.0000 1.0000
69.1300 2.0000 1.0000
69.1840 2.0000 1.0000
69.2380 1.0000 1.0000
69.2920 1.0000 1.0000
69.3460 1.0000 1.0000
69.4000 1.0000 1.0000
69.4540 0.0000 1.0000
69.5080 0.0000 1.0000
69.5620 3.0000 1.0000
69.6160 0.0000 1.0000
69.6700 2.0000 1.0000
69.7240 2.0000 1.0000
69.7780 0.0000 1.0000
69.8320 0.0000 1.0000
69.8860 2.0000 1.0000
69.9400 0.0000 1.0000
69.9940 0.0000 1.0000
70.0480 3.0000 1.0000
70.1020 1.0000 1.0000
70.1560 0.0000 1.0000
70.2100 0.0000 1.0000
70.2640 3.0000 1.0000
70.3180 2.0000 1.0000
70.3720 4.0000 1.0000
70.4260 2.0000 1.0000
70.4800 0.0000 1.0000
70.5340 1.0000 1.0000
70.5880 0.0000 1.0000
70.6420 3.0000 1.0000
70.6960 1.0000 1.0000
70.7500 0.0000 1.0000
70.8040 1.0000 1.0000
70.8580 1.0000 1.0000
70.9120 2.0000 1.0000
70.9660 0.0000 1.0000
71.0200 1.0000 1.0000
71.0740 0.0000 1.0000
71.1280 1.0000 1.0000
71.1820 1.0000 1.0000
71.2360 1.0000 1.0000
71.2900 0.0000 1.0000
71.3440 0.0000 1.0000
71.3980 2.0000 1.0000
71.4520 0.0000 1.0000
71.5060 1.0000 1.0000
71.5600 1.0000 1.0000
71.6140 1.0000 1.0000
71.6680 1.0000 1.0000
71.7220 1.0000 1.0000
71.7760 1.0000 1.0000
71.8300 1.0000 1.0000
71.8840 0.0000 1.0000
71.9380 2.0000 1.0000
71.9920 0.0000 1.0000
72.0460 2.0000 1.0000
72.1000 1.0000 1.0000
72.1540 0.0000 1.0000
72.2080 2.0000 1.0000
72.2620 1.0000 1.0000
72.3160 0.0000 1.0000
72.3700 1.0000 1.0000
72.4240 2.0000 1.0000
72.4780 3.0000 1.0000
72.5320 0.0000 1.0000
72.5860 1.0000 1.0000
72.6400 2.0000 1.0000
72.6940 1.0000 1.0000
72.7480 3.0000 1.0000
72.8020 0.0000 1.0000
72.8560 1.0000 1.0000
72.9100 1.0000 1.0000
72.9640 1.0000 1.0000
73.0180 1.0000 1.0000
73.0720 1.0000 1.0000
73.1260 1.0000 1.0000
73.1800 3.0000 1.0000
73.2340 2.0000 1.0000
73.2880 0.0000 1.0000
73.3420 1.0000 1.0000
73.3960 1.0000 1.0000
73.4500 3.0000 1.0000
73.5040 0.0000 1.0000
73.5580 1.0000 1.0000
73.6120 1.0000 1.0000
73.6660 0.0000 1.0000
73.7200 0.0000 1.0000
73.7740 1.0000 1.0000
73.8280 3.0000 1.0000
73.8820 0.0000 1.0000
73.9360 1.0000 1.0000
73.9900 3.0000 1.0000
74.0440 2.0000 1.0000
74.0980 1.0000 1.0000
74.1520 0.0000 1.0000
74.2060 1.0000 1.0000
74.2600 1.0000 1.0000
74.3140 2.0000 1.0000
74.3680 1.0000 1.0000
74.4220 1.0000 1.0000
74.4760 4.0000 1.0000
74.5300 0.0000 1.0000
74.5840 1.0000 1.0000
74.6380 3.0000 1.0000
74.6920 3.0000 1.0000
74.7460 0.0000 1.0000
74.8000 1.0000 1.0000
74.8540 5.0000 1.0000
74.9080 3.0000 1.0000
74.9620 0.0000 1.0000
75.0160 0.0000 1.0000
75.0700 1.0000 1.0000
75.1240 1.0000 1.0000
75.1780 0.0000 1.0000
75.2320 1.0000 1.0000
75.2860 2.0000 1.0000
75.3400 1.0000 1.0000
75.3940 2.0000 1.0000
75.4480 2.0000 1.0000
75.5020 0.0000 1.0000
75.5560 1.0000 1.0000
75.6100 0.0000 1.0000
75.6640 3.0000 1.0000
75.7180 1.0000 1.0000
75.7720 2.0000 1.0000
75.8260 3.0000 1.0000
75.8800 2.0000 1.0000
75.9340 0.0000 1.0000
75.9880 2.0000 1.0000
76.0420 2.0000 1.0000
76.0960 2.0000 1.0000
76.1500 3.0000 1.0000
76.2040 1.0000 1.0000
76.2580 0.0000 1.0000
76.3120 0.0000 1.0000
76.3660 2.0000 1.0000
76.4200 1.0000 1.0000
76.4740 1.0000 1.0000
76.5280 1.0000 1.0000
76.5820 2.0000 1.0000
76.6360 0.0000 1.0000
76.6900 2.0000 1.0000
76.7440 1.0000 1.0000
76.7980 0.0000 1.0000
76.8520 0.0000 1.0000
76.9060 0.0000 1.0000
76.9600 1.0000 1.0000
77.0140 1.0000 1.0000
77.0680 2.0000 1.0000
77.1220 6.0000 1.0000
77.1760 1.0000 1.0000
77.2300 0.0000 1.0000
77.2840 0.0000 1.0000
77.3380 0.0000 1.0000
77.3920 1.0000 1.0000
77.4460 2.0000 1.0000
77.5000 2.0000 1.0000
77.5540 0.0000 1.0000
77.6080 1.0000 1.0000
77.6620 1.0000 1.0000
77.7160 1.0000 1.0000
77.7700 1.0000 1.0000
77.8240 2.0000 1.0000
77.8780 0.0000 1.0000
77.9320 1.0000 1.0000
77.9860 0.0000 1.0000
78.0400 0.0000 1.0000
78.0940 1.0000 1.0000
78.1480 1.0000 1.0000
78.2020 1.0000 1.0000
78.2560 3.0000 1.0000
78.3100 0.0000 1.0000
78.3640 1.0000 1.0000
78.4180 1.0000 1.0000
78.4720 0.0000 1.0000
78.5260 2.0000 1.0000
78.5800 4.0000 1.0000
78.6340 1.0000 1.0000
78.6880 2.0000 1.0000
78.7420 1.0000 1.0000
78.7960 0.0000 1.0000
78.8500 0.0000 1.0000
78.9040 0.0000 1.0000
78.9580 1.0000 1.0000
79.0120 1.0000 1.0000
79.0660 3.0000 1.0000
79.1200 3.0000 1.0000
79.1740 2.0000 1.0000
79.2280 0.0000 1.0000
79.2820 3.0000 1.0000
79.3360 2.0000 1.0000
79.3900 0.0000 1.0000
79.4440 1.0000 1.0000
79.4980 2.0000 1.0000
79.5520 0.0000 1.0000
79.6060 0.0000 1.0000
79.6600 0.0000 1.0000
79.7140 1.0000 1.0000
79.7680 2.0000 1.0000
79.8220 0.0000 1.0000
79.8760 2.0000 1.0000
79.9300 0.0000 1.0000
79.9840 0.0000 1.0000
80.0380 1.0000 1.0000
80.0920 1.0000 1.0000
80.1460 3.0000 1.0000
80.2000 0.0000 1.0000
80.2540 1.0000 1.0000
80.3080 2.0000 1.0000
80.3620 0.0000 1.0000
80.4160 1.0000 1.0000
80.4700 1.0000 1.0000
80.5240 1.0000 1.0000
80.5780 0.0000 1.0000
80.6320 4.0000 1.0000
80.6860 2.0000 1.0000
80.7400 1.0000 1.0000
80.7940 0.0000 1.0000
80.8480 1.0000 1.0000
80.9020 1.0000 1.0000
80.9560 2.0000 1.0000
81.0100 1.0000 1.0000
81.0640 0.0000 1.0000
81.1180 1.0000 1.0000
81.1720 1.0000 1.0000
81.2260 0.0000 1.0000
81.2800 2.0000 1.0000
81.3340 3.0000 1.0000
81.3880 3.0000 1.0000
81.4420 3.0000 1.0000
81.4960 2.0000 1.0000
81.5500 0.0000 1.0000
81.6040 2.0000 1.0000
81.6580 1.0000 1.0000
81.7120 3.0000 1.0000
81.7660 1.0000 1.0000
81.8200 0.0000 1.0000
81.8740 0.0000 1.0000
81.9280 3.0000 1.0000
81.9820 1.0000 1.0000
82.0360 1.0000 1.0000
82.0900 3.0000 1.0000
82.1440 1.0000 1.0000
82.1980 0.0000 1.0000
82.2520 2.0000 1.0000
82.3060 0.0000 1.0000
82.3600 0.0000 1.0000
82.4140 2.0000 1.0000
82.4680 1.0000 1.0000
82.5220 2.0000 1.0000
82.5760 3.0000 1.0000
82.6300 0.0000 1.0000
82.6840 2.0000 1.0000
82.7380 1.0000 1.0000
82.7920 0.0000 1.0000
82.8460 0.0000 1.0000
82.9000 1.0000 1.0000
82.9540 1.0000 1.0000
83.0080 1.0000 1.0000
83.0620 1.0000 1.0000
83.1160 1.0000 1.0000
83.1700 1.0000 1.0000
83.2240 3.0000 1.0000
83.2780 2.0000 1.0000
83.3320 4.0000 1.0000
83.3860 1.0000 1.0000
83.4400 1.0000 1.0000
83.4940 3.0000 1.0000
83.5480 0.0000 1.0000
83.6020 1.0000 1.0000
83.6560 0.0000 1.0000
83.7100 0.0000 1.0000
83.7640 1.0000 1.0000
83.8180 0.0000 1.0000
83.8720 0.0000 1.0000
83.9260 0.0000 1.0000
83.9800 0.0000 1.0000
84.0340 1.0000 1.0000
84.0880 1.0000 1.0000
84.1420 0.0000 1.0000
84.1960 0.0000 1.0000
84.2500 2.0000 1.0000
84.3040 1.0000 1.0000
84.3580 1.0000 1.0000
84.4120 2.0000 1.0000
84.4660 1.0000 1.0000
84.5200 3.0000 1.0000
84.5740 0.0000 1.0000
84.6280 1.0000 1.0000
84.6820 1.0000 1.0000
84.7360 1.0000 1.0000
84.7900 3.0000 1.0000
84.8440 1.0000 1.0000
84.8980 1.0000 1.0000
84.9520 0.0000 1.0000
85.0060 2.0000 1.0000
85.0600 0.0000 1.0000
85.1140 2.0000 1.0000
85.1680 4.0000 1.0000
85.2220 1.0000 1.0000
85.2760 0.0000 1.0000
85.3300 1.0000 1.0000
85.3840 4.0000 1.0000
85.4380 1.0000 1.0000
85.4920 3.0000 1.0000
85.5460 1.0000 1.0000
85.6000 1.0000 1.0000
85.6540 2.0000 1.0000
85.7080 1.0000 1.0000
85.7620 3.0000 1.0000
85.8160 2.0000 1.0000
85.8700 1.0000 1.0000
85.9240 1.0000 1.0000
85.9780 0.0000 1.0000
86.0320 3.0000 1.0000
86.0860 2.0000 1.0000
86.1400 2.0000 1.0000
86.1940 2.0000 1.0000
86.2480 2.0000 1.0000
86.3020 2.0000 1.0000
86.3560 0.0000 1.0000
86.4100 0.0000 1.0000
86.4640 1.0000 1.0000
86.5180 1.0000 1.0000
86.5720 1.0000 1.0000
86.6260 0.0000 1.0000
86.6800 1.0000 1.0000
86.7340 1.0000 1.0000
86.7880 0.0000 1.0000
86.8420 0.0000 1.0000
86.8960 1.0000 1.0000
86.9500 0.0000 1.0000
87.0040 0.0000 1.0000
87.0580 0.0000 1.0000
87.1120 1.0000 1.0000
87.1660 2.0000 1.0000
87.2200 1.0000 1.0000
87.2740 1.0000 1.0000
87.3280 0.0000 1.0000
87.3820 0.0000 1.0000
87.4360 1.0000 1.0000
87.4900 1.0000 1.0000
87.5440 1.0000 1.0000
87.5980 1.0000 1.0000
87.6520 4.0000 1.0000
87.7060 0.0000 1.0000
87.7600 0.0000 1.0000
87.8140 3.0000 1.0000
87.8680 0.0000 1.0000
87.9220 2.0000 1.0000
87.9760 3.0000 1.0000
88.0300 3.0000 1.0000
88.0840 4.0000 1.0000
88.1380 1.0000 1.0000
88.1920 1.0000 1.0000
88.2460 0.0000 1.0000
88.3000 2.0000 1.0000
88.3540 1.0000 1.0000
88.4080 1.0000 1.0000
88.4620 3.0000 1.0000
88.5160 1.0000 1.0000
88.5700 0.0000 1.0000
88.6240 0.0000 1.0000
88.6780 1.0000 1.0000
88.7320 2.0000 1.0000
88.7860 0.0000 1.0000
88.8400 0.0000 1.0000
88.8940 1.0000 1.0000
88.9480 5.0000 1.0000
89.0020 2.0000 1.0000
89.0560 0.0000 1.0000
89.1100 3.0000 1.0000
89.1640 1.0000 1.0000
89.2180 1.0000 1.0000
89.2720 1.0000 1.0000
89.3260 1.0000 1.0000
89.3800 1.0000 1.0000
89.4340 2.0000 1.0000
89.4880 1.0000 1.0000
89.5420 1.0000 1.0000
89.5960 0.0000 1.0000
89.6500 1.0000 1.0000
89.7040 2.0000 1.0000
89.7580 0.0000 1.0000
89.8120 2.0000 1.0000
89.8660 2.0000 1.0000
89.9200 1.0000 1.0000
89.9740 0.0000 1.0000
90.0000 3.0000 1.0000
*RAS_INT_END
*RAS_DATA_END